File: Examples/data/20181108_RvsT_3CH_Side1.dat
[Header]
TITLE, 20181108 PCCO 17 Grow N2O Annealed 200 Torr O2 2min
FILEOPENTIME,10839542.50,11/27/2018,9:49 AM
BYAPP, Resistivity, 2.1, 1.0
INFO, APPNAME, PPMS MultiVu Application, 1.5.11
INFO, Short, Sample1 Name
INFO, 1, Sample1 Cross Section
INFO, 1, Sample1 Length
INFO, Ohm, Sample1 Units
INFO, Long, Sample2 Name
INFO, 1, Sample2 Cross Section
INFO, 1, Sample2 Length
INFO, Ohm, Sample2 Units
INFO, Sum, Sample3 Name
INFO, 1, Sample3 Cross Section
INFO, 1, Sample3 Length
INFO, Ohm, Sample3 Units
INFO, , Sample4 Name
INFO, 1, Sample4 Cross Section
INFO, 1, Sample4 Length
INFO, Ohm-m, Sample4 Units
FIELDGROUP, Resistivity,2,3,4,5,6,7,8,9,10,11,12,13,14,15,16,17,18,19,20,21,22,23,24,25,26,27,28,29,30,31,32,33,34,35,36,37,38,39,40,41
STARTUPGROUP, Resistivity
STARTUPAXIS, X, 2, LINEAR, AUTO
STARTUPAXIS, Y1, 7, LINEAR, AUTO
STARTUPAXIS, Y2, 9, LINEAR, AUTO
STARTUPAXIS, Y3, 11, LINEAR, AUTO
PLOT_APPEARANCE, ALL, HORZ_GRID_ON, VERT_GRID_ON, MARKERS_AND_LINES, ALL_LINES
DATATYPE, TIME, 2
DATATYPE, COMMENT, 1
[Data]
Comment,Time Stamp (sec),Status (code),Temperature (K),Magnetic Field (Oe),Sample Position (deg),Bridge 1 Resistivity (Ohm),Bridge 1 Excitation (uA),Bridge 2 Resistivity (Ohm),Bridge 2 Excitation (uA),Bridge 3 Resistivity (Ohm),Bridge 3 Excitation (uA),Bridge 4 Resistivity (Ohm-m),Bridge 4 Excitation (uA),Bridge 1 Std. Dev. (Ohm),Bridge 2 Std. Dev. (Ohm),Bridge 3 Std. Dev. (Ohm),Bridge 4 Std. Dev. (Ohm-m),Number of Readings,Bridge 1 Resistance (Ohms),Bridge 2 Resistance (Ohms),Bridge 3 Resistance (Ohms),Bridge 4 Resistance (Ohms),Signal 1 Vin (V),Signal 2 Vin (V),Digital Inputs (code),Drive 1 Iout (mA),Drive 1 Ipower (watts),Drive 2 Iout (mA),Drive 2 Ipower (watts),Pressure (),Map 20 (),Map 21 (),Map 22 (),Map 23 (),Map 24 (),Map 25 (),Map 26 (),Map 27 (),Map 28 (),Map 29 ()
,10839563.72,4370,299.986953735352,-0.0850000008940697,90.0139999389648,542.59078125,99.7262005615234,681.202514648438,99.3060806274414,1223.71150390625,71.2748382568359,,,0.00784121021271034,0.0115506765527273,0.0210877513744876,,25,542.59078125,681.202514648438,1223.71150390625,
,10839721.73,4374,289.944702148438,-0.0850000008940697,90.0139999389648,531.476704101563,99.9020004272461,667.228408203125,99.9020004272461,1198.66975097656,75.9649963378906,,,0.593041836596561,0.748622877171734,1.34243353521062,,25,531.476704101563,667.228408203125,1198.66975097656,
,10839821.61,4370,281.417892456055,-0.0850000008940697,90.0139999389648,513.396726074219,99.9020004272461,644.289973144531,99.9020004272461,1157.75270507813,78.4565173339844,,,0.469791751145395,0.593603405895962,1.04861217500852,,25,513.396726074219,644.289973144531,1157.75270507813,
,10839929.77,4370,272.479690551758,-0.0850000008940697,90.0139999389648,497.821807861328,99.9020004272461,624.693952636719,99.9020004272461,1122.56437011719,79.6289978027344,,,0.418272445203776,0.528047548414241,0.947557968323041,,25,497.821807861328,624.693952636719,1122.56437011719,
,10840011.84,4370,265.478790283203,-0.0850000008940697,90.0139999389648,485.240009765625,99.9020004272461,608.721079101563,99.9020004272461,1094.03720703125,83.5370025634766,,,0.443106257463327,0.562328817404084,1.00565017971492,,25,485.240009765625,608.721079101563,1094.03720703125,
,10840096.47,4370,258.518005371094,-0.0850000008940697,90.0139999389648,472.759130859375,99.9020004272461,592.953371582031,99.9020004272461,1065.78155761719,83.5370025634766,,,0.419912722780327,0.533091813824682,0.950517187508903,,25,472.759130859375,592.953371582031,1065.78155761719,
,10840168.91,4370,252.494453430176,-0.0850000008940697,90.0139999389648,462.372618408203,99.9020004272461,579.910798339844,99.9020004272461,1042.27415527344,87.6890029907227,,,0.418259963362391,0.531891082375353,0.944165634817156,,25,462.372618408203,579.910798339844,1042.27415527344,
,10840240.95,4370,246.479652404785,-0.0850000008940697,90.0139999389648,452.146358642578,99.9020004272461,566.989133300781,99.9020004272461,1019.12252441406,87.6890029907227,,,0.407525484467873,0.515493318105454,0.921898608693394,,25,452.146358642578,566.989133300781,1019.12252441406,
,10840336.89,4370,238.466499328613,-0.0850000008940697,90.0139999389648,438.471413574219,99.9020004272461,549.638112792969,99.9020004272461,987.98970703125,91.8420028686523,,,0.412104303771722,0.521027725203789,0.93578219919657,,25,438.471413574219,549.638112792969,987.98970703125,
,10840408.81,4370,232.458251953125,-0.0850000008940697,90.0139999389648,428.28205078125,99.9020004272461,536.768254394531,99.9020004272461,965.025551757813,91.8420028686523,,,0.424062661619204,0.534521183294959,0.960252226196479,,25,428.28205078125,536.768254394531,965.025551757813,
,10840493.45,4370,225.467750549316,-0.0850000008940697,90.0139999389648,417.034663085938,99.9020004272461,522.554904785156,99.9020004272461,939.530983886719,99.9020004272461,,,0.377504552358833,0.476408330000704,0.853679281754897,,25,417.034663085938,522.554904785156,939.530983886719,
,10840564.19,4370,219.535751342773,-0.0850000008940697,90.0139999389648,407.787231445313,99.9020004272461,510.869847412109,99.9020004272461,918.602790527344,99.9020004272461,,,0.374575227320876,0.476853466762127,0.851414315564974,,25,407.787231445313,510.869847412109,918.602790527344,
,10840636.61,4370,213.513298034668,-0.0850000008940697,90.0139999389648,398.387126464844,99.9020004272461,499.056922607422,99.9020004272461,897.4408984375,99.9020004272461,,,0.371821633675671,0.468829209091274,0.839632327059871,,25,398.387126464844,499.056922607422,897.4408984375,
,10840720.64,4370,206.458549499512,-0.0850000008940697,90.0139999389648,387.314371337891,99.9020004272461,485.064365234375,99.9020004272461,872.373100585938,99.9020004272461,,,0.371285790159227,0.471288794684126,0.841626066646029,,25,387.314371337891,485.064365234375,872.373100585938,
,10840793.63,4370,200.443496704102,-0.0850000008940697,90.0139999389648,378.314801025391,99.9020004272461,473.624376220703,99.9020004272461,851.884270019531,99.9020004272461,,,0.349434915294049,0.441680526845253,0.791842432730435,,25,378.314801025391,473.624376220703,851.884270019531,
,10840875.98,4370,193.556549072266,-0.0850000008940697,90.0139999389648,368.3084765625,99.9020004272461,461.033356933594,99.9020004272461,829.33779296875,99.9020004272461,,,0.345963931473047,0.439487703506052,0.786739151147592,,25,368.3084765625,461.033356933594,829.33779296875,
,10840948.98,4370,187.45719909668,-0.0850000008940697,90.0139999389648,359.651876220703,99.9020004272461,450.025516357422,99.9020004272461,809.622314453125,99.9020004272461,,,0.349588764983554,0.445051205658143,0.797080235167118,,25,359.651876220703,450.025516357422,809.622314453125,
,10841019.44,4370,181.508750915527,-0.0850000008940697,90.0139999389648,351.302674560547,99.9020004272461,439.463958740234,99.9020004272461,790.816389160156,99.9020004272461,,,0.346254461675258,0.438056206273618,0.777085680526676,,25,351.302674560547,439.463958740234,790.816389160156,
,10841092.39,4370,175.515594482422,-0.0850000008940697,90.0139999389648,342.866309814453,99.9020004272461,428.779399414062,99.9020004272461,771.699055175781,99.9020004272461,,,0.328922944570082,0.416079324231398,0.746375665092447,,25,342.866309814453,428.779399414062,771.699055175781,
,10841177.59,4370,168.42610168457,-0.0850000008940697,90.0139999389648,333.412121582031,99.9020004272461,416.810612792969,99.9020004272461,750.266457519531,99.9020004272461,,,0.313327781457756,0.398343622947113,0.703256094652334,,25,333.412121582031,416.810612792969,750.266457519531,
,10841261.03,4370,161.476951599121,-0.0850000008940697,90.0139999389648,324.594008789063,99.9020004272461,405.696826171875,99.9020004272461,730.287797851562,99.9020004272461,,,0.297795377087063,0.374917018009911,0.672921613516062,,25,324.594008789063,405.696826171875,730.287797851562,
,10841344.50,4370,154.486099243164,-0.0850000008940697,90.0139999389648,316.089158935547,99.9020004272461,394.928316650391,99.9020004272461,711.011921386719,99.9020004272461,,,0.294096734965051,0.37380608787177,0.667487441018141,,25,316.089158935547,394.928316650391,711.011921386719,
,10841417.53,4370,148.441650390625,-0.0850000008940697,90.0139999389648,308.957481689453,99.9020004272461,385.832490234375,99.9020004272461,694.784938964844,99.9020004272461,,,0.271401119255485,0.343249123158736,0.611745199006456,,25,308.957481689453,385.832490234375,694.784938964844,
,10841488.41,4370,142.529945373535,-0.0850000008940697,90.0139999389648,302.473647460938,99.9020004272461,377.566643066406,99.9020004272461,680.082905273438,99.9020004272461,,,0.259482986311103,0.327541525586042,0.588104849913986,,25,302.473647460938,377.566643066406,680.082905273438,
,10841559.42,4370,136.457649230957,-0.0850000008940697,90.0139999389648,296.181820068359,99.9020004272461,369.579768066406,99.9020004272461,665.72388671875,99.9020004272461,,,0.269163314306697,0.340696879414587,0.613986212645384,,25,296.181820068359,369.579768066406,665.72388671875,
,10841632.75,4370,130.522354125977,-0.0850000008940697,90.0139999389648,289.9076171875,99.9020004272461,361.611807861328,99.9020004272461,651.556889648438,99.9020004272461,,,0.23363586428467,0.297749726116032,0.529494416097808,,25,289.9076171875,361.611807861328,651.556889648438,
,10841705.34,4370,124.446300506592,-0.0850000008940697,90.0139999389648,284.348038330078,99.9020004272461,354.580974121094,99.9020004272461,638.927072753906,99.9020004272461,,,0.21202526921881,0.270632512394265,0.481370190580815,,25,284.348038330078,354.580974121094,638.927072753906,
,10841800.00,4370,116.494998931885,-0.0850000008940697,90.0139999389648,277.650263671875,99.9020004272461,346.053688964844,99.9020004272461,623.7009765625,99.9020004272461,,,0.211285779336495,0.266248062953888,0.477672225636654,,25,277.650263671875,346.053688964844,623.7009765625,
,10841873.61,4370,110.424449920654,-0.0850000008940697,90.0139999389648,272.947456054688,99.9020004272461,340.024445800781,99.9020004272461,612.945981445313,99.9020004272461,,,0.173090775331223,0.22080412922226,0.392191378287051,,25,272.947456054688,340.024445800781,612.945981445313,
,10841944.83,4370,104.514747619629,-0.0850000008940697,90.0139999389648,268.970428466797,99.9020004272461,334.972554931641,99.9020004272461,603.94013671875,99.9020004272461,,,0.149456112237322,0.193157435805295,0.342263170783081,,25,268.970428466797,334.972554931641,603.94013671875,
,10842016.73,4370,98.4851493835449,-0.0850000008940697,90.0139999389648,265.468814697266,99.9020004272461,330.455981445312,99.9020004272461,595.949177246094,99.9020004272461,,,0.132367196342057,0.169290714809019,0.301668131122564,,25,265.468814697266,330.455981445312,595.949177246094,
,10842101.08,4370,91.444652557373,-0.0850000008940697,90.0139999389648,261.934821777344,99.9020004272461,325.896335449219,99.9020004272461,587.848532714844,99.9020004272461,,,0.113234125745385,0.147030655472079,0.262720230269731,,25,261.934821777344,325.896335449219,587.848532714844,
,10842173.17,4370,85.4403495788574,-0.0850000008940697,90.0139999389648,259.573210449219,99.9020004272461,322.811291503906,99.9020004272461,582.373852539062,99.9020004272461,,,0.0809716459424148,0.105851732575635,0.187241669046299,,25,259.573210449219,322.811291503906,582.373852539062,
,10842257.20,4370,78.4684524536133,-0.0850000008940697,90.0139999389648,257.680551757813,99.9020004272461,320.286674804687,99.9020004272461,577.958784179688,99.9020004272461,,,0.0513353753757222,0.0672878133665432,0.118392198749313,,25,257.680551757813,320.286674804687,577.958784179688,
,10842329.81,4370,72.5044479370117,-0.0850000008940697,90.0139999389648,256.718354492187,99.9020004272461,318.939453125,99.9020004272461,575.654833984375,99.9020004272461,,,0.0264055590439544,0.0373145904569063,0.0612472311602577,,25,256.718354492187,318.939453125,575.654833984375,
,10842427.44,4370,64.4915008544922,-0.0850000008940697,90.0139999389648,256.486846923828,99.9020004272461,318.4380859375,99.9020004272461,574.92443359375,99.9020004272461,,,0.0146566114865606,0.00936666424777615,0.0210534811315677,,25,256.486846923828,318.4380859375,574.92443359375,
,10842513.23,4370,57.3839988708496,-0.0850000008940697,90.0139999389648,257.407969970703,99.9020004272461,319.380374755859,99.9020004272461,576.780090332031,99.9020004272461,,,0.0519389405417655,0.0543830116412624,0.104296401967983,,25,257.407969970703,319.380374755859,576.780090332031,
,10842597.58,4370,50.5180511474609,-0.0850000008940697,90.0139999389648,259.365067138672,99.9020004272461,321.599547119141,99.9020004272461,580.975847167969,99.9020004272461,,,0.0866417496522656,0.10069013595948,0.187156944092771,,25,259.365067138672,321.599547119141,580.975847167969,
,10842695.48,4370,42.5545997619629,-0.0850000008940697,90.0139999389648,263.094208984375,99.9020004272461,325.937413330078,99.9020004272461,589.0324609375,99.9020004272461,,,0.131359307333411,0.155185828444821,0.284343887317998,,25,263.094208984375,325.937413330078,589.0324609375,
,10842784.14,4370,35.4532012939453,-0.0850000008940697,90.0139999389648,267.750690917969,99.9020004272461,331.473720703125,99.9020004272461,599.194670410156,99.9020004272461,,,0.16985982435576,0.20363058076324,0.375191288019963,,25,267.750690917969,331.473720703125,599.194670410156,
,10842860.23,4370,29.8922004699707,-0.0850000008940697,90.0139999389648,272.580150146484,99.9020004272461,337.220003662109,99.9020004272461,609.817136230469,99.9020004272461,,,0.117445055550772,0.139355696734447,0.254442065231452,,25,272.580150146484,337.220003662109,609.817136230469,
,10843069.92,4370,28.9018497467041,-0.0850000008940697,90.0139999389648,273.586187744141,99.9020004272461,338.417437744141,99.9020004272461,611.995815429687,99.9020004272461,,,0.0414813487025883,0.0491858419120748,0.0928366984966426,,25,273.586187744141,338.417437744141,611.995815429687,
,10843146.34,4370,27.5927495956421,-0.0850000008940697,90.0139999389648,274.812834472656,99.9020004272461,339.881468505859,99.9020004272461,614.700783691406,99.9020004272461,,,0.0463855070344872,0.0517110146303159,0.096657583992444,,25,274.812834472656,339.881468505859,614.700783691406,
,10843218.88,4370,26.3966503143311,-0.0850000008940697,90.0139999389648,275.966403808594,99.9020004272461,341.255802001953,99.9020004272461,617.211730957031,99.9020004272461,,,0.0466790398187176,0.0563944270741302,0.103597002836009,,25,275.966403808594,341.255802001953,617.211730957031,
,10843302.97,4370,25.0111503601074,-0.0850000008940697,90.0139999389648,277.314674072266,99.9020004272461,342.866270751953,99.9020004272461,620.174147949219,99.9020004272461,,,0.042721233234527,0.0511622262482092,0.0934155188989353,,25,277.314674072266,342.866270751953,620.174147949219,
,10843375.16,4370,23.797550201416,-0.0850000008940697,90.0139999389648,278.541402587891,99.9020004272461,344.335533447266,99.9020004272461,622.88533203125,99.9020004272461,,,0.0474420688240027,0.0581175182825545,0.103189564683679,,25,278.541402587891,344.335533447266,622.88533203125,
,10843451.23,4370,22.5012502670288,-0.0850000008940697,90.0139999389648,279.938171386719,99.9020004272461,345.995830078125,99.9020004272461,625.932976074219,99.9020004272461,,,0.0503737569847616,0.059241276061851,0.109755641340685,,25,279.938171386719,345.995830078125,625.932976074219,
,10843524.64,4370,21.3053493499756,-0.0850000008940697,90.0139999389648,281.243526611328,99.9020004272461,347.562257080078,99.9020004272461,628.798486328125,99.9020004272461,,,0.0444116392432312,0.0541959625470984,0.0972796109065957,,25,281.243526611328,347.562257080078,628.798486328125,
,10843616.22,4370,19.7948999404907,-0.0850000008940697,90.0139999389648,282.930261230469,99.9020004272461,349.577791748047,99.9020004272461,632.515283203125,99.9020004272461,,,0.0517442065137813,0.0604882534529047,0.111239715814324,,25,282.930261230469,349.577791748047,632.515283203125,
,10843686.92,4370,18.6014003753662,-0.0850000008940697,90.0139999389648,284.29013671875,99.9020004272461,351.194357910156,99.9020004272461,635.486364746094,99.9020004272461,,,0.055473742629739,0.0649262181740005,0.119450750331247,,25,284.29013671875,351.194357910156,635.486364746094,
,10843764.19,4370,17.3052005767822,-0.0850000008940697,90.0139999389648,285.843516845703,99.9020004272461,353.057026367188,99.9020004272461,638.906755371094,99.9020004272461,,,0.0580563685885634,0.06750962461042,0.124659002604463,,25,285.843516845703,353.057026367188,638.906755371094,
,10843843.55,4370,15.9822497367859,-0.0850000008940697,90.0139999389648,287.47037109375,99.9020004272461,354.999398193359,99.9020004272461,642.459001464844,99.9020004272461,,,0.0598566207118823,0.071404138858355,0.131688622228768,,25,287.47037109375,354.999398193359,642.459001464844,
,10843920.69,4370,14.6989002227783,-0.0850000008940697,90.0139999389648,289.072200927734,99.9020004272461,356.893443603516,99.9020004272461,645.963937988281,99.9020004272461,,,0.0594942934783743,0.0707514934561062,0.130386598072301,,25,289.072200927734,356.893443603516,645.963937988281,
,10843999.34,4370,13.387900352478,-0.0850000008940697,90.0139999389648,290.659759521484,99.9020004272461,358.785822753906,99.9020004272461,649.452534179688,99.9020004272461,,,0.0580020297383918,0.068546332529616,0.12909400967624,,25,290.659759521484,358.785822753906,649.452534179688,
,10844077.22,4370,12.0899000167847,-0.0850000008940697,90.0139999389648,292.148682861328,99.9020004272461,360.537602539063,99.9020004272461,652.692084960937,99.9020004272461,,,0.051371399970531,0.0598274905243079,0.110375620901104,,25,292.148682861328,360.537602539063,652.692084960937,
,10844148.80,4370,10.8920001983643,-0.0850000008940697,90.0139999389648,293.250450439453,99.9020004272461,361.798892822266,99.9020004272461,655.041745605469,99.9020004272461,,,0.0347967975727443,0.0392828548771152,0.071883738659676,,25,293.250450439453,361.798892822266,655.041745605469,
,10844331.14,4375,9.25719976425171,-0.0850000008940697,90.0139999389648,293.275219726563,99.9020004272461,361.616265869141,99.9020004272461,654.893549804688,99.9020004272461,,,0.0196925709447285,0.0277393121023004,0.0474330300042606,,25,293.275219726563,361.616265869141,654.893549804688,
,10844463.38,4375,8.66085004806519,-0.0850000008940697,90.0139999389648,292.184339599609,99.9020004272461,360.149000244141,99.9020004272461,652.32552734375,99.9020004272461,,,0.0387983097924656,0.0542338110262902,0.0935279493906977,,25,292.184339599609,360.149000244141,652.32552734375,
,10844589.41,4375,8.0455002784729,-0.0850000008940697,90.0139999389648,289.573334960937,99.9020004272461,356.722795410156,99.9020004272461,646.294907226562,99.9020004272461,,,0.153440939396493,0.197580085924515,0.354952691816786,,25,289.573334960937,356.722795410156,646.294907226562,
,10844747.11,4375,7.37794995307922,-0.0850000008940697,90.0139999389648,283.094700927734,99.9020004272461,348.243041992188,99.9020004272461,631.31427734375,99.9020004272461,,,0.231894740784304,0.29439721092249,0.522710554875079,,25,283.094700927734,348.243041992188,631.31427734375,
,10844915.42,4370,6.31019997596741,-0.0850000008940697,90.0139999389648,249.323117675781,99.9020004272461,304.214288330078,99.9020004272461,553.502182617187,99.9020004272461,,,2.37114499457335,3.10058191930424,5.47611179476035,,25,249.323117675781,304.214288330078,553.502182617187,
,10844995.77,4370,5.00720000267029,-0.0850000008940697,90.0139999389648,117.091810302734,99.9020004272461,131.210758972168,99.9020004272461,249.177604980469,99.9020004272461,,,5.42107566365981,6.82861840814708,12.2869929548098,,25,117.091810302734,131.210758972168,249.177604980469,
,10845078.98,4370,3.68930006027222,-0.0850000008940697,90.0139999389648,10.883568649292,99.9020004272461,7.78040567398071,99.9020004272461,18.4090813446045,99.9020004272461,,,1.49719815092875,1.34381811212304,2.82470391995763,,25,10.883568649292,7.78040567398071,18.4090813446045,
,10845162.00,4370,2.39504992961884,-0.0850000008940697,90.0139999389648,0.0695970937609673,99.9020004272461,0.0187714284658432,99.9020004272461,0.0828516437113285,99.9020004272461,,,0.0130456328767424,0.00610610450136714,0.0193859803962413,,25,0.0695970937609673,0.0187714284658432,0.0828516437113285,
,10845288.23,4370,2.50244998931885,-0.0850000008940697,90.0139999389648,0.0549617943167686,99.9020004272461,0.0116966311726719,99.9020004272461,0.0658206601440907,99.9020004272461,,,0.0140566682213327,0.00540548011262331,0.0200103529084025,,25,0.0549617943167686,0.0116966311726719,0.0658206601440907,
,10845360.31,4370,3.7036999464035,-0.0850000008940697,90.0139999389648,10.7726667785645,99.9020004272461,7.79677074432373,99.9020004272461,18.547262878418,99.9020004272461,,,1.52375679271165,1.37373633997213,3.06853738912352,,25,10.7726667785645,7.79677074432373,18.547262878418,
,10845438.75,4370,5.00714993476868,-0.0850000008940697,90.0139999389648,113.422569274902,99.9020004272461,127.273410949707,99.9020004272461,241.537695922852,99.9020004272461,,,5.69189993898454,7.16501187893722,12.8748591525854,,25,113.422569274902,127.273410949707,241.537695922852,
,10845516.05,4370,6.3000500202179,-0.0850000008940697,90.0139999389648,246.615967407227,99.9020004272461,300.546654052734,99.9020004272461,546.643923339844,99.9020004272461,,,3.07334787902706,4.06361441527495,7.1787317457708,,25,246.615967407227,300.546654052734,546.643923339844,
,10845594.17,4370,7.59669995307922,-0.0850000008940697,90.0139999389648,285.735865478516,99.9020004272461,351.722189941406,99.9020004272461,637.37498046875,99.9020004272461,,,0.499219007726476,0.652617538546111,1.15081971420509,,25,285.735865478516,351.722189941406,637.37498046875,
,10845666.72,4370,8.79780006408691,-0.0850000008940697,90.0139999389648,292.442902832031,99.9020004272461,360.480231933594,99.9020004272461,652.925500488281,99.9020004272461,,,0.073011952370725,0.091473355133866,0.16545933406572,,25,292.442902832031,360.480231933594,652.925500488281,
,10845751.00,4370,10.2003002166748,-0.0850000008940697,90.0139999389648,293.615541992188,99.9020004272461,362.171097412109,99.9020004272461,655.784194335938,99.9020004272461,,,0.0096293938459643,0.00714715473855015,0.0164667751552822,,25,293.615541992188,362.171097412109,655.784194335938,
,10845823.38,4370,11.4219498634338,-0.0850000008940697,90.0139999389648,292.893764648438,99.9020004272461,361.392829589844,99.9020004272461,654.294521484375,99.9020004272461,,,0.0465702812114906,0.0559227273328136,0.101322208469308,,25,292.893764648438,361.392829589844,654.294521484375,
,10845900.34,4370,12.6938500404358,-0.0850000008940697,90.0139999389648,291.580427246094,99.9020004272461,359.867991943359,99.9020004272461,651.458166503906,99.9020004272461,,,0.0529611784115874,0.0622599437953898,0.115141631493577,,25,291.580427246094,359.867991943359,651.458166503906,
,10845978.88,4370,14.0070996284485,-0.0850000008940697,90.0139999389648,290.030238037109,99.9020004272461,358.033869628906,99.9020004272461,648.073688964844,99.9020004272461,,,0.0580375703179623,0.0712592325034449,0.125305294932417,,25,290.030238037109,358.033869628906,648.073688964844,
,10846051.06,4370,15.2010998725891,-0.0850000008940697,90.0139999389648,288.570949707031,99.9020004272461,356.299337158203,99.9020004272461,644.860346679688,99.9020004272461,,,0.052135084439282,0.0621932571642355,0.115757623803681,,25,288.570949707031,356.299337158203,644.860346679688,
,10846128.97,4370,16.5080003738403,-0.0850000008940697,90.0139999389648,286.984118652344,99.9020004272461,354.421202392578,99.9020004272461,641.404096679688,99.9020004272461,,,0.0593158251517175,0.0705823040071163,0.131542258855438,,25,286.984118652344,354.421202392578,641.404096679688,
,10846199.98,4370,17.690899848938,-0.0850000008940697,90.0139999389648,285.558836669922,99.9020004272461,352.720434570312,99.9020004272461,638.277231445313,99.9020004272461,,,0.0556974266578942,0.0658176881232655,0.120440439442365,,25,285.558836669922,352.720434570312,638.277231445313,
,10846272.98,4370,18.9117994308472,-0.0850000008940697,90.0139999389648,284.130196533203,99.9020004272461,351.015335693359,99.9020004272461,635.143627929687,99.9020004272461,,,0.0577043104715831,0.0682967374773892,0.127149858170145,,25,284.130196533203,351.015335693359,635.143627929687,
,10846351.23,4370,20.211350440979,-0.0850000008940697,90.0139999389648,282.638194580078,99.9020004272461,349.2318359375,99.9020004272461,631.868542480469,99.9020004272461,,,0.0557764151047507,0.0650943623303008,0.120170440199043,,25,282.638194580078,349.2318359375,631.868542480469,
,10846422.39,4370,21.3970003128052,-0.0850000008940697,90.0139999389648,281.325096435547,99.9020004272461,347.661737060547,99.9020004272461,628.985344238281,99.9020004272461,,,0.0555784264472772,0.0643913017016806,0.117707591486136,,25,281.325096435547,347.661737060547,628.985344238281,
,10846494.67,4370,22.5984497070313,-0.0850000008940697,90.0139999389648,280.034324951172,99.9020004272461,346.1095703125,99.9020004272461,626.135224609375,99.9020004272461,,,0.0509406187264767,0.0588044080199587,0.111228493081818,,25,280.034324951172,346.1095703125,626.135224609375,
,10846566.47,4370,23.7949495315552,-0.0850000008940697,90.0139999389648,278.774454345703,99.9020004272461,344.60654296875,99.9020004272461,623.3888671875,99.9020004272461,,,0.0491908756404563,0.0573702555342642,0.108181862999346,,25,278.774454345703,344.60654296875,623.3888671875,
,10846639.63,4370,25.0126504898071,-0.0850000008940697,90.0139999389648,277.544146728516,99.9020004272461,343.133686523438,99.9020004272461,620.667326660156,99.9020004272461,,,0.0483100692850915,0.0584134459446584,0.106316006170064,,25,277.544146728516,343.133686523438,620.667326660156,
,10846716.89,4370,26.3038501739502,-0.0850000008940697,90.0139999389648,276.252005615234,99.9020004272461,341.601408691406,99.9020004272461,617.850817871094,99.9020004272461,,,0.0472721445534452,0.0551180581114728,0.102499726107205,,25,276.252005615234,341.601408691406,617.850817871094,
,10846788.63,4370,27.5031003952026,-0.0850000008940697,90.0139999389648,275.119633789063,99.9020004272461,340.240366210938,99.9020004272461,615.352978515625,99.9020004272461,,,0.0465226302989722,0.0555205571030462,0.100442413308247,,25,275.119633789063,340.240366210938,615.352978515625,
,10846860.58,4370,28.6977500915527,-0.0850000008940697,90.0139999389648,274.019376220703,99.9020004272461,338.929250488281,99.9020004272461,612.955065917969,99.9020004272461,,,0.0434911468757431,0.0520694504771222,0.0970568437821736,,25,274.019376220703,338.929250488281,612.955065917969,
,10846932.98,4370,29.9057493209839,-0.0850000008940697,90.0139999389648,272.938638916016,99.9020004272461,337.637012939453,99.9020004272461,610.570007324219,99.9020004272461,,,0.0418548730008124,0.0499636276694675,0.0917094589925278,,25,272.938638916016,337.637012939453,610.570007324219,
,10847005.00,4370,31.1069993972778,-0.0850000008940697,90.0139999389648,271.9052734375,99.9020004272461,336.411558837891,99.9020004272461,608.316472167969,99.9020004272461,,,0.0412323637829074,0.0487927318985851,0.0888492558277247,,25,271.9052734375,336.411558837891,608.316472167969,
,10847076.94,4370,32.3079986572266,-0.0850000008940697,90.0139999389648,270.924265136719,99.9020004272461,335.235631103516,99.9020004272461,606.15265625,99.9020004272461,,,0.0383180009667151,0.0466429895269583,0.0851869481863704,,25,270.924265136719,335.235631103516,606.15265625,
,10847149.23,4370,33.5115489959717,-0.0850000008940697,90.0139999389648,269.963032226563,99.9020004272461,334.088341064453,99.9020004272461,604.055400390625,99.9020004272461,,,0.0367084730301838,0.0455951543463671,0.08321298319213,,25,269.963032226563,334.088341064453,604.055400390625,
,10847221.23,4370,34.7062511444092,-0.0850000008940697,90.0139999389648,269.039250488281,99.9020004272461,332.999533691406,99.9020004272461,602.040334472656,99.9020004272461,,,0.0376744480803149,0.0436641465342458,0.0787245946381787,,25,269.039250488281,332.999533691406,602.040334472656,
,10847292.77,4370,35.9032001495361,-0.0850000008940697,90.0139999389648,268.161021728516,99.9020004272461,331.952392578125,99.9020004272461,600.110690917969,99.9020004272461,,,0.0357302034590696,0.0410523441834175,0.0749968485089373,,25,268.161021728516,331.952392578125,600.110690917969,
,10847365.20,4370,37.1088008880615,-0.0850000008940697,90.0139999389648,267.308343505859,99.9020004272461,330.934000244141,99.9020004272461,598.24775390625,99.9020004272461,,,0.033702575302513,0.0393961814319383,0.0737320942415334,,25,267.308343505859,330.934000244141,598.24775390625,
,10847437.34,4370,38.3130512237549,-0.0850000008940697,90.0139999389648,266.492738037109,99.9020004272461,329.965808105469,99.9020004272461,596.461198730469,99.9020004272461,,,0.0314698079095563,0.0379318691986743,0.0694254780572079,,25,266.492738037109,329.965808105469,596.461198730469,
,10847508.31,4370,39.4953002929688,-0.0850000008940697,90.0139999389648,265.731947021484,99.9020004272461,329.070560302734,99.9020004272461,594.801416015625,99.9020004272461,,,0.029221251856024,0.0365223048826281,0.0670328619951819,,25,265.731947021484,329.070560302734,594.801416015625,
,10847580.38,4370,40.7005996704102,-0.0850000008940697,90.0139999389648,264.976235351562,99.9020004272461,328.172403564453,99.9020004272461,593.144873046875,99.9020004272461,,,0.0297810031778319,0.0365047189246129,0.064680468430057,,25,264.976235351562,328.172403564453,593.144873046875,
,10847652.42,4370,41.899450302124,-0.0850000008940697,90.0139999389648,264.262373046875,99.9020004272461,327.327425537109,99.9020004272461,591.591062011719,99.9020004272461,,,0.0261190410800349,0.0328269381862519,0.060990848671504,,25,264.262373046875,327.327425537109,591.591062011719,
,10847724.39,4370,43.0990009307861,-0.0850000008940697,90.0139999389648,263.585655517578,99.9020004272461,326.527747802734,99.9020004272461,590.109697265625,99.9020004272461,,,0.0288438321341956,0.0321126789634658,0.0565571972135588,,25,263.585655517578,326.527747802734,590.109697265625,
,10847802.95,4370,44.4074001312256,-0.0850000008940697,90.0139999389648,262.886435546875,99.9020004272461,325.705029296875,99.9020004272461,588.595935058594,99.9020004272461,,,0.0254972818576544,0.0295090265706026,0.0538579440804876,,25,262.886435546875,325.705029296875,588.595935058594,
,10847875.36,4370,45.6121997833252,-0.0850000008940697,90.0139999389648,262.280974121094,99.9020004272461,324.993688964844,99.9020004272461,587.272290039062,99.9020004272461,,,0.0229437110003555,0.0272462799444468,0.0524750731995017,,25,262.280974121094,324.993688964844,587.272290039062,
,10847946.58,4370,46.7997493743896,-0.0850000008940697,90.0139999389648,261.708992919922,99.9020004272461,324.325711669922,99.9020004272461,586.034985351562,99.9020004272461,,,0.0219422868954423,0.0267755226079236,0.0494089179508482,,25,261.708992919922,324.325711669922,586.034985351562,
,10848019.05,4370,48.0034999847412,-0.0850000008940697,90.0139999389648,261.161673583984,99.9020004272461,323.687575683594,99.9020004272461,584.849711914062,99.9020004272461,,,0.0215763229592908,0.0252213275743753,0.0466960599699296,,25,261.161673583984,323.687575683594,584.849711914062,
,10848090.23,4370,49.194450378418,-0.0850000008940697,90.0139999389648,260.645729980469,99.9020004272461,323.079399414062,99.9020004272461,583.7291015625,99.9020004272461,,,0.0203234325616499,0.023822530923782,0.0424728599124816,,25,260.645729980469,323.079399414062,583.7291015625,
,10849215.19,4370,29.8210496902466,89999.3984375,90.0139999389648,271.748765869141,99.9020004272461,336.244290771484,99.9020004272461,607.996455078125,99.9020004272461,,,0.0281613431543955,0.0320160107916624,0.0585420633871741,,25,271.748765869141,336.244290771484,607.996455078125,
,10849295.45,4370,28.3964500427246,89999.3984375,90.0139999389648,272.952124023437,99.9020004272461,337.673592529297,99.9020004272461,610.625268554688,99.9020004272461,,,0.0376102051909746,0.0458313843399532,0.0833520476337141,,25,272.952124023437,337.673592529297,610.625268554688,
,10849373.75,4370,27.0888500213623,89999.3984375,90.0139999389648,274.046199951172,99.9020004272461,338.981804199219,99.9020004272461,613.027373046875,99.9020004272461,,,0.0426097055340024,0.0501125450555032,0.0920616229283653,,25,274.046199951172,338.981804199219,613.027373046875,
,10849450.98,4370,25.8050003051758,89999.3984375,90.0139999389648,275.198986816406,99.9020004272461,340.366749267578,99.9020004272461,615.569904785156,99.9020004272461,,,0.0488586734042526,0.0600280142339204,0.111201240935756,,25,275.198986816406,340.366749267578,615.569904785156,
,10849535.17,4370,24.405650138855,89999.3984375,90.0139999389648,276.485944824219,99.9020004272461,341.908087158203,99.9020004272461,618.398234863281,99.9020004272461,,,0.0427767086833065,0.052204960937387,0.094872290988155,,25,276.485944824219,341.908087158203,618.398234863281,
,10849607.17,4370,23.2016000747681,89999.3984375,90.0139999389648,277.650694580078,99.9020004272461,343.293638916016,99.9020004272461,620.943569335937,99.9020004272461,,,0.0452859638981666,0.0538618715642927,0.100124756993968,,25,277.650694580078,343.293638916016,620.943569335937,
,10849685.17,4370,21.8990497589111,89999.3984375,90.0139999389648,278.938935546875,99.9020004272461,344.846058349609,99.9020004272461,623.774946289063,99.9020004272461,,,0.0486059970145167,0.0572828443588596,0.106681883202955,,25,278.938935546875,344.846058349609,623.774946289063,
,10849756.47,4370,20.699200630188,89999.3984375,90.0139999389648,280.169748535156,99.9020004272461,346.310339355469,99.9020004272461,626.478605957031,99.9020004272461,,,0.0571811571570823,0.0680070961036875,0.124997125905493,,25,280.169748535156,346.310339355469,626.478605957031,
,10849846.28,4370,19.2079000473022,89999.3984375,90.0139999389648,281.771840820312,99.9020004272461,348.231129150391,99.9020004272461,630.001740722656,99.9020004272461,,,0.0519414090918913,0.0637680238599267,0.114675943003228,,25,281.771840820312,348.231129150391,630.001740722656,
,10849924.66,4370,17.9040994644165,89999.3984375,90.0139999389648,283.20533203125,99.9020004272461,349.957816162109,99.9020004272461,633.15306640625,99.9020004272461,,,0.0525944787725047,0.0636726708541612,0.118138400652816,,25,283.20533203125,349.957816162109,633.15306640625,
,10850009.53,4370,16.4906997680664,89999.3984375,90.0139999389648,284.823923339844,99.9020004272461,351.899638671875,99.9020004272461,636.71451171875,99.9020004272461,,,0.0576114002550094,0.0691417570959299,0.124913753291507,,25,284.823923339844,351.899638671875,636.71451171875,
,10850080.89,4370,15.3013501167297,89999.3984375,90.0139999389648,286.273493652344,99.9020004272461,353.629561767578,99.9020004272461,639.902807617187,99.9020004272461,,,0.0576638492709057,0.0689527118211946,0.128330771545811,,25,286.273493652344,353.629561767578,639.902807617187,
,10850153.59,4370,14.0893001556396,89999.3984375,90.0139999389648,287.791801757812,99.9020004272461,355.453065185547,99.9020004272461,643.247387695312,99.9020004272461,,,0.0602553766602902,0.0754557105172847,0.134627899425294,,25,287.791801757812,355.453065185547,643.247387695312,
,10850224.95,4370,12.8997502326965,89999.3984375,90.0139999389648,289.364898681641,99.9020004272461,357.351104736328,99.9020004272461,646.725202636719,99.9020004272461,,,0.0655630301128527,0.0795145270815161,0.144237775525696,,25,289.364898681641,357.351104736328,646.725202636719,
,10850309.41,4370,11.4953999519348,89999.3984375,90.0139999389648,291.383284912109,99.9020004272461,359.773681640625,99.9020004272461,651.144853515625,99.9020004272461,,,0.0708376037482055,0.085211459938061,0.15708380787518,,25,291.383284912109,359.773681640625,651.144853515625,
,10850380.48,4370,10.3022003173828,89999.3984375,90.0139999389648,293.201759033203,99.9020004272461,361.960959472656,99.9020004272461,655.148857421875,99.9020004272461,,,0.0775126550823634,0.0924081768461974,0.167895196318355,,25,293.201759033203,361.960959472656,655.148857421875,
,10850462.58,4370,8.97499990463257,89999.3984375,90.0139999389648,295.411612548828,99.9020004272461,364.615639648437,99.9020004272461,660.016579589844,99.9020004272461,,,0.0800870370339693,0.0986127797641193,0.178236700183982,,25,295.411612548828,364.615639648437,660.016579589844,
,10850538.70,4370,7.79199981689453,89999.3984375,90.0139999389648,297.608358154297,99.9020004272461,367.257191162109,99.9020004272461,664.878513183594,99.9020004272461,,,0.0892307924289308,0.105313543272219,0.195144526849739,,25,297.608358154297,367.257191162109,664.878513183594,
,10850614.13,4370,6.59934997558594,89999.3984375,90.0139999389648,300.151953125,99.9020004272461,370.302546386719,99.9020004272461,670.452719726562,99.9020004272461,,,0.100339343990617,0.12195323753913,0.222024062337605,,25,300.151953125,370.302546386719,670.452719726562,
,10850691.66,4370,5.38455009460449,89999.3984375,90.0139999389648,303.092780761719,99.9020004272461,373.860285644531,99.9020004272461,676.968447265625,99.9020004272461,,,0.121340337868694,0.150476290503141,0.273199966089135,,25,303.092780761719,373.860285644531,676.968447265625,
,10850767.36,4370,4.20374989509583,89999.3984375,90.0139999389648,306.574556884766,99.9020004272461,378.053543701172,99.9020004272461,684.647939453125,99.9020004272461,,,0.15685481361343,0.187235174099667,0.345814692616837,,25,306.574556884766,378.053543701172,684.647939453125,
,10850851.13,4370,2.89330005645752,89999.3984375,90.0139999389648,311.466553955078,99.9020004272461,383.946168212891,99.9020004272461,695.438957519531,99.9020004272461,,,0.18884506779783,0.227902305509125,0.41714889551682,,25,311.466553955078,383.946168212891,695.438957519531,
,10850979.20,4370,2.08704996109009,89999.3984375,90.0139999389648,315.163052978516,99.9020004272461,388.388858642578,99.9020004272461,703.520773925781,99.9020004272461,,,0.210206153498036,0.256612061200338,0.472454417968458,,25,315.163052978516,388.388858642578,703.520773925781,
,10851052.97,4370,3.30655002593994,89999.3984375,90.0139999389648,309.809790039062,99.9020004272461,381.928665771484,99.9020004272461,691.765698242187,99.9020004272461,,,0.189908677683947,0.229223262127048,0.415069533099092,,25,309.809790039062,381.928665771484,691.765698242187,
,10851130.95,4370,4.59455013275146,89999.3984375,90.0139999389648,305.356936035156,99.9020004272461,376.573367919922,99.9020004272461,681.909111328125,99.9020004272461,,,0.144884756858202,0.174221548449007,0.317080628708646,,25,305.356936035156,376.573367919922,681.909111328125,
,10851209.48,4370,5.91455006599426,89999.3984375,90.0139999389648,301.807420654297,99.9020004272461,372.298548583984,99.9020004272461,674.089006347656,99.9020004272461,,,0.12145641899216,0.144560761354603,0.268123766923644,,25,301.807420654297,372.298548583984,674.089006347656,
,10851280.66,4370,7.09395003318787,89999.3984375,90.0139999389648,299.130421142578,99.9020004272461,369.095717773438,99.9020004272461,668.224284667969,99.9020004272461,,,0.101931982501858,0.124079435389809,0.225230402809727,,25,299.130421142578,369.095717773438,668.224284667969,
,10851358.72,4370,8.39489984512329,89999.3984375,90.0139999389648,296.574359130859,99.9020004272461,366.0057421875,99.9020004272461,662.594248046875,99.9020004272461,,,0.0890314048315027,0.10494854879815,0.193652647369751,,25,296.574359130859,366.0057421875,662.594248046875,
,10851437.03,4370,9.70009994506836,89999.3984375,90.0139999389648,294.290533447266,99.9020004272461,363.258137207031,99.9020004272461,657.535532226563,99.9020004272461,,,0.0782450802731489,0.0951282477288305,0.173634358667102,,25,294.290533447266,363.258137207031,657.535532226563,
,10851508.73,4370,10.9024000167847,89999.3984375,90.0139999389648,292.384505615234,99.9020004272461,360.969943847656,99.9020004272461,653.364143066406,99.9020004272461,,,0.0752534647278787,0.090111315677753,0.16596903743337,,25,292.384505615234,360.969943847656,653.364143066406,
,10851580.66,4370,12.0934996604919,89999.3984375,90.0139999389648,290.628752441406,99.9020004272461,358.861334228516,99.9020004272461,649.478884277344,99.9020004272461,,,0.0697992657877135,0.0830323580957037,0.150544587428114,,25,290.628752441406,358.861334228516,649.478884277344,
,10851652.89,4370,13.2972497940063,89999.3984375,90.0139999389648,288.964029541016,99.9020004272461,356.87099609375,99.9020004272461,645.835559082031,99.9020004272461,,,0.0637730336979977,0.0779341320049775,0.139713652678653,,25,288.964029541016,356.87099609375,645.835559082031,
,10851725.02,4370,14.5020499229431,89999.3984375,90.0139999389648,287.402318115234,99.9020004272461,354.9862109375,99.9020004272461,642.381884765625,99.9020004272461,,,0.0602510347447203,0.0720651395276766,0.134795569551859,,25,287.402318115234,354.9862109375,642.381884765625,
,10851797.13,4370,15.7009501457214,89999.3984375,90.0139999389648,285.91328125,99.9020004272461,353.211892089844,99.9020004272461,639.125991210938,99.9020004272461,,,0.0588126093617215,0.0691562347256751,0.126874794086339,,25,285.91328125,353.211892089844,639.125991210938,
,10851868.64,4370,16.8959503173828,89999.3984375,90.0139999389648,284.494194335937,99.9020004272461,351.507584228516,99.9020004272461,636.000725097656,99.9020004272461,,,0.0546920586340037,0.0643655819591217,0.118685490340494,,25,284.494194335937,351.507584228516,636.000725097656,
,10851941.66,4370,18.1042003631592,89999.3984375,90.0139999389648,283.118443603516,99.9020004272461,349.846539306641,99.9020004272461,632.972854003906,99.9020004272461,,,0.0534022163849201,0.0631901171922801,0.115348824244247,,25,283.118443603516,349.846539306641,632.972854003906,
,10852013.58,4370,19.3072500228882,89999.3984375,90.0139999389648,281.812769775391,99.9020004272461,348.283460693359,99.9020004272461,630.101389160156,99.9020004272461,,,0.0509166962958815,0.0628927130992984,0.112661926774054,,25,281.812769775391,348.283460693359,630.101389160156,
,10852085.52,4370,20.5091495513916,89999.3984375,90.0139999389648,280.548033447266,99.9020004272461,346.765885009766,99.9020004272461,627.30630859375,99.9020004272461,,,0.0496192699330084,0.0603267515913162,0.109208159623967,,25,280.548033447266,346.765885009766,627.30630859375,
,10852157.75,4370,21.7110500335693,89999.3984375,90.0139999389648,279.309777832031,99.9020004272461,345.283564453125,99.9020004272461,624.584055175781,99.9020004272461,,,0.0490032623946869,0.0580262940248695,0.10812154999625,,25,279.309777832031,345.283564453125,624.584055175781,
,10852228.98,4370,22.8978500366211,89999.3984375,90.0139999389648,278.122431640625,99.9020004272461,343.86701171875,99.9020004272461,621.987756347656,99.9020004272461,,,0.0473973178662418,0.0547227584850898,0.103167514792913,,25,278.122431640625,343.86701171875,621.987756347656,
,10852301.05,4370,24.1009998321533,89999.3984375,90.0139999389648,276.976932373047,99.9020004272461,342.495695800781,99.9020004272461,619.469040527344,99.9020004272461,,,0.0451443210899802,0.0542667559878419,0.10066584455856,,25,276.976932373047,342.495695800781,619.469040527344,
,10852373.09,4370,25.3164005279541,89999.3984375,90.0139999389648,275.839044189453,99.9020004272461,341.124587402344,99.9020004272461,616.970773925781,99.9020004272461,,,0.0445038031511516,0.0549987634534541,0.0993391323133688,,25,275.839044189453,341.124587402344,616.970773925781,
,10852451.16,4370,26.6050996780396,89999.3984375,90.0139999389648,274.6608984375,99.9020004272461,339.725771484375,99.9020004272461,614.385498046875,99.9020004272461,,,0.0433113078926235,0.0507033226135797,0.0939965201361539,,25,274.6608984375,339.725771484375,614.385498046875,
,10852522.92,4370,27.7978000640869,89999.3984375,90.0139999389648,273.635008544922,99.9020004272461,338.491965332031,99.9020004272461,612.133371582031,99.9020004272461,,,0.0430455616849197,0.0507364840872967,0.0920782602019267,,25,273.635008544922,338.491965332031,612.133371582031,
,10852594.92,4370,29.0016508102417,89999.3984375,90.0139999389648,272.621311035156,99.9020004272461,337.282623291016,99.9020004272461,609.895959472656,99.9020004272461,,,0.0419591724346102,0.0500190467442813,0.0938746020418407,,25,272.621311035156,337.282623291016,609.895959472656,
,10852667.34,4370,30.2045001983643,89999.3984375,90.0139999389648,271.636976318359,99.9020004272461,336.105826416016,99.9020004272461,607.7486328125,99.9020004272461,,,0.0391058282908282,0.0452644408198249,0.0842499709100321,,25,271.636976318359,336.105826416016,607.7486328125,
,10852739.00,4370,31.4039001464844,89999.3984375,90.0139999389648,270.683731689453,99.9020004272461,334.975246582031,99.9020004272461,605.656748046875,99.9020004272461,,,0.0373320855035839,0.0444532306150626,0.0828394497208707,,25,270.683731689453,334.975246582031,605.656748046875,
,10852810.94,4370,32.6049003601074,89999.3984375,90.0139999389648,269.780567626953,99.9020004272461,333.898615722656,99.9020004272461,603.677060546875,99.9020004272461,,,0.0361305130165649,0.0429742392032982,0.0795166880285339,,25,269.780567626953,333.898615722656,603.677060546875,
,10852882.89,4370,33.7966499328613,89999.3984375,90.0139999389648,268.887655029297,99.9020004272461,332.828465576172,99.9020004272461,601.720568847656,99.9020004272461,,,0.0351479602517359,0.0406819399948186,0.0759648660804768,,25,268.887655029297,332.828465576172,601.720568847656,
,10852955.31,4370,35.005350112915,89999.3984375,90.0139999389648,268.036624755859,99.9020004272461,331.81466796875,99.9020004272461,599.843391113281,99.9020004272461,,,0.0330460427346559,0.0390915369725718,0.0715692078819068,,25,268.036624755859,331.81466796875,599.843391113281,
,10853027.00,4370,36.1997509002686,89999.3984375,90.0139999389648,267.225754394531,99.9020004272461,330.849885253906,99.9020004272461,598.068515625,99.9020004272461,,,0.033267701467942,0.0375345365209082,0.0705166038186491,,25,267.225754394531,330.849885253906,598.068515625,
,10853098.48,4370,37.392599105835,89999.3984375,90.0139999389648,266.449442138672,99.9020004272461,329.927872314453,99.9020004272461,596.371149902344,99.9020004272461,,,0.0302871521140562,0.0374848666100104,0.0679695368281401,,25,266.449442138672,329.927872314453,596.371149902344,
,10853171.75,4370,38.6131992340088,89999.3984375,90.0139999389648,265.680828857422,99.9020004272461,329.023609619141,99.9020004272461,594.703659667969,99.9020004272461,,,0.029717314859333,0.0334325613640082,0.0628164043157568,,25,265.680828857422,329.023609619141,594.703659667969,
,10853243.39,4370,39.8094501495361,89999.3984375,90.0139999389648,264.953511962891,99.9020004272461,328.160561523437,99.9020004272461,593.112504882812,99.9020004272461,,,0.0281793623530684,0.0334261045029332,0.0618838692210852,,25,264.953511962891,328.160561523437,593.112504882812,
,10853315.72,4370,41.0128993988037,89999.3984375,90.0139999389648,264.268214111328,99.9020004272461,327.346208496094,99.9020004272461,591.609345703125,99.9020004272461,,,0.0271470333133303,0.033361014610549,0.0587092904526411,,25,264.268214111328,327.346208496094,591.609345703125,
,10853392.63,4370,42.2959003448486,89999.3984375,90.0139999389648,263.570538330078,99.9020004272461,326.522578125,99.9020004272461,590.087465820312,99.9020004272461,,,0.0256715042952322,0.0304631004460177,0.0561429586031024,,25,263.570538330078,326.522578125,590.087465820312,
,10853465.30,4370,43.5037498474121,89999.3984375,90.0139999389648,262.938647460937,99.9020004272461,325.774342041016,99.9020004272461,588.709357910156,99.9020004272461,,,0.0253729847807312,0.029825601808778,0.0532437247826129,,25,262.938647460937,325.774342041016,588.709357910156,
,10853537.31,4370,44.7074489593506,89999.3984375,90.0139999389648,262.332349853516,99.9020004272461,325.067758789063,99.9020004272461,587.401596679687,99.9020004272461,,,0.023786919124161,0.0276645932848575,0.0497493793256614,,25,262.332349853516,325.067758789063,587.401596679687,
,10853609.52,4370,45.9113998413086,89999.3984375,90.0139999389648,261.775343017578,99.9020004272461,324.414993896484,99.9020004272461,586.190554199219,99.9020004272461,,,0.0216091697801689,0.0268972610816716,0.0489937001536055,,25,261.775343017578,324.414993896484,586.190554199219,
,10853681.44,4370,47.1068496704102,89999.3984375,90.0139999389648,261.247674560547,99.9020004272461,323.796614990234,99.9020004272461,585.042221679687,99.9020004272461,,,0.0209077919569259,0.0243804500582795,0.0443081985886649,,25,261.247674560547,323.796614990234,585.042221679687,
,10853753.56,4370,48.3124504089355,89999.3984375,90.0139999389648,260.734973144531,99.9020004272461,323.195845947266,99.9020004272461,583.929213867188,99.9020004272461,,,0.0194882302809968,0.0219756044953002,0.0428497824129631,,25,260.734973144531,323.195845947266,583.929213867188,
,10853824.80,4370,49.499698638916,89999.3984375,90.0139999389648,260.275372314453,99.9020004272461,322.658186035156,99.9020004272461,582.928664550781,99.9020004272461,,,0.0196059114986341,0.0208842882494057,0.0394654140064487,,25,260.275372314453,322.658186035156,582.928664550781,
,10853861.67,4370,50.0368995666504,89999.3984375,90.0139999389648,260.047091064453,99.9020004272461,322.392614746094,99.9020004272461,582.435581054688,99.9020004272461,,,0.0161080921010413,0.0187515183668473,0.0341439059839277,,25,260.047091064453,322.392614746094,582.435581054688,