File: Examples/data/Add-135-15Feb2019-1.dat
[Header]
TITLE,Addenda Pate thermique
BYAPP,HeatCapacity,3.5.4,1.5
INFO,0,MASS:Sample Mass (mg)
INFO,0,MASSERR:Sample Mass Error (mg)
INFO,0,MOLWGHT:Formula Weight (g/mole)
INFO,0,ATOMS:Atoms per Formula Unit
INFO,PPMS Heat Capacity Option 3.5.4 Build 1,APPNAME
DATATYPE,TIME,1
STARTUPAXIS, X, 2, LINEAR, AUTO
STARTUPAXIS, Y1, 3, LINEAR, AUTO
[Data]
Time Stamp (Seconds),PPMS Status (Code),Puck Temp (Kelvin),System Temp (Kelvin),Field (Oersted),Pressure (Torr),Sample Temp (Kelvin),Temp Rise (Kelvin),Samp HC (µJ/K),Samp HC Err (µJ/K),Addenda HC (µJ/K),Addenda HC Err (µJ/K),Total HC (µJ/K),Total HC Err (µJ/K),Fit Deviation (ChiSquare),Time Const tau1 (seconds),Time Const tau2 (seconds),Sample Coupling (Percent),Debye Temp (Kelvin),Debye Temp Err (Kelvin),Cal Correction (Factor),Therm Resist (Ohms),Htr Resist (Ohms),Puck Resist (Ohms),Wire Cond (W/K),Meas Time (seconds),Temp Squared (K^2),Samp HC/Temp (µJ/K/K),Addenda Offset HC (µJ/K)
17800462.38,5905,2.00668,2.1086,-0.137,0.0002575,2.1044531,0.039598415,0,0,0.28569069,0.00152,0.28569069,0.00152,3.1394774,0.14014636,0,100,,,1,,,,2.0385E-6,0.289585,4.4287231,0,0
17800480.22,5905,2.00579,2.1077,-0.137,0.0002733,2.1029372,0.038923931,0,0,0.28501024,0.001432,0.28501024,0.001432,2.5537225,0.14024163,0,100,,,1,,,,2.0323E-6,0.2802927,4.4223448,0,0
17800497.78,5905,2.00525,2.1075,-0.137,0.0002669,2.1027136,0.038980868,0,0,0.28381058,0.00176,0.28381058,0.00176,1.7762195,0.13979391,0,100,,,1,,,,2.0302E-6,0.2804833,4.4214045,0,0
17800835.58,5905,2.49006,2.5737,-0.137,0.0002575,2.5702696,0.041846325,0,0,0.4425037,0.00334,0.4425037,0.00334,1.5386357,0.16533175,0,100,,,1,,,,2.6765E-6,0.2795878,6.6062857,0,0
17800853.39,5905,2.49102,2.5753,-0.137,0.0002701,2.5735732,0.046682957,0,0,0.44420577,0.002069,0.44420577,0.002069,1.2614015,0.16583948,0,100,,,1,,,,2.6785E-6,0.3306635,6.6232789,0,0
17800870.97,5905,2.49213,2.5749,-0.137,0.0002701,2.5748,0.04677898,0,0,0.44424645,0.002623,0.44424645,0.002623,2.0496284,0.16576268,0,100,,,1,,,,2.68E-6,0.331679,6.629595,0,0
17801218.11,5905,2.9864,3.0947,-0.137,0.0002606,3.0784196,0.04940258,0,0,0.69226818,0.002558,0.69226818,0.002558,1.2740416,0.20478823,0,100,,,1,,,,3.3804E-6,0.3315254,9.4766675,0,0
17801235.88,5905,2.98759,3.0966,-0.137,0.0002514,3.0839632,0.056781985,0,0,0.69397537,0.002728,0.69397537,0.002728,1.0917043,0.20520675,0,100,,,1,,,,3.3818E-6,0.4095765,9.5108287,0,0
17801253.48,5905,2.98896,3.0983,-0.137,0.0002799,3.0854516,0.05675491,0,0,0.69612765,0.002604,0.69612765,0.002604,1.3826109,0.20544828,0,100,,,1,,,,3.3883E-6,0.4104135,9.5200117,0,0
17801604.78,5905,3.48514,3.6181,-0.137,0.0002514,3.5910395,0.059478708,0,0,1.0295612,0.003732,1.0295612,0.003732,1.9145739,0.25140726,0,100,,,1,,,,4.0952E-6,0.4108966,12.895565,0,0
17801622.69,5905,3.48651,3.618,-0.137,0.0002637,3.5962873,0.067632457,0,0,1.035027,0.003245,1.035027,0.003245,3.2328564,0.25293017,0,100,,,1,,,,4.0921E-6,0.5028145,12.933283,0,0
17801640.47,5905,3.48762,3.6186,-0.137,0.0002575,3.5975796,0.068043043,0,0,1.0337425,0.0028,1.0337425,0.0028,1.8074182,0.25249364,0,100,,,1,,,,4.0941E-6,0.5058603,12.942579,0,0
17801992.63,5905,3.98262,4.1366,-0.137,0.0002637,4.1041793,0.068251478,0,0,1.5041607,0,1.5041607,0,3.1748407,0.29947038,0,100,,,1,,,,5.0227E-6,0.5049873,16.844288,0,0
17802010.58,5905,3.98458,4.1378,-0.137,0.0002701,4.1091795,0.076105896,0,0,1.5127556,0.003791,1.5127556,0.003791,7.3725147,0.30345951,0,100,,,1,,,,4.985E-6,0.5989408,16.885356,0,0
17802028.64,5905,3.98576,4.1379,-0.137,0.0002544,4.1118241,0.076525791,0,0,1.5185421,0.003706,1.5185421,0.003706,5.6382528,0.3034553,0,100,,,1,,,,5.0042E-6,0.606919,16.907098,0,0
17802349.27,5905,4.4809,4.627,-0.137,0.0002575,4.5998432,0.077258536,0,0,2.1025554,0.005694,2.1025554,0.005694,3.4929284,0.3589624,0,100,,,1,,,,5.8573E-6,0.6069106,21.158557,0,0
17802367.61,5905,4.48274,4.6295,-0.137,0.0002606,4.6061302,0.086137221,0,0,2.1108974,0.00533,2.1108974,0.00533,3.9247599,0.36356314,0,100,,,1,,,,5.8061E-6,0.7179248,21.216435,0,0
17802385.75,5905,4.48397,4.6316,-0.137,0.0002669,4.6081125,0.08692463,0,0,2.1091915,0.005553,2.1091915,0.005553,3.7037722,0.36330526,0,100,,,1,,,,5.8056E-6,0.7271263,21.234701,0,0
17802705.63,5905,4.97843,5.1396,-0.137,0.0002701,5.108673,0.088890818,0,0,2.7732595,0.006919,2.7732595,0.006919,2.6779733,0.41492102,0,100,,,1,,,,6.6838E-6,0.7266105,26.09854,0,0
17802723.81,5905,4.98092,5.1408,-0.137,0.0002484,5.1146679,0.096589169,0,0,2.7868772,0.007536,2.7868772,0.007536,3.7512958,0.4184471,0,100,,,1,,,,6.66E-6,0.829842,26.159828,0,0
17802741.97,5905,4.98238,5.142,-0.137,0.0002575,5.1167395,0.09723008,0,0,2.7839388,0.006591,2.7839388,0.006591,2.9618742,0.41830959,0,100,,,1,,,,6.6552E-6,0.8368942,26.181023,0,0
17803058.25,5905,5.477,5.6498,-0.137,0.0002701,5.6168348,0.099170425,0,0,3.5779117,0.007624,3.5779117,0.007624,2.3596236,0.47617805,0,100,,,1,,,,7.5138E-6,0.8366192,31.548833,0,0
17803077.47,5905,5.47932,5.652,-0.137,0.0002606,5.6234701,0.10733272,0,0,3.5912587,0.008421,3.5912587,0.008421,2.0319155,0.47780922,0,100,,,1,,,,7.5161E-6,0.9523561,31.623416,0,0
17803096.63,5905,5.48112,5.6526,-0.137,0.0002544,5.6257663,0.10763543,0,0,3.5884338,0.008204,3.5884338,0.008204,3.5161645,0.47712516,0,100,,,1,,,,7.5209E-6,0.9556184,31.649246,0,0
17803406.67,5905,5.97563,6.157,-0.137,0.0002575,6.1241163,0.10940924,0,0,4.510934,0.01213,4.510934,0.01213,2.6218023,0.53543391,0,100,,,1,,,,8.4248E-6,0.9542503,37.504801,0,0
17803429.59,5905,5.97837,6.1584,-0.137,0.0002575,6.1311831,0.11726306,0,0,4.5200888,0.01086,4.5200888,0.01086,1.5562668,0.53449469,0,100,,,1,,,,8.4568E-6,1.070868,37.591406,0,0
17803450.67,5905,5.9809,6.1603,-0.137,0.0002733,6.1335608,0.11721566,0,0,4.5283001,0.01122,4.5283001,0.01122,2.6263775,0.53591387,0,100,,,1,,,,8.4497E-6,1.068989,37.620568,0,0
17803752.14,5905,6.47305,6.6605,-0.137,0.0002514,6.6300889,0.11940386,0,0,5.5654593,0.01163,5.5654593,0.01163,4.1977645,0.59091146,0,100,,,1,,,,9.4184E-6,1.071828,43.958079,0,0
17803772.33,5905,6.47673,6.6645,-0.137,0.0002637,6.6370077,0.12695797,0,0,5.5858758,0.01143,5.5858758,0.01143,5.4022171,0.59638297,0,100,,,1,,,,9.3663E-6,1.181823,44.049871,0,0
17803792.53,5905,6.47857,6.6661,-0.137,0.0002544,6.6399063,0.12773062,0,0,5.5834163,0.01148,5.5834163,0.01148,4.098106,0.5953431,0,100,,,1,,,,9.3785E-6,1.192766,44.088356,0,0
17804089.31,5905,6.97223,7.1653,-0.137,0.0002544,7.1352155,0.13022723,0,0,6.7257353,0.01519,6.7257353,0.01519,4.4484427,0.65249777,0,100,,,1,,,,1.0308E-5,1.190686,50.9113,0,0
17804109.78,5905,6.9752,7.1683,-0.137,0.0002669,7.1425434,0.13765056,0,0,6.744265,0.01457,6.744265,0.01457,3.4736298,0.65401511,0,100,,,1,,,,1.0312E-5,1.304996,51.015927,0,0
17804130.38,5905,6.97782,7.1698,-0.137,0.0002544,7.1456388,0.13788695,0,0,6.752535,0.01342,6.752535,0.01342,5.5686345,0.65433153,0,100,,,1,,,,1.032E-5,1.30803,51.060153,0,0
17804416.31,5905,7.46893,7.6662,-0.137,0.0002544,7.6394251,0.13974697,0,0,8.0512221,0.0169,8.0512221,0.0169,2.7945209,0.70972682,0,100,,,1,,,,1.1344E-5,1.308663,58.360816,0,0
17804437.14,5905,7.47336,7.6699,-0.137,0.0002575,7.6465609,0.14666061,0,0,8.0773856,0.01797,8.0773856,0.01797,5.3175624,0.71167063,0,100,,,1,,,,1.135E-5,1.419454,58.469894,0,0
17804457.64,5905,7.47775,7.6726,-0.137,0.0002701,7.6499645,0.14705268,0,0,8.0882583,0.01831,8.0882583,0.01831,5.5723622,0.71350609,0,100,,,1,,,,1.1336E-5,1.423341,58.521957,0,0
17804734.25,5905,7.96771,8.1664,-0.137,0.0002669,8.141083,0.1497835,0,0,9.4816502,0.02084,9.4816502,0.02084,3.0401098,0.76960249,0,100,,,1,,,,1.232E-5,1.427012,66.277232,0,0
17804756.14,5905,7.97162,8.169,-0.137,0.0002669,8.1481199,0.15668817,0,0,9.4890531,0.02073,9.4890531,0.02073,3.7043884,0.767534,0,100,,,1,,,,1.2363E-5,1.539205,66.391857,0,0
17804778.06,5905,7.97537,8.1721,-0.137,0.0002669,8.1514959,0.15641007,0,0,9.5059054,0.01962,9.5059054,0.01962,5.8768127,0.76896252,0,100,,,1,,,,1.2362E-5,1.535068,66.446886,0,0
17805043.83,5905,8.46523,8.6669,-0.137,0.0002669,8.642198,0.15972717,0,0,10.969443,0.02558,10.969443,0.02558,3.6080417,0.82784512,0,100,,,1,,,,1.3251E-5,1.537925,74.687587,0,0
17805065.77,5905,8.4694,8.6698,-0.137,0.0002733,8.6498188,0.1667025,0,0,11.010071,0.02414,11.010071,0.02414,2.9593017,0.82985927,0,100,,,1,,,,1.3267E-5,1.65569,74.819366,0,0
17805087.77,5905,8.47349,8.6743,-0.137,0.0002606,8.6537044,0.16706104,0,0,11.022199,0.02481,11.022199,0.02481,2.6113428,0.82957985,0,100,,,1,,,,1.3286E-5,1.659719,74.886599,0,0
17805348.42,5905,8.96324,9.169,-0.137,0.0002701,9.1475462,0.16921009,0,0,12.692404,0.02633,12.692404,0.02633,11.393588,0.8871471,0,100,,,1,,,,1.4307E-5,1.65916,83.677602,0,0
17805370.05,5905,8.96886,9.1717,-0.137,0.0002701,9.156072,0.17637798,0,0,12.719284,0.0247,12.719284,0.0247,8.4932857,0.88991275,0,100,,,1,,,,1.4293E-5,1.774294,83.833654,0,0
17805392.42,5905,8.97246,9.1745,-0.137,0.0002637,9.1598148,0.17652272,0,0,12.733482,0.02586,12.733482,0.02586,12.121213,0.88724259,0,100,,,1,,,,1.4352E-5,1.779826,83.902207,0,0
17805648,5905,9.46265,9.668,-0.137,0.0002799,9.6508186,0.17871263,0,0,14.522775,0.02845,14.522775,0.02845,8.3404938,0.94693958,0,100,,,1,,,,1.5337E-5,1.774485,93.1383,0,0
17805670.16,5905,9.46715,9.6713,-0.137,0.0002484,9.6589502,0.18590993,0,0,14.549824,0.02901,14.549824,0.02901,18.880433,0.94827025,0,100,,,1,,,,1.5344E-5,1.893879,93.295319,0,0
17805692.16,5905,9.47161,9.6745,-0.137,0.0002544,9.6623853,0.18602564,0,0,14.564926,0.02713,14.564926,0.02713,11.199746,0.94761911,0,100,,,1,,,,1.537E-5,1.89654,93.361689,0,0
17806292.91,5905,10.0081,10.1749,-0.137,0.0002733,10.18351,0.18927344,0,0,16.534373,0.03299,16.534373,0.03299,17.145048,1.0067709,0,100,,,1,,,,1.6423E-5,1.895238,103.70387,0,0
17806315.09,5905,10.0085,10.1728,-0.137,0.0002701,10.185745,0.19634491,0,0,16.533856,0.03035,16.533856,0.03035,7.7196127,1.0063327,0,100,,,1,,,,1.643E-5,2.013542,103.7494,0,0
17806337.53,5905,10.0086,10.1691,-0.137,0.0002575,10.185702,0.19613534,0,0,16.527926,0.02821,16.527926,0.02821,7.2034485,1.0036801,0,100,,,1,,,,1.6467E-5,2.012665,103.74852,0,0
17806616.13,5905,10.9732,11.1212,-0.137,0.0002701,11.147144,0.21475522,0,0,20.47984,0.04137,20.47984,0.04137,9.827461,1.1236433,0,100,,,1,,,,1.8226E-5,2.219456,124.25882,0,0
17806638.56,5905,10.976,11.1225,-0.137,0.0002484,11.151007,0.21609692,0,0,20.491676,0.04237,20.491676,0.04237,11.43936,1.121507,0,100,,,1,,,,1.8272E-5,2.247287,124.34497,0,0
17806661.08,5905,10.9814,11.1236,-0.137,0.0002575,11.154463,0.21585431,0,0,20.521144,0.04284,20.521144,0.04284,9.4927633,1.1225338,0,100,,,1,,,,1.8281E-5,2.243014,124.42204,0,0
17806906.17,5905,11.9716,12.0972,-0.137,0.0002733,12.134827,0.22082211,0,0,25.066497,0.05417,25.066497,0.05417,10.581865,1.2398577,0,100,,,1,,,,2.0217E-5,2.245068,147.25403,0,0
17806928.98,5905,11.9753,12.0991,-0.137,0.0002799,12.145835,0.23475859,0,0,25.134827,0.05602,25.134827,0.05602,13.71531,1.2408673,0,100,,,1,,,,2.0256E-5,2.479715,147.5213,0,0
17806951.75,5905,11.98,12.1013,-0.137,0.0002606,12.149976,0.23500649,0,0,25.149759,0.05635,25.149759,0.05635,9.0458656,1.2414127,0,100,,,1,,,,2.0259E-5,2.481735,147.62191,0,0
17807198.2,5905,12.9736,13.0887,-0.137,0.0002606,13.139613,0.23928863,0,0,30.19197,0.07043,30.19197,0.07043,6.7559548,1.3625432,0,100,,,1,,,,2.2159E-5,2.482825,172.64942,0,0
17807222.61,5905,12.9789,13.0917,-0.137,0.0002669,13.15082,0.25430064,0,0,30.26042,0.05847,30.26042,0.05847,4.9482586,1.3696697,0,100,,,1,,,,2.2093E-5,2.725086,172.94407,0,0
17807247,5905,12.9817,13.0922,-0.137,0.0002575,13.1544,0.25475388,0,0,30.268509,0.05745,30.268509,0.05745,4.9081258,1.3669572,0,100,,,1,,,,2.2143E-5,2.739339,173.03824,0,0
17807494.06,5905,13.9735,14.084,-0.137,0.0002544,14.146614,0.26117163,0,0,35.782397,0.06613,35.782397,0.06613,9.8676796,1.4957347,0,100,,,1,,,,2.3923E-5,2.733914,200.12669,0,0
17807519.41,5905,13.9776,14.0878,-0.137,0.0002606,14.157473,0.27444604,0,0,35.868553,0.06727,35.868553,0.06727,19.126908,1.4966207,0,100,,,1,,,,2.3966E-5,2.991469,200.43404,0,0
17807543.64,5905,13.9822,14.0883,-0.137,0.0002544,14.161082,0.27481524,0,0,35.873928,0.06633,35.873928,0.06633,11.081435,1.4973131,0,100,,,1,,,,2.3959E-5,2.993241,200.53624,0,0
17807789.61,5905,14.9749,15.081,-0.137,0.0002733,15.152975,0.27979614,0,0,41.893764,0.08296,41.893764,0.08296,10.414454,1.6246351,0,100,,,1,,,,2.5787E-5,2.994626,229.61266,0,0
17807814.39,5905,14.9791,15.0846,-0.137,0.0002733,15.164264,0.29371311,0,0,41.982419,0.08891,41.982419,0.08891,16.28575,1.625115,0,100,,,1,,,,2.5834E-5,3.24927,229.95491,0,0
17807839.31,5905,14.9825,15.0852,-0.137,0.0002575,15.167632,0.2936874,0,0,41.99874,0.08475,41.99874,0.08475,16.652539,1.6241968,0,100,,,1,,,,2.5858E-5,3.25023,230.05705,0,0
17808088.09,5905,15.9765,16.0813,-0.137,0.0002799,16.158944,0.29759152,0,0,48.46355,0.108,48.46355,0.108,11.699124,1.7583951,0,100,,,1,,,,2.7561E-5,3.248394,261.11148,0,0
17808113.03,5905,15.9828,16.0824,-0.137,0.0002637,16.172525,0.31298071,0,0,48.553476,0.1093,48.553476,0.1093,9.2837712,1.758397,0,100,,,1,,,,2.7612E-5,3.51679,261.55058,0,0
17808138.38,5905,15.9895,16.0779,-0.137,0.0002637,16.176195,0.31310365,0,0,48.549889,0.107,48.549889,0.107,26.701402,1.7575245,0,100,,,1,,,,2.7624E-5,3.516794,261.66928,0,0
17808385.52,5905,16.9764,17.0724,-0.137,0.0002637,17.161243,0.31608212,0,0,55.378507,0.1337,55.378507,0.1337,13.139449,1.8912395,0,100,,,1,,,,2.9282E-5,3.515049,294.50825,0,0
17808411.81,5905,16.9803,17.0751,-0.137,0.0002606,17.173489,0.33235023,0,0,55.502118,0.1069,55.502118,0.1069,21.302879,1.9006636,0,100,,,1,,,,2.9201E-5,3.782479,294.92873,0,0
17808438.06,5905,16.9834,17.0778,-0.137,0.0002766,17.1772,0.33316799,0,0,55.513064,0.1046,55.513064,0.1046,27.164444,1.900582,0,100,,,1,,,,2.9208E-5,3.801327,295.0562,0,0
17808687.83,5905,17.9672,18.086,-0.137,0.0002637,18.16735,0.33822831,0,0,62.786638,0.1331,62.786638,0.1331,6.1863898,2.0436634,0,100,,,1,,,,3.0723E-5,3.801164,330.05259,0,0
17808714.61,5905,17.9713,18.0914,-0.137,0.0002733,18.181452,0.35339361,0,0,62.899196,0.1371,62.899196,0.1371,23.512417,2.0430942,0,100,,,1,,,,3.0786E-5,4.087327,330.56518,0,0
17808741.61,5905,17.9759,18.0961,-0.137,0.0002701,18.186656,0.35317724,0,0,62.933463,0.1321,62.933463,0.1321,27.227681,2.0430067,0,100,,,1,,,,3.0804E-5,4.086188,330.75445,0,0
17808992.14,5905,18.9785,19.0754,-0.137,0.0002766,19.179353,0.35661972,0,0,70.794707,0.1601,70.794707,0.1601,11.18176,2.1822383,0,100,,,1,,,,3.2441E-5,4.086013,367.84758,0,0
17809024.41,5905,18.9833,19.0799,-0.137,0.0002733,19.19264,0.37246628,0,0,70.886086,0.1639,70.886086,0.1639,12.126926,2.1845225,0,100,,,1,,,,3.2449E-5,4.364477,368.35743,0,0
17809056.41,5905,18.9848,19.0817,-0.137,0.0002575,19.197197,0.37267496,0,0,70.93956,0.1637,70.93956,0.1637,17.353801,2.184222,0,100,,,1,,,,3.2478E-5,4.369045,368.53237,0,0
17809312.17,5905,19.9548,20.0879,-0.137,0.0002637,20.170302,0.37569663,0,0,79.020679,0.2076,79.020679,0.2076,8.4891132,2.3315528,0,100,,,1,,,,3.3892E-5,4.368444,406.8411,0,0
17809344.38,5905,19.9558,20.1062,-0.137,0.0002766,20.189724,0.39247704,0,0,79.149341,0.2072,79.149341,0.2072,12.312556,2.3286099,0,100,,,1,,,,3.399E-5,4.663106,407.62495,0,0
17809376.63,5905,19.9609,20.1183,-0.137,0.0002733,20.198537,0.39241745,0,0,79.244038,0.1998,79.244038,0.1998,10.336178,2.3299843,0,100,,,1,,,,3.4011E-5,4.65722,407.98089,0,0
17809714.33,5905,21.9866,22.1154,-0.137,0.0002669,22.221776,0.42758944,0,0,97.297145,0.2549,97.297145,0.2549,37.031516,2.6506076,0,100,,,1,,,,3.6707E-5,5.119424,493.80733,0,0
17809749,5905,22.002,22.0969,-0.137,0.0002766,22.240834,0.4356239,0,0,97.391181,0.2459,97.391181,0.2459,7.8568134,2.6469852,0,100,,,1,,,,3.6793E-5,5.301215,494.6547,0,0
17809788.84,5905,21.9986,22.0881,-0.137,0.0002669,22.234685,0.43494395,0,0,97.243698,0.2216,97.243698,0.2216,3.0192116,2.6272034,0,100,,,1,,,,3.7014E-5,5.29397,494.38123,0,0
17810088.98,5905,23.9798,24.074,-0.137,0.0002669,24.207076,0.44084644,0,0,116.0509,0.3264,116.0509,0.3264,12.245094,2.9427714,0,100,,,1,,,,3.9436E-5,5.254407,585.98251,0,0
17810125.25,5905,23.9865,24.0754,-0.137,0.0002733,24.23199,0.47559496,0,0,116.34154,0.2746,116.34154,0.2746,66.036528,2.9547943,0,100,,,1,,,,3.9374E-5,5.885543,587.18936,0,0
17810161.44,5905,23.9889,24.0767,-0.137,0.0002799,24.236286,0.47661045,0,0,116.35283,0.2679,116.35283,0.2679,45.776784,2.9520677,0,100,,,1,,,,3.9414E-5,5.909589,587.39755,0,0
17810462.8,5905,25.9812,26.0737,-0.137,0.0002833,26.219933,0.48271421,0,0,137.08627,0.3719,137.08627,0.3719,13.507068,3.2713969,0,100,,,1,,,,4.1905E-5,5.904135,687.4849,0,0
17810500.31,5905,25.9866,26.0737,-0.137,0.0002766,26.244942,0.51602175,0,0,137.30076,0.3753,137.30076,0.3753,74.772517,3.2708595,0,100,,,1,,,,4.1977E-5,6.542794,688.79696,0,0
17810537.75,5905,25.9901,26.0737,-0.137,0.0002669,26.249965,0.51630242,0,0,137.35762,0.3673,137.35762,0.3673,31.768699,3.2703272,0,100,,,1,,,,4.2001E-5,6.541719,689.06069,0,0
17810841.09,5905,27.9551,28.1427,-0.137,0.0002799,28.213511,0.52050611,0,0,159.06141,0.5054,159.06141,0.5054,4.5150725,3.6074565,0,100,,,1,,,,4.4092E-5,6.540654,796.0022,0,0
17810881.23,5905,27.966,28.1373,-0.137,0.0002733,28.252082,0.55760819,0,0,159.58309,0.446,159.58309,0.446,23.193447,3.6193071,0,100,,,1,,,,4.4092E-5,7.214913,798.18011,0,0
17810921.45,5905,27.9822,28.1548,-0.137,0.0002733,28.263923,0.55869065,0,0,159.82585,0.4578,159.82585,0.4578,66.208019,3.6236469,0,100,,,1,,,,4.4106E-5,7.238614,798.84932,0,0
17811227.8,5905,29.9811,30.0842,-0.137,0.0002766,30.25079,0.5623624,0,0,182.85539,0.5511,182.85539,0.5511,13.630648,3.9459608,0,100,,,1,,,,4.634E-5,7.247294,915.11032,0,0
17811269.45,5905,29.9918,30.0795,-0.137,0.0002936,30.277053,0.59707186,0,0,183.28571,0.4921,183.28571,0.4921,13.48227,3.9595561,0,100,,,1,,,,4.6289E-5,7.891922,916.69995,0,0
17811312.22,5905,29.9942,30.0818,-0.137,0.0002799,30.283617,0.59713867,0,0,183.32961,0.4837,183.32961,0.4837,14.479115,3.9574332,0,100,,,1,,,,4.6325E-5,7.919112,917.09748,0,0
17811626,5905,31.9491,32.1503,-0.137,0.0002766,32.237349,0.60191682,0,0,208.06475,0.6769,208.06475,0.6769,2.2470089,4.3434088,0,100,,,1,,,,4.7904E-5,7.914866,1039.2467,0,0
17811669.05,5905,31.9707,32.1695,-0.137,0.0002867,32.27816,0.64067069,0,0,208.59619,0.6557,208.59619,0.6557,71.072188,4.3348213,0,100,,,1,,,,4.8121E-5,8.686818,1041.8796,0,0
17811720.03,5905,31.9833,32.1635,-0.137,0.0002833,32.298086,0.63933614,0,0,208.55083,0.6069,208.55083,0.6069,34.268359,4.30737,0,100,,,1,,,,4.8417E-5,8.669643,1043.1663,0,0
17812028.7,5905,33.9528,34.1467,-0.137,0.0002971,34.245662,0.63853318,0,0,234.00755,0.7769,234.00755,0.7769,2.760871,4.6663198,0,100,,,1,,,,5.0148E-5,8.61474,1172.7653,0,0
17812081.61,5905,33.9784,34.1711,-0.137,0.0002901,34.291244,0.67791373,0,0,234.83213,0.7141,234.83213,0.7141,4.024222,4.6928219,0,100,,,1,,,,5.0041E-5,9.33264,1175.8894,0,0
17812127.86,5905,33.9951,34.1441,-0.137,0.0003043,34.324973,0.67950871,0,0,235.12387,0.6955,235.12387,0.6955,28.203584,4.6807322,0,100,,,1,,,,5.0232E-5,9.385644,1178.2038,0,0
17812547.5,5905,35.9899,36.1585,-0.137,0.0003043,36.301536,0.67780362,0,0,262.17468,0.8407,262.17468,0.8407,1.3961421,5.0103416,0,100,,,1,,,,5.2327E-5,9.361464,1317.8015,0,0
17812602.36,5905,36.016,36.1448,-0.137,0.0002971,36.347856,0.71440153,0,0,263.06354,0.766,263.06354,0.766,10.824741,5.0445688,0,100,,,1,,,,5.2148E-5,10.02068,1321.1666,0,0
17812657.02,5905,36.0208,36.113,-0.137,0.0002867,36.36646,0.71747942,0,0,262.48955,0.6706,262.48955,0.6706,40.274977,5.0076474,0,100,,,1,,,,5.2418E-5,10.08914,1322.5194,0,0
17813083.67,5905,38.0059,38.1742,-0.137,0.0002669,38.313145,0.72057641,0,0,289.51814,0.8906,289.51814,0.8906,4.1454526,5.4371579,0,100,,,1,,,,5.3248E-5,10.01529,1467.8971,0,0
17813140.78,5905,38.0211,38.1325,-0.137,0.0002733,38.367536,0.7636571,0,0,290.06335,0.8784,290.06335,0.8784,5.1472613,5.44623,0,100,,,1,,,,5.3259E-5,10.87432,1472.0678,0,0
17813198.11,5905,38.0211,38.1072,-0.137,0.0002799,38.382021,0.76464511,0,0,289.71686,0.7698,289.71686,0.7698,13.814274,5.3851509,0,100,,,1,,,,5.3799E-5,10.89246,1473.1795,0,0
17813663.36,5905,40.0174,40.1349,-0.137,0.0002701,40.355806,0.76266806,0,0,318.14689,1.025,318.14689,1.025,3.2075614,5.8237425,0,100,,,1,,,,5.4629E-5,10.7703,1628.5911,0,0
17813722.27,5905,40.0265,40.1093,-0.137,0.0002833,40.398821,0.80780218,0,0,318.36797,0.8526,318.36797,0.8526,37.142697,5.7815152,0,100,,,1,,,,5.5067E-5,11.64749,1632.0647,0,0
17813780.42,5905,40.0167,40.0971,-0.137,0.0002701,40.391523,0.80267531,0,0,318.10339,0.8004,318.10339,0.8004,3.513634,5.7563872,0,100,,,1,,,,5.5261E-5,11.56303,1631.4751,0,0
17814382.64,5905,45.0305,45.1243,-0.137,0.0002766,45.407039,0.87467214,0,0,398.89626,1.1,398.89626,1.1,53.731788,6.8102025,0,100,,,1,,,,5.8573E-5,12.86086,2061.7992,0,0
17814447.27,5905,45.0192,45.1057,-0.137,0.0002833,45.429462,0.90367883,0,0,398.95212,0.9646,398.95212,0.9646,5.1524611,6.7900277,0,100,,,1,,,,5.8756E-5,13.6204,2063.836,0,0
17814512.09,5905,45.0117,45.1084,-0.137,0.0002606,45.423005,0.9019081,0,0,398.90997,0.952,398.90997,0.952,2.6363245,6.7811299,0,100,,,1,,,,5.8826E-5,13.58006,2063.2494,0,0
17815068.53,5905,50.0272,50.1591,-0.137,0.0002799,50.37899,0.90775507,0,0,487.78885,1.43,487.78885,1.43,1.5558401,7.9262807,0,100,,,1,,,,6.1541E-5,13.56226,2538.0426,0,0
17815140.34,5905,50.0195,50.1299,-0.137,0.0002833,50.455757,1.00729,0,0,489.19913,1.142,489.19913,1.142,19.563854,7.8958033,0,100,,,1,,,,6.1957E-5,15.85256,2545.7834,0,0
17815211.97,5905,50.0265,50.1157,-0.137,0.0002766,50.45957,1.0051828,0,0,488.79887,1.083,488.79887,1.083,2.1621501,7.8633689,0,100,,,1,,,,6.2162E-5,15.79161,2546.1682,0,0
17815773.7,5905,55.023,55.1525,-0.137,0.0002799,55.394425,1.0121644,0,0,584.67874,1.622,584.67874,1.622,1.0508689,9.0897444,0,100,,,1,,,,6.4323E-5,15.72674,3068.5424,0,0
17815851.89,5905,55.0287,55.1259,-0.137,0.0002901,55.481253,1.1158943,0,0,586.29295,1.301,586.29295,1.301,10.494671,9.0408641,0,100,,,1,,,,6.4849E-5,18.17949,3078.1694,0,0
17815930.09,5905,55.0249,55.1068,-0.137,0.0002833,55.491088,1.1123518,0,0,586.21699,1.218,586.21699,1.218,1.8272936,9.0045714,0,100,,,1,,,,6.5102E-5,18.08173,3079.2609,0,0
17816443.28,5905,60.0113,60.1842,-0.137,0.0002971,60.384188,1.1100982,0,0,692.7663,1.931,692.7663,1.931,0.53625287,10.351572,0,100,,,1,,,,6.6924E-5,18.00914,3646.2502,0,0
17816530.5,5905,60.0276,60.143,-0.137,0.0002833,60.495788,1.2217257,0,0,695.15311,1.416,695.15311,1.416,30.7957,10.26366,0,100,,,1,,,,6.773E-5,20.70314,3659.7404,0,0
17816617,5905,60.0261,60.13,-0.137,0.0002867,60.51433,1.2131971,0,0,694.84581,1.349,694.84581,1.349,3.3289431,10.220701,0,100,,,1,,,,6.7984E-5,20.52732,3661.9841,0,0
17817157.05,5905,65.0163,65.188,-0.137,0.0002701,65.415096,1.2058794,0,0,812.47917,2.011,812.47917,2.011,0.44841935,11.599474,0,100,,,1,,,,7.0044E-5,20.4414,4279.1347,0,0
17817251.42,5905,65.0284,65.1515,-0.137,0.0002669,65.528886,1.3182344,0,0,814.86268,1.591,814.86268,1.591,43.98654,11.510389,0,100,,,1,,,,7.0794E-5,23.19895,4294.0349,0,0
17817344,5905,65.0251,65.1286,-0.137,0.0002701,65.550282,1.3112021,0,0,814.67697,1.437,814.67697,1.437,1.4127998,11.446704,0,100,,,1,,,,7.1171E-5,23.02078,4296.8395,0,0
17817848.45,5905,70.0033,70.2178,-0.137,0.0002867,70.396482,1.3062774,0,0,940.21614,2.254,940.21614,2.254,0.39601045,12.913299,0,100,,,1,,,,7.281E-5,22.89341,4955.6647,0,0
17817950.7,5905,70.0181,70.1883,-0.137,0.0002766,70.531791,1.4217017,0,0,943.58768,1.808,943.58768,1.808,15.830701,12.846094,0,100,,,1,,,,7.3453E-5,25.8266,4974.7336,0,0
17818054.11,5905,70.0191,70.1593,-0.137,0.0002766,70.573502,1.4156088,0,0,943.46301,1.578,943.46301,1.578,3.9506534,12.761951,0,100,,,1,,,,7.3928E-5,25.69219,4980.6192,0,0
17818583.86,5905,75.0023,75.1998,-0.137,0.0002733,75.46115,1.4078673,0,0,1077.4642,2.208,1077.4642,2.208,0.39503093,14.173848,0,100,,,1,,,,7.6018E-5,25.5239,5694.3852,0,0
17818693.23,5905,75.0118,75.1799,-0.137,0.0002833,75.57368,1.5211882,0,0,1080.2563,1.787,1080.2563,1.787,2.3126004,14.070978,0,100,,,1,,,,7.6772E-5,28.3477,5711.3811,0,0
17818818.69,5905,75.0142,75.1594,-0.137,0.0002901,75.605483,1.5159658,0,0,1080.6857,1.757,1080.6857,1.757,27.936977,14.058984,0,100,,,1,,,,7.6868E-5,28.14196,5716.1891,0,0
17819379.88,5905,80.0217,80.166,-0.137,0.0002936,80.527246,1.5055465,0,0,1229.3458,2.398,1229.3458,2.398,0.32043783,15.511126,0,100,,,1,,,,7.9256E-5,28.11797,6484.6373,0,0
17819497.75,5905,80.0175,80.142,-0.137,0.0002936,80.635942,1.6188241,0,0,1231.9243,1.827,1231.9243,1.827,1.4152378,15.358912,0,100,,,1,,,,8.0209E-5,31.02225,6502.1552,0,0
17819632.73,5905,80.0138,80.1216,-0.137,0.0002766,80.657007,1.6114674,0,0,1231.9342,1.882,1231.9342,1.882,123.47513,15.355073,0,100,,,1,,,,8.023E-5,30.71782,6505.5527,0,0
17820204.42,5905,85.0266,85.1596,-0.137,0.0002867,85.565373,1.6034214,0,0,1388.3001,2.624,1388.3001,2.624,0.25298577,16.873589,0,100,,,1,,,,8.2277E-5,30.71015,7321.4331,0,0
17820349.33,5905,85.0216,85.1282,-0.137,0.0002901,85.685226,1.7233377,0,0,1391.11,2.057,1391.11,2.057,25.204637,16.707067,0,100,,,1,,,,8.3265E-5,33.74718,7341.958,0,0
17820494,5905,85.0095,85.1107,-0.137,0.0003043,85.704041,1.7144011,0,0,1391.0349,1.926,1391.0349,1.926,10.426913,16.664428,0,100,,,1,,,,8.3473E-5,33.41413,7345.1827,0,0
17821085.41,5905,90.0268,90.1625,-0.137,0.0002833,90.627791,1.7029447,0,0,1556.1898,2.779,1556.1898,2.779,0.24586167,18.204577,0,100,,,1,,,,8.5483E-5,33.32886,8213.3964,0,0
17821239.98,5905,90.0159,90.1399,-0.137,0.0002901,90.746741,1.8243532,0,0,1559.2142,2.172,1559.2142,2.172,72.900637,18.017939,0,100,,,1,,,,8.6537E-5,36.40915,8234.971,0,0
17821392.09,5905,90.0108,90.1194,-0.137,0.0002833,90.769029,1.8116135,0,0,1559.3553,2.124,1559.3553,2.124,22.028484,17.98859,0,100,,,1,,,,8.6686E-5,36.03588,8239.0166,0,0
17822005.59,5905,95.0291,95.169,-0.137,0.0002901,95.681786,1.8153211,0,0,1724.4064,2.87,1724.4064,2.87,0.24698608,19.503169,0,100,,,1,,,,8.8417E-5,35.97718,9155.0041,0,0
17822168.5,5905,95.0156,95.14,-0.137,0.0002901,95.799625,1.9346644,0,0,1727.9491,2.324,1727.9491,2.324,97.977868,19.316813,0,100,,,1,,,,8.9453E-5,39.00634,9177.5681,0,0
17822330.53,5905,95.011,95.1188,-0.137,0.0002971,95.822038,1.9243898,0,0,1727.5592,2.219,1727.5592,2.219,11.401481,19.285358,0,100,,,1,,,,8.9579E-5,38.63363,9181.863,0,0
17822956.94,5905,100.036,100.172,-0.137,0.0002971,100.72437,1.9178575,0,0,1904.3797,3.245,1904.3797,3.245,0.24122085,20.820385,0,100,,,1,,,,9.1467E-5,38.57072,10145.398,0,0
17823129.38,5905,100.021,100.141,-0.137,0.0002971,100.85019,2.0432809,0,0,1906.6996,2.539,1906.6996,2.539,74.372511,20.609826,0,100,,,1,,,,9.2514E-5,41.64077,10170.762,0,0
17823299.84,5905,100.016,100.116,-0.137,0.0002936,100.87259,2.0286333,0,0,1906.4454,2.44,1906.4454,2.44,25.9576,20.569479,0,100,,,1,,,,9.2683E-5,41.21965,10175.28,0,0
17824235.91,5905,110.012,110.172,-0.137,0.0003079,110.83106,2.1965927,0,0,2285.6203,3.13,2285.6203,3.13,9.0837995,23.072957,0,100,,,1,,,,9.9061E-5,44.5721,12283.525,0,0
17824424.48,5905,110.013,110.134,-0.137,0.0003079,110.9013,2.2305637,0,0,2287.5295,2.964,2287.5295,2.964,47.809023,23.058805,0,100,,,1,,,,9.9204E-5,46.14591,12299.099,0,0
17824613.69,5905,110.006,110.126,-0.137,0.0003116,110.94287,2.2302939,0,0,2288.2535,2.832,2288.2535,2.832,17.655954,23.009618,0,100,,,1,,,,9.9448E-5,46.11761,12308.321,0,0
17825417.44,5905,120.024,120.21,-0.137,0.0002971,120.75369,2.2596129,0,0,2675.7411,4.253,2675.7411,4.253,0.18073983,25.565954,0,100,,,1,,,,0.00010466,46.01924,14581.454,0,0
17825623.98,5905,120.02,120.168,-0.137,0.0002971,120.94907,2.4532401,0,0,2682.1627,3.419,2682.1627,3.419,6.1106564,25.316515,0,100,,,1,,,,0.00010595,51.13191,14628.677,0,0
17825827.58,5905,120.007,120.136,-0.137,0.0002901,120.99312,2.4376593,0,0,2682.1688,3.189,2682.1688,3.189,53.26419,25.253368,0,100,,,1,,,,0.00010621,50.63303,14639.336,0,0
17826728.69,5905,130.034,130.221,-0.137,0.0002901,130.6886,2.434944,0,0,3082.841,5.143,3082.841,5.143,0.17905448,27.669297,0,100,,,1,,,,0.00011142,50.50674,17079.509,0,0
17826949.33,5905,130.009,130.192,-0.137,0.0003043,130.93809,2.6611299,0,0,3091.8286,4.283,3091.8286,4.283,1.3217294,27.41885,0,100,,,1,,,,0.00011276,55.33859,17144.783,0,0
17827167.47,5905,130.01,130.152,-0.137,0.0002936,131.02173,2.6467516,0,0,3093.0165,3.923,3093.0165,3.923,5.4722525,27.334984,0,100,,,1,,,,0.00011315,54.8377,17166.695,0,0
17828172.33,5905,140.033,140.193,-0.137,0.0003007,140.80656,2.6570717,0,0,3501.1741,5.481,3501.1741,5.481,0.1555882,29.442929,0,100,,,1,,,,0.00011891,54.66997,19826.488,0,0
17828406.75,5905,140.013,140.165,-0.137,0.0003007,141.04841,2.85994,0,0,3508.7841,4.473,3508.7841,4.473,1.3484919,29.158612,0,100,,,1,,,,0.00012033,58.88586,19894.653,0,0
17828638.66,5905,140.014,140.137,-0.137,0.0002936,141.12903,2.8466304,0,0,3509.3993,4.012,3509.3993,4.012,46.94758,29.027811,0,100,,,1,,,,0.0001209,58.31722,19917.403,0,0
17829556.97,5905,150.018,150.189,-0.137,0.0003043,150.86102,2.8541885,0,0,3916.0273,6.212,3916.0273,6.212,0.13766372,30.968247,0,100,,,1,,,,0.00012645,58.05562,22759.048,0,0
17829799.72,5905,150.007,150.152,-0.137,0.0003154,151.12641,3.0672759,0,0,3925.3906,5.053,3925.3906,5.053,1.1918512,30.676759,0,100,,,1,,,,0.00012796,61.93649,22839.192,0,0
17830042.23,5905,150.001,150.134,-0.137,0.0003116,151.21455,3.0497563,0,0,3925.0085,4.512,3925.0085,4.512,9.4268309,30.538667,0,100,,,1,,,,0.00012853,61.35352,22865.842,0,0
17831059.42,5905,160.013,160.209,-0.137,0.0003268,161.05468,3.0767648,0,0,4333.4334,6.485,4333.4334,6.485,0.14217738,32.134078,0,100,,,1,,,,0.00013485,61.07733,25938.611,0,0
17831311.42,5905,160.009,160.173,-0.137,0.0003268,161.30231,3.2691844,0,0,4339.1519,5.261,4339.1519,5.261,1.5501613,31.807377,0,100,,,1,,,,0.00013642,64.26816,26018.437,0,0
17831560.86,5905,160.004,160.165,-0.137,0.0003154,161.38454,3.2537896,0,0,4339.5633,4.729,4339.5633,4.729,24.001178,31.688211,0,100,,,1,,,,0.00013695,63.61475,26044.97,0,0
17832494.52,5905,170.017,170.223,-0.137,0.0003191,171.12386,3.2815088,0,0,4740.4044,7.475,4740.4044,7.475,0.13620241,33.067826,0,100,,,1,,,,0.00014335,63.37642,29283.376,0,0
17832717.33,5905,170.004,170.186,-0.137,0.000323,171.37969,3.4694311,0,0,4746.0476,5.212,4746.0476,5.212,0.71890851,32.637739,0,100,,,1,,,,0.00014542,66.13565,29370.998,0,0
17832971.83,5905,170.008,170.166,-0.137,0.0003347,171.47168,3.4496925,0,0,4744.9452,5.015,4744.9452,5.015,21.244003,32.575523,0,100,,,1,,,,0.00014566,65.27548,29402.538,0,0
17833993.2,5905,180.022,180.163,-0.137,0.0003347,181.26704,3.5058875,0,0,5130.4435,7.695,5130.4435,7.695,0.13434874,33.689403,0,100,,,1,,,,0.00015229,65.15105,32857.739,0,0
17834255.17,5905,180.01,180.142,-0.137,0.0003387,181.52107,3.6833456,0,0,5133.9754,5.653,5133.9754,5.653,1.6169634,33.292813,0,100,,,1,,,,0.00015421,67.37881,32949.9,0,0
17834515.31,5905,180.01,180.125,-0.137,0.000323,181.59218,3.6603219,0,0,5133.1153,5.088,5133.1153,5.088,5.9366931,33.148662,0,100,,,1,,,,0.00015485,66.58563,32975.719,0,0
17835470.56,5905,190.02,190.153,-0.137,0.0003387,191.34596,3.7077269,0,0,5511.8221,7.975,5511.8221,7.975,0.14224306,34.125922,0,100,,,1,,,,0.00016151,66.29732,36613.277,0,0
17835738.8,5905,189.997,190.132,-0.137,0.0003553,191.615,3.8997229,0,0,5511.97,5.84,5511.97,5.84,1.7240728,33.710261,0,100,,,1,,,,0.00016351,68.25184,36716.31,0,0
17836001.38,5905,190.001,190.101,-0.137,0.0003428,191.6937,3.8751219,0,0,5512.1011,5.25,5512.1011,5.25,5.7831525,33.572337,0,100,,,1,,,,0.00016419,67.42052,36746.475,0,0
17836929.91,5905,200.022,200.137,-0.137,0.0003596,201.46152,3.9350542,0,0,5876.4002,8.826,5876.4002,8.826,0.13087864,34.380121,0,100,,,1,,,,0.00017092,67.14467,40586.744,0,0
17837198.14,5905,200.013,200.107,-0.137,0.0003596,201.74017,4.1210356,0,0,5876.4265,6.353,5876.4265,6.353,1.7934015,33.942146,0,100,,,1,,,,0.00017313,68.76024,40699.098,0,0
17837463.17,5905,200,200.075,-0.137,0.0003682,201.8178,4.0939869,0,0,5874.1057,5.517,5874.1057,5.517,6.0137215,33.762227,0,100,,,1,,,,0.00017398,67.88429,40730.425,0,0
17838466.39,5905,210.006,210.136,-0.137,0.0004003,211.66097,4.1554059,0,0,6242.5466,9.127,6242.5466,9.127,0.14427934,34.325154,0,100,,,1,,,,0.00018187,67.52445,44800.364,0,0
17838732.92,5905,209.984,210.1,-0.137,0.00041,211.91289,4.3237131,0,0,6240.1842,6.454,6240.1842,6.454,6.2533441,33.891721,0,100,,,1,,,,0.00018412,68.65031,44907.072,0,0
17838998.25,5905,210.008,210.087,-0.137,0.0003682,211.97018,4.2953235,0,0,6236.9254,5.857,6236.9254,5.857,1.8659962,33.760672,0,100,,,1,,,,0.00018474,67.78344,44931.358,0,0
17839890.38,5905,220.016,220.149,-0.137,0.0003596,221.78621,4.2903556,0,0,6732.1545,20.26,6732.1545,20.26,0.6248236,34.520151,0,100,,,1,,,,0.00019502,67.52134,49189.124,0,0
17840159.45,5905,220.011,220.107,-0.137,0.0003727,222.06064,4.529628,0,0,6633.9218,7.677,6633.9218,7.677,37.191591,33.791287,0,100,,,1,,,,0.00019632,69.0403,49310.927,0,0
17840422.48,5905,220.005,220.097,-0.137,0.0003553,222.11174,4.4815276,0,0,6625.1241,6.705,6625.1241,6.705,2.5700521,33.664364,0,100,,,1,,,,0.0001968,67.58257,49333.627,0,0
17841311.95,5905,230.014,230.094,-0.137,0.0003727,231.92087,4.4941019,0,0,7134.6781,9.799,7134.6781,9.799,0.14834939,34.397267,0,100,,,1,,,,0.00020742,67.32873,53787.29,0,0
17841580.13,5905,230.009,230.077,-0.137,0.0003682,232.20022,4.7176459,0,0,7018.588,7.733,7018.588,7.733,51.636032,33.557499,0,100,,,1,,,,0.00020915,68.79453,53916.941,0,0
17841842.45,5905,230.006,230.064,-0.137,0.0004199,232.22759,4.6540953,0,0,7009.6707,6.771,7009.6707,6.771,1.0789373,33.391232,0,100,,,1,,,,0.00020993,67.115,53929.655,0,0
17842531.59,5905,240.017,240.103,-0.137,0.0005081,242.00366,4.7184911,0,0,7452.2847,23.88,7452.2847,23.88,0.75659259,34.121498,0,100,,,1,,,,0.0002184,66.78246,58565.772,0,0
17842797.19,5905,240.006,240.061,-0.137,0.0006224,242.28072,4.9281212,0,0,7310.7416,6.926,7310.7416,6.926,9.9189987,32.905304,0,100,,,1,,,,0.00022218,68.243,58699.949,0,0
17843055.7,5905,240.003,240.063,-0.137,0.0008348,242.28071,4.8204331,0,0,7306.7323,6.506,7306.7323,6.506,1.983049,32.693001,0,100,,,1,,,,0.0002235,65.81061,58699.945,0,0
17843701.72,5905,250.047,250.054,-0.137,0.0010506,252.0983,4.8867453,0,0,7623.4122,10.12,7623.4122,10.12,0.13966035,32.019029,0,100,,,1,,,,0.00023809,65.386,63553.555,0,0
17843951.86,5905,249.998,250.013,-0.137,0.0017577,252.24856,4.8955202,0,0,7609.1517,6.911,7609.1517,6.911,11.211956,31.057538,0,100,,,1,,,,0.000245,64.03806,63629.337,0,0
17844197.03,5905,250.033,250.014,-0.137,0.0008266,252.28975,4.8569166,0,0,7651.3365,5.663,7651.3365,5.663,1.3570006,32.174189,0,100,,,1,,,,0.00023781,62.11508,63650.117,0,0
17844934.39,5905,260.01,260.052,-0.137,0.0004249,262.23112,5.1579657,0,0,7917.9843,10.71,7917.9843,10.71,0.15742718,32.52653,0,100,,,1,,,,0.00024343,64.34838,68765.16,0,0
17845189.03,5905,260.006,260.036,-0.137,0.0004249,262.44085,5.297559,0,0,7900.8218,7.117,7900.8218,7.117,4.7684718,32.117283,0,100,,,1,,,,0.000246,65.05306,68875.202,0,0
17845440.22,5905,260.007,260.02,-0.137,0.0004149,262.4746,5.2666617,0,0,7897.7384,6.702,7897.7384,6.702,0.6282163,32.06232,0,100,,,1,,,,0.00024632,64.23457,68892.917,0,0
17846176.97,5905,269.994,270.1,-0.137,0.0004352,272.38365,5.3888569,0,0,8211.4693,12.02,8211.4693,12.02,0.17651605,31.859708,0,100,,,1,,,,0.00025774,64.12464,74192.853,0,0
17846428.13,5905,270.013,270.075,-0.137,0.00043,272.58551,5.4917631,0,0,8186.7175,7.777,8186.7175,7.777,7.7602818,31.484433,0,100,,,1,,,,0.00026002,63.71942,74302.862,0,0
17846675.45,5905,270.005,270.073,-0.137,0.0004249,272.62109,5.4583965,0,0,8181.2345,7.436,8181.2345,7.436,0.86491105,31.418501,0,100,,,1,,,,0.0002604,62.96887,74322.259,0,0
17847314.56,5905,280.015,280.128,-0.137,0.0004674,282.46777,5.5729591,0,0,8486.2633,12.92,8486.2633,12.92,0.22388646,31.073596,0,100,,,1,,,,0.0002731,62.837,79788.043,0,0
17847559.39,5905,280.01,280.079,-0.137,0.0004564,282.66281,5.6690579,0,0,8455.4385,8.467,8455.4385,8.467,9.4376956,30.793349,0,100,,,1,,,,0.00027459,62.14719,79898.266,0,0
17847801.25,5905,280.006,280.069,-0.137,0.000473,282.71801,5.6543886,0,0,8447.5303,7.817,8447.5303,7.817,1.0830829,30.68067,0,100,,,1,,,,0.00027534,61.5867,79929.472,0,0
17848492.39,5905,289.989,290.039,-0.137,0.0005204,292.48466,5.7741537,0,0,8727.3276,12.95,8727.3276,12.95,0.14054739,30.391235,0,100,,,1,,,,0.00028717,61.36134,85547.277,0,0
17848731.73,5905,289.99,290.016,-0.137,0.0005524,292.70884,5.8761682,0,0,8684.797,8.814,8684.797,8.814,10.20701,29.959209,0,100,,,1,,,,0.00028989,60.78247,85678.464,0,0
17848968.69,5905,290.009,290.012,-0.137,0.0005394,292.74969,5.8371939,0,0,8677.8595,8.225,8677.8595,8.225,0.93521023,29.875381,0,100,,,1,,,,0.00029047,59.91842,85702.38,0,0
17849656.22,5905,299.994,300.074,-0.137,0.0006298,302.64792,6.0065567,0,0,8889.1674,12.72,8889.1674,12.72,0.14726964,29.514532,0,100,,,1,,,,0.00030118,59.75076,91595.765,0,0
17849889.45,5905,300.021,300.066,-0.137,0.0006298,302.86654,6.0850579,0,0,8877.1939,8.709,8877.1939,8.709,15.88433,29.159647,0,100,,,1,,,,0.00030443,59.02906,91728.139,0,0
17850120.66,5905,299.999,300.061,-0.137,0.0006606,302.91341,6.0520221,0,0,8872.6138,8.062,8872.6138,8.062,1.0255812,29.049166,0,100,,,1,,,,0.00030543,58.31929,91756.532,0,0
17850723.58,5905,310.016,310.079,-0.137,0.0008773,312.72653,6.140973,0,0,9170.4261,15.69,9170.4261,15.69,0.38825032,28.520627,0,100,,,1,,,,0.00032154,58.09833,97797.882,0,0
17850949.83,5905,310.028,310.026,-0.137,0.0008709,312.9497,6.2502209,0,0,9097.2468,8.852,9097.2468,8.852,14.224067,28.256931,0,100,,,1,,,,0.00032195,57.04125,97937.512,0,0
17851174.66,5905,310.011,310.019,-0.137,0.0008893,312.99799,6.2309889,0,0,9093.9042,8.335,9093.9042,8.335,0.9526408,28.213441,0,100,,,1,,,,0.00032233,56.51386,97967.743,0,0
17851851.86,5905,319.975,320.012,-0.137,0.0009091,322.78996,6.3431236,0,0,9361.0507,14.91,9361.0507,14.91,0.26630901,27.714123,0,100,,,1,,,,0.00033777,56.42688,104193.36,0,0
17852072.7,5905,320.016,319.995,-0.137,0.0009079,323.0117,6.4560309,0,0,9282.9042,9.166,9282.9042,9.166,5.2949361,27.44345,0,100,,,1,,,,0.00033826,55.42825,104336.56,0,0
17852291.75,5905,320.035,319.997,-0.137,0.0009049,323.05513,6.4250779,0,0,9279.3567,9.194,9279.3567,9.194,1.2396619,27.371653,0,100,,,1,,,,0.00033901,54.8869,104364.62,0,0
17852892.31,5905,329.999,330.021,-0.137,0.0009116,332.96991,6.5856882,0,0,9491.787,11.7,9491.787,11.7,0.20159268,26.882973,0,100,,,1,,,,0.00035308,54.74331,110868.96,0,0
17853106.86,5905,330.008,330.002,-0.137,0.0009091,333.17738,6.6791914,0,0,9465.0155,9.303,9465.0155,9.303,2.2686829,26.656631,0,100,,,1,,,,0.00035507,53.76595,111007.17,0,0
17853319.98,5905,330.014,329.979,-0.137,0.0009079,333.22371,6.6565583,0,0,9464.5972,9.535,9464.5972,9.535,0.8448278,26.662602,0,100,,,1,,,,0.00035498,53.31326,111038.04,0,0
17853985.19,5905,340.021,339.975,-0.137,0.0009145,343.02045,6.7844176,0,0,9708.0926,13.42,9708.0926,13.42,0.21013847,26.135957,0,100,,,1,,,,0.00037145,53.3252,117663.03,0,0
17854196.11,5905,340.021,339.951,-0.137,0.000913,343.2076,6.8597986,0,0,9682.8475,10.36,9682.8475,10.36,7.6896569,25.905616,0,100,,,1,,,,0.00037377,52.27191,117791.45,0,0
17854404,5905,339.996,339.967,-0.137,0.0009103,343.25113,6.8488207,0,0,9669.3338,10.48,9669.3338,10.48,1.3774711,25.817304,0,100,,,1,,,,0.00037453,51.81123,117821.34,0,0
17854966.2,5905,350.001,350.007,-0.137,0.0009236,352.99791,6.9442959,0,0,9908.0147,13.83,9908.0147,13.83,0.15800405,25.510378,0,100,,,1,,,,0.00038839,51.63461,124607.52,0,0
17855292.56,5905,350.028,350.001,-0.137,0.000913,353.25165,6.9520297,0,0,9879.8539,11.1,9879.8539,11.1,1.9778147,25.226683,0,100,,,1,,,,0.00039164,51.02076,124786.73,0,0
17855495.13,5905,350.025,350.001,-0.137,0.0009116,353.35595,7.0652664,0,0,9875.7568,11.01,9875.7568,11.01,1.2974874,25.186898,0,100,,,1,,,,0.0003921,50.45337,124860.43,0,0
17856146.78,5905,360.009,360.001,-0.137,0.0009216,363.01061,7.192508,0,0,10076.713,13.65,10076.713,13.65,0.14623231,24.808211,0,100,,,1,,,,0.00040618,50.3738,131776.7,0,0
17856346.91,5905,360.04,360.002,-0.137,0.0009162,363.30776,7.3249571,0,0,10051.841,11.72,10051.841,11.72,52.754297,24.495695,0,100,,,1,,,,0.00041035,49.61642,131992.53,0,0
17856546.09,5905,360.066,360.012,-0.137,0.0009179,363.36989,7.2827574,0,0,10050.246,11.83,10050.246,11.83,3.0199978,24.449796,0,100,,,1,,,,0.00041106,48.99139,132037.68,0,0