File: Examples/data/CV-135-17Feb2019-1.dat
[Header]
TITLE,Addenda Pate thermique
BYAPP,HeatCapacity,3.5.4,1.5
INFO,0,MASS:Sample Mass (mg)
INFO,0,MASSERR:Sample Mass Error (mg)
INFO,0,MOLWGHT:Formula Weight (g/mole)
INFO,0,ATOMS:Atoms per Formula Unit
INFO,PPMS Heat Capacity Option 3.5.4 Build 1,APPNAME
DATATYPE,TIME,1
STARTUPAXIS, X, 2, LINEAR, AUTO
STARTUPAXIS, Y1, 3, LINEAR, AUTO
[Data]
Time Stamp (Seconds),PPMS Status (Code),Puck Temp (Kelvin),System Temp (Kelvin),Field (Oersted),Pressure (Torr),Sample Temp (Kelvin),Temp Rise (Kelvin),Samp HC (µJ/K),Samp HC Err (µJ/K),Addenda HC (µJ/K),Addenda HC Err (µJ/K),Total HC (µJ/K),Total HC Err (µJ/K),Fit Deviation (ChiSquare),Time Const tau1 (seconds),Time Const tau2 (seconds),Sample Coupling (Percent),Debye Temp (Kelvin),Debye Temp Err (Kelvin),Cal Correction (Factor),Therm Resist (Ohms),Htr Resist (Ohms),Puck Resist (Ohms),Wire Cond (W/K),Meas Time (seconds),Temp Squared (K^2),Samp HC/Temp (µJ/K/K),Addenda Offset HC (µJ/K)
17952549.48,5905,2.50363,2.5595,-0.137,0.0002971,2.6399842,0.051886252,1.0131402,0.004246,0.47445314,0.001578,1.4875933,0.004246,1.6406824,0.56653341,0.0073736382,94.024487,0,0,1,,,,2.7042E-6,1.132453,6.9695166,0.38376751,0
17952575.86,5905,2.50309,2.5603,-0.137,0.0002936,2.6391694,0.051889282,1.0125536,0.004595,0.47406751,0.001578,1.4866212,0.004595,0.52669968,0.56293502,0.0069617383,94.32138,0,0,1,,,,2.7155E-6,1.133067,6.9652153,0.38366375,0
17952601.17,5905,2.50281,2.5607,-0.137,0.0003116,2.6384747,0.051884737,1.0176648,0.004176,0.47388302,0.001577,1.4915478,0.004176,1.104683,0.57766554,0.0074478035,94.067246,0,0,1,,,,2.6589E-6,1.12587,6.9615486,0.38570194,0
17952904.42,5905,2.98794,3.0684,-0.137,0.0003268,3.1158662,0.059993561,1.2677266,0.003521,0.71733088,0.001536,1.9850575,0.003521,2.2933128,0.60815814,0.0069874284,95.062209,0,0,1,,,,3.334E-6,1.155331,9.7086224,0.40686169,0
17952930.95,5905,2.98946,3.0711,-0.137,0.0002971,3.1177366,0.061732231,1.2721051,0.00321,0.71835167,0.001537,1.9904567,0.00321,1.5969828,0.60903177,0.0072465926,94.884542,0,0,1,,,,3.3411E-6,1.216316,9.7202817,0.40802198,0
17952957.63,5905,2.99093,3.0715,-0.137,0.0003154,3.1193061,0.061531309,1.2744696,0.003536,0.71918831,0.001538,1.9936579,0.003536,1.520233,0.6021239,0.0068589067,95.100084,0,0,1,,,,3.3816E-6,1.218064,9.7300706,0.40857472,0
17953300.22,5905,3.4857,3.5999,-0.137,0.0002971,3.6196675,0.06874048,1.5450678,0.00432,1.0587996,0.001872,2.6038674,0.00432,1.649051,0.65080068,0.0070796388,95.548032,0,0,1,,,,4.0674E-6,1.204248,13.101993,0.42685353,0
17953327.97,5905,3.48756,3.6011,-0.137,0.0003043,3.6238832,0.07233468,1.5333639,0.003912,1.0620533,0.001869,2.5954172,0.003912,1.731849,0.64840511,0.0068201786,95.703159,0,0,1,,,,4.0662E-6,1.301601,13.13253,0.4231273,0
17953354.81,5905,3.48929,3.6065,-0.137,0.0002867,3.6246697,0.071759459,1.5520197,0.004186,1.0626634,0.001869,2.6146831,0.004186,1.6460084,0.64990958,0.0068801806,95.665368,0,0,1,,,,4.0881E-6,1.29681,13.138231,0.42818238,0
17953706.78,5905,3.98325,4.1283,-0.137,0.0003079,4.1267627,0.077092723,1.8949863,0.003853,1.5396421,0.001488,3.4346284,0.003853,3.2713682,0.70674594,0.0066759825,96.235552,0,0,1,,,,4.9182E-6,1.299819,17.030171,0.45919439,0
17953733.53,5905,3.98567,4.1289,-0.137,0.0002971,4.1313269,0.081041845,1.9004709,0.00375,1.5443256,0.001496,3.4447965,0.00375,4.8396699,0.70587816,0.0062116784,96.489754,0,0,1,,,,4.9347E-6,1.413492,17.067862,0.46001466,0
17953760.22,5905,3.98783,4.1323,-0.137,0.0002867,4.1330753,0.080887609,1.9021844,0.003953,1.5461466,0.0015,3.448331,0.003953,3.4604964,0.70179466,0.005997731,96.58976,0,0,1,,,,4.9668E-6,1.411756,17.082311,0.46023464,0
17954089.89,5905,4.48172,4.6253,-0.137,0.0002901,4.6196421,0.085553335,2.2588766,0.006036,2.1389526,0.003254,4.3978292,0.006036,2.0839593,0.77078721,0.0067231587,96.564222,0,0,1,,,,5.7597E-6,1.403589,21.341093,0.4889722,0
17954117.48,5905,4.48452,4.6281,-0.137,0.0002936,4.6242009,0.090364748,2.274934,0.005367,2.1445035,0.003265,4.4194375,0.005367,1.3219046,0.77825389,0.0074529541,96.232796,0,0,1,,,,5.7381E-6,1.541574,21.383234,0.49196263,0
17954144.84,5905,4.48635,4.6303,-0.137,0.0002971,4.6271497,0.091199863,2.2675207,0.005392,2.1481526,0.003272,4.4156733,0.005392,2.1705309,0.7782605,0.0069270321,96.495228,0,0,1,,,,5.7286E-6,1.556508,21.410514,0.49004698,0
17954479.73,5905,4.98004,5.1416,-0.137,0.0002833,5.1253477,0.095823756,2.7224207,0.006717,2.8144765,0.004082,5.5368972,0.006717,1.7926557,0.84845477,0.0077243617,96.423789,0,0,1,,,,6.5849E-6,1.556521,26.269189,0.531168,0
17954507.66,5905,4.98287,5.1463,-0.137,0.0002936,5.1308961,0.10077693,2.7257749,0.006929,2.8222086,0.004089,5.5479836,0.006929,1.811125,0.84532246,0.0073737405,96.570889,0,0,1,,,,6.6199E-6,1.69691,26.326095,0.53124735,0
17954535.56,5905,4.98534,5.1459,-0.137,0.0003007,5.1332377,0.10078994,2.7398819,0.006783,2.8258103,0.004092,5.5656923,0.006783,3.4429397,0.85460426,0.007393802,96.598411,0,0,1,,,,6.5687E-6,1.690645,26.350129,0.53375318,0
17954866.61,5905,5.47775,5.6558,-0.137,0.0002936,5.6311987,0.10541668,3.2545527,0.008521,3.6226167,0.004724,6.8771694,0.008521,2.131136,0.92638907,0.0073170024,96.885524,0,0,1,,,,7.4775E-6,1.709209,31.710399,0.57795026,0
17954896.39,5905,5.48183,5.6593,-0.137,0.0003007,5.6374567,0.11072365,3.26036,0.008157,3.6331892,0.004742,6.8935492,0.008157,3.1662597,0.93344686,0.0080025727,96.624186,0,0,1,,,,7.4433E-6,1.852778,31.780918,0.57833881,0
17954927.42,5905,5.48429,5.6619,-0.137,0.0002833,5.640744,0.11097968,3.2798303,0.008783,3.6386871,0.004751,6.9185174,0.008783,5.9111783,0.93189824,0.0078163045,96.696506,0,0,1,,,,7.4816E-6,1.866894,31.817992,0.58145349,0
17955254.97,5905,5.9768,6.1647,-0.137,0.0002901,6.1364694,0.11508127,3.8240188,0.01081,4.559512,0.006621,8.3835308,0.01081,4.2102749,1.0069231,0.0081246363,96.807579,0,0,1,,,,8.3835E-6,1.863796,37.656257,0.62316269,0
17955285.08,5905,5.98056,6.171,-0.137,0.0002971,6.1428218,0.12060176,3.8331445,0.01062,4.5716691,0.00663,8.4048136,0.01062,3.9338018,1.0104768,0.0079046592,96.903144,0,0,1,,,,8.3734E-6,2.013846,37.734259,0.62400387,0
17955316.16,5905,5.98292,6.1719,-0.137,0.0002833,6.1460486,0.12061625,3.8648946,0.01037,4.5780442,0.006635,8.4429388,0.01037,3.2491235,1.0119191,0.0076084661,97.022824,0,0,1,,,,8.3976E-6,2.020954,37.773913,0.62884218,0
17955637.44,5905,6.4749,6.6746,-0.137,0.0002936,6.6414159,0.12513162,4.4782415,0.01075,5.6223017,0.006682,10.100543,0.01075,3.8916322,1.0980155,0.008311006,96.988662,0,0,1,,,,9.2555E-6,2.023838,44.108405,0.67429017,0
17955667.59,5905,6.47894,6.6769,-0.137,0.0002867,6.6485741,0.13100818,4.488683,0.01069,5.6381948,0.006697,10.126878,0.01069,3.8411249,1.0901273,0.0077021743,97.185553,0,0,1,,,,9.3429E-6,2.196031,44.203538,0.67513468,0
17955696.64,5905,6.48265,6.6812,-0.137,0.0002971,6.6515148,0.130634,4.4967489,0.01087,5.6447404,0.006703,10.141489,0.01087,1.6536804,1.0955059,0.0079340199,97.116467,0,0,1,,,,9.3118E-6,2.180255,44.24265,0.67604884,0
17956011.81,5905,6.9733,7.1808,-0.137,0.0002867,7.1451477,0.13512966,5.2025934,0.01338,6.7905967,0.008381,11.99319,0.01338,3.1704845,1.1886213,0.0093688732,96.853435,0,0,1,,,,1.0152E-5,2.191012,51.053135,0.72812959,0
17956042.61,5905,6.97797,7.1834,-0.137,0.0002936,7.1528629,0.14172513,5.2210812,0.01279,6.8114283,0.008412,12.032509,0.01279,2.1916087,1.1827314,0.008412368,97.155393,0,0,1,,,,1.023E-5,2.377243,51.163448,0.72992888,0
17956072.11,5905,6.98168,7.1871,-0.137,0.0002799,7.1561502,0.14139145,5.2285008,0.01314,6.8195217,0.008424,12.048023,0.01314,4.2135559,1.1839274,0.0082257265,97.220263,0,0,1,,,,1.0232E-5,2.365463,51.210486,0.73063039,0
17956378.86,5905,7.47101,7.6806,-0.137,0.0002971,7.646748,0.14403667,6.0770084,0.01677,8.1210932,0.0103,14.198102,0.01677,3.8241644,1.2776084,0.0091868768,97.116204,0,0,1,,,,1.1174E-5,2.367855,58.472754,0.79471802,0
17956408.53,5905,7.47557,7.6853,-0.137,0.0002833,7.6548954,0.15094155,6.0969515,0.01782,8.1460816,0.01033,14.243033,0.01782,0.69245251,1.2805629,0.0097819185,96.940025,0,0,1,,,,1.1187E-5,2.555217,58.597424,0.79647745,0
17956438.02,5905,7.48039,7.6898,-0.137,0.0003079,7.6589837,0.15127477,6.0886385,0.01608,8.1573721,0.01034,14.246011,0.01608,2.9622298,1.2785511,0.0097848028,96.93333,0,0,1,,,,1.1207E-5,2.561126,58.660031,0.7949669,0
17956734.17,5905,7.96941,8.1837,-0.137,0.0002971,8.1475718,0.1531071,7.0542688,0.01873,9.5513187,0.01187,16.605587,0.01873,2.3394306,1.3715245,0.0096717549,97.165989,0,0,1,,,,1.2172E-5,2.557102,66.382926,0.86581241,0
17956766.42,5905,7.97471,8.189,-0.137,0.0003007,8.1574071,0.16133169,7.0968948,0.0187,9.5633945,0.01189,16.660289,0.0187,2.5577217,1.3635826,0.0059787983,98.227032,0,0,1,,,,1.2258E-5,2.743049,66.54329,0.86999395,0
17956799.72,5905,7.97938,8.1912,-0.137,0.0002936,8.1619125,0.16077292,7.0844716,0.01847,9.5768704,0.01191,16.661342,0.01847,4.2464949,1.3645749,0.0073519484,97.826047,0,0,1,,,,1.2259E-5,2.727165,66.616816,0.86799161,0
17957093.59,5905,8.46843,8.687,-0.137,0.0002936,8.651582,0.16490146,8.079287,0.02274,11.066004,0.0144,19.145291,0.02274,1.6226115,1.4688101,0.0087800693,97.587184,0,0,1,,,,1.3092E-5,2.72915,74.849871,0.93385083,0
17957125.75,5905,8.47406,8.6908,-0.137,0.0002867,8.6609647,0.1715686,8.0996257,0.02341,11.098066,0.01442,19.197691,0.02341,1.3348374,1.4655283,0.0081171718,97.761704,0,0,1,,,,1.3153E-5,2.93762,75.012309,0.93518748,0
17957158.06,5905,8.47938,8.6945,-0.137,0.0003007,8.6650043,0.1711931,8.1312815,0.02274,11.111554,0.01443,19.242835,0.02274,2.0783376,1.4711694,0.0092885297,97.454588,0,0,1,,,,1.3141E-5,2.931057,75.082299,0.93840479,0
17957440.19,5905,8.96618,9.1848,-0.137,0.0002867,9.1538923,0.17410602,9.3642838,0.02301,12.779031,0.01483,22.143314,0.02301,2.5467507,1.5794895,0.010123723,97.417104,0,0,1,,,,1.4086E-5,2.942339,83.793744,1.0229838,0
17957471.78,5905,8.97251,9.19,-0.137,0.0003116,9.1641381,0.1813329,9.3720938,0.02293,12.817429,0.01486,22.189523,0.02293,1.2989432,1.5740412,0.0093702901,97.597503,0,0,1,,,,1.4159E-5,3.158979,83.981427,1.0226923,0
17957503.61,5905,8.97674,9.1928,-0.137,0.0002971,9.1683317,0.18089666,9.3747362,0.02325,12.831653,0.01486,22.206389,0.02325,1.9434221,1.5690224,0.0087373039,97.75014,0,0,1,,,,1.4211E-5,3.148082,84.058307,1.0225128,0
17957781.25,5905,9.46439,9.6849,-0.137,0.0002669,9.655491,0.18276967,10.750799,0.02693,14.613037,0.01633,25.363836,0.02693,1.2045601,1.6875663,0.010927476,97.392476,0,0,1,,,,1.5103E-5,3.138045,93.228507,1.1134389,0
17957812.83,5905,9.47108,9.6888,-0.137,0.0002901,9.6655044,0.1907681,10.803546,0.02488,14.653504,0.01636,25.45705,0.02488,3.9164692,1.6886411,0.010697964,97.448707,0,0,1,,,,1.5147E-5,3.375133,93.421976,1.1177426,0
17957844.42,5905,9.47586,9.6947,-0.137,0.0002901,9.6703835,0.19088971,10.82278,0.02588,14.671264,0.01637,25.494044,0.02588,5.6706248,1.6857204,0.0099820129,97.612993,0,0,1,,,,1.5191E-5,3.377282,93.516318,1.1191677,0
17958501.25,5905,11.009,11.1878,-0.137,0.0002971,11.198869,0.22131487,16.203345,0.03728,20.812496,0.02504,37.01584,0.03728,5.0666094,2.0325386,0.0095927126,98.104762,0,0,1,,,,1.8279E-5,4.062656,125.41466,1.4468733,0
17958535.03,5905,11.0099,11.1823,-0.137,0.0002766,11.198276,0.22124843,16.178805,0.03769,20.809976,0.02503,36.988781,0.03769,4.2148619,2.0357957,0.0096019086,98.105662,0,0,1,,,,1.8237E-5,4.065077,125.40139,1.4447586,0
17958568.92,5905,11.0104,11.1773,-0.137,0.0002901,11.19718,0.22140135,16.209896,0.03729,20.80577,0.02502,37.015666,0.03729,6.06863,2.0423199,0.010289734,97.978537,0,0,1,,,,1.8196E-5,4.071591,125.37683,1.4476767,0
17958820.11,5905,11.9688,12.1144,-0.137,0.0002936,12.137422,0.22424373,20.614834,0.05048,25.216253,0.03217,45.831087,0.05048,1.4500446,2.3299091,0.013821026,97.636571,0,0,1,,,,1.9768E-5,4.08464,147.31701,1.6984524,0
17958854.22,5905,11.977,12.1194,-0.137,0.0002733,12.154159,0.24249406,20.729735,0.05078,25.307207,0.03227,46.036942,0.05078,5.3023613,2.317678,0.012220389,97.896368,0,0,1,,,,1.995E-5,4.659818,147.72359,1.7055672,0
17958888.53,5905,11.9833,12.1186,-0.137,0.0002833,12.158339,0.24167618,20.729625,0.04865,25.327749,0.03229,46.057373,0.04865,9.9413392,2.3189195,0.013184037,97.733732,0,0,1,,,,1.9955E-5,4.635356,147.8252,1.7049718,0
17959146.41,5905,12.973,13.1011,-0.137,0.0002867,13.141714,0.2417644,26.424711,0.05988,30.375963,0.03594,56.800674,0.05988,1.7920743,2.6306434,0.014398885,97.826895,0,0,1,,,,2.1696E-5,4.637839,172.70464,2.0107508,0
17959182.89,5905,12.9789,13.1049,-0.137,0.0002936,13.158433,0.26304663,26.609486,0.05715,30.447946,0.03598,57.057432,0.05715,12.180391,2.623963,0.012472011,98.110391,0,0,1,,,,2.1836E-5,5.261287,173.14437,2.0222381,0
17959219.14,5905,12.9843,13.1064,-0.137,0.0002799,13.1626,0.26221869,26.65942,0.05969,30.469667,0.03599,57.129087,0.05969,10.429329,2.6216514,0.012556568,98.096183,0,0,1,,,,2.1884E-5,5.247926,173.25404,2.0253916,0
17959479.88,5905,13.9748,14.0923,-0.137,0.0002936,14.146838,0.26209157,33.494696,0.06941,35.968655,0.0386,69.463352,0.06941,1.9343912,2.9746605,0.016038971,97.865008,0,0,1,,,,2.3471E-5,5.243303,200.13302,2.3676454,0
17959517.14,5905,13.9799,14.0967,-0.137,0.0002799,14.164791,0.28422291,33.682439,0.06958,36.055888,0.0387,69.738326,0.06958,16.91915,2.9586223,0.012985895,98.258532,0,0,1,,,,2.3669E-5,5.949321,200.64131,2.3778987,0
17959553.72,5905,13.9839,14.1013,-0.137,0.0002867,14.168689,0.28328391,33.753638,0.06866,36.078099,0.03873,69.831737,0.06866,16.547625,2.961581,0.012704911,98.297626,0,0,1,,,,2.3675E-5,5.917245,200.75176,2.3822696,0
17959821.89,5905,14.9764,15.0911,-0.137,0.0002766,15.155042,0.28204295,42.159647,0.08791,42.106675,0.04969,84.266321,0.08791,3.0765476,3.3547005,0.017010329,97.991942,0,0,1,,,,2.5248E-5,5.923162,229.67529,2.7818892,0
17959866.56,5905,14.983,15.0962,-0.137,0.0003007,15.173528,0.30447585,42.322004,0.09046,42.238657,0.04995,84.560661,0.09046,9.3303484,3.3498585,0.016233437,98.08003,0,0,1,,,,2.5367E-5,6.709401,230.23594,2.7892001,0
17959910.91,5905,14.987,15.0998,-0.137,0.0002936,15.1776,0.3044112,42.34478,0.08721,42.263691,0.05,84.608471,0.08721,41.442922,3.3442965,0.015639339,98.146608,0,0,1,,,,2.542E-5,6.699717,230.35955,2.7899522,0
17960179.11,5905,15.9784,16.0805,-0.137,0.0002833,16.156838,0.29954505,52.205008,0.1049,48.683645,0.06261,100.88865,0.1049,1.6343083,3.7309649,0.017289322,98.159866,0,0,1,,,,2.7177E-5,6.688593,261.04342,3.2311401,0
17960226.11,5905,15.9691,16.0949,-0.137,0.0002867,16.166919,0.32324897,52.388999,0.1152,48.73653,0.06267,101.12553,0.1152,0.79971277,3.7292075,0.015367197,98.36197,0,0,1,,,,2.7239E-5,7.46193,261.36926,3.2405061,0
17960273.27,5905,15.9693,16.1151,-0.137,0.0002867,16.174584,0.32362649,52.447885,0.113,48.791477,0.06273,101.23936,0.113,4.4367862,3.7657542,0.016998614,98.206936,0,0,1,,,,2.7017E-5,7.458415,261.61718,3.242611,0
17960542.88,5905,16.9827,17.096,-0.137,0.0002799,17.17257,0.32079029,64.014358,0.1266,55.732231,0.06673,119.74659,0.1266,2.0351124,4.2090189,0.018627748,98.234549,0,0,1,,,,2.8597E-5,7.531508,294.89716,3.7277098,0
17960592.98,5905,16.9892,17.0958,-0.137,0.0002833,17.190949,0.34597852,64.297384,0.1286,55.850235,0.06686,120.14762,0.1286,27.285758,4.1954157,0.017131804,98.369835,0,0,1,,,,2.8774E-5,8.418038,295.52871,3.7401882,0
17960642.41,5905,16.9901,17.0999,-0.137,0.0002799,17.19302,0.34533707,64.306391,0.1228,55.863989,0.06687,120.17038,0.1228,20.326044,4.1916875,0.016632107,98.415682,0,0,1,,,,2.8801E-5,8.390831,295.59993,3.7402616,0
17960914.41,5905,17.963,18.1087,-0.137,0.0003043,18.16665,0.34089616,77.277619,0.164,63.044255,0.0778,140.32187,0.164,1.2318973,4.709265,0.020949187,98.214587,0,0,1,,,,2.9962E-5,8.383375,330.02716,4.2538179,0
17960967.38,5905,17.9715,18.1225,-0.137,0.0002971,18.193088,0.36856677,77.799743,0.1623,63.237822,0.07814,141.03757,0.1623,5.6411882,4.7049288,0.019960687,98.296029,0,0,1,,,,3.0135E-5,9.41853,330.98844,4.2763353,0
17961020.03,5905,17.9791,18.1296,-0.137,0.0003007,18.202605,0.3683717,77.87068,0.1583,63.309313,0.07827,141.17999,0.1583,50.179114,4.6919309,0.01885717,98.385257,0,0,1,,,,3.0241E-5,9.409858,331.33483,4.2779964,0
17961297.66,5905,18.9693,19.0912,-0.137,0.0002936,19.17409,0.3619828,92.490659,0.1908,71.076731,0.09439,163.56739,0.1908,1.5260565,5.2099927,0.022398679,98.261169,0,0,1,,,,3.1573E-5,9.383862,367.64574,4.8237313,0
17961353.11,5905,18.9764,19.1038,-0.137,0.0002867,19.198454,0.38920714,93.02368,0.187,71.264966,0.09487,164.28865,0.187,22.885544,5.2006987,0.019978147,98.44462,0,0,1,,,,3.175E-5,10.41999,368.58062,4.8453736,0
17961409.5,5905,18.9835,19.1112,-0.137,0.0002799,19.207102,0.38865239,93.204451,0.1861,71.335005,0.09505,164.53946,0.1861,50.713098,5.2021927,0.020006539,98.442656,0,0,1,,,,3.179E-5,10.4014,368.91278,4.8526035,0
17961706.28,5905,19.9586,20.1024,-0.137,0.0002971,20.173525,0.38296082,109.33782,0.2189,79.390585,0.1192,188.72841,0.2189,1.3534345,5.7070406,0.022012398,98.425408,0,0,1,,,,3.3248E-5,10.40439,406.97111,5.4198669,0
17961763.66,5905,19.96,20.1326,-0.137,0.0002867,20.198598,0.40971198,110.01456,0.2335,79.600976,0.1199,189.61553,0.2335,21.713227,5.7782144,0.023156541,98.36332,0,0,1,,,,3.3E-5,11.41408,407.98335,5.4466433,0
17961823.16,5905,19.9703,20.1508,-0.137,0.0003043,20.214733,0.41123776,110.20305,0.2322,79.7385,0.1204,189.94155,0.2322,4.5004654,5.7736657,0.022361742,98.417979,0,0,1,,,,3.3077E-5,11.55643,408.63541,5.4516207,0
17962242.31,5905,22.9984,23.1085,-0.137,0.0003007,23.23483,0.45420133,171.18247,0.3088,107.02291,0.1516,278.20538,0.3088,15.996716,7.5422719,0.027225074,98.480538,0,0,1,,,,3.7102E-5,13.88486,539.85732,7.3674942,0
17962319.89,5905,23.0032,23.1009,-0.137,0.0002867,23.254705,0.47711541,171.59144,0.3115,107.19784,0.1519,278.78928,0.3115,38.748784,7.4899505,0.024029355,98.648752,0,0,1,,,,3.7416E-5,15.08454,540.7813,7.3787838,0
17962398.73,5905,23.0033,23.0985,-0.137,0.0002971,23.254276,0.47574038,171.43957,0.3073,107.19077,0.1519,278.63034,0.3073,11.393453,7.4718183,0.023355289,98.683619,0,0,1,,,,3.748E-5,14.9799,540.76133,7.3723892,0
17962743.09,5905,24.9843,25.0848,-0.137,0.0002936,25.213883,0.46534527,218.6798,0.4406,126.89115,0.19,345.57095,0.4406,0.84371247,8.8741724,0.032082242,98.448811,0,0,1,,,,3.9188E-5,14.94364,635.73989,8.6729918,0
17962828.08,5905,24.9936,25.0931,-0.137,0.0003154,25.258286,0.52329943,220.33066,0.4089,127.32065,0.191,347.6513,0.4089,21.182292,8.8087654,0.027185922,98.673719,0,0,1,,,,3.968E-5,17.74834,637.98101,8.723104,0
17962914,5905,24.9975,25.0944,-0.137,0.0003007,25.263645,0.51996006,220.22944,0.3974,127.37011,0.1911,347.59955,0.3974,39.844504,8.7694206,0.02596769,98.727635,0,0,1,,,,3.9843E-5,17.61753,638.25174,8.7172474,0
17963305.36,5905,26.9776,27.169,-0.137,0.0002833,27.230225,0.50917852,274.10014,0.5847,148.56195,0.2459,422.66209,0.5847,0.44472648,10.297183,0.036475295,98.449691,0,0,1,,,,4.1319E-5,17.53884,741.48518,10.066025,0
17963400.42,5905,27.0031,27.1701,-0.137,0.0002936,27.2857,0.56773172,276.04948,0.5194,149.14078,0.2476,425.19026,0.5194,38.054575,10.253073,0.033132993,98.584023,0,0,1,,,,4.1721E-5,20.59437,744.50944,10.117002,0
17963495.36,5905,27.0192,27.1213,-0.137,0.0002971,27.311969,0.56473659,275.36725,0.4955,149.40564,0.2483,424.77288,0.4955,1.3020813,10.033707,0.024568435,98.927924,0,0,1,,,,4.2528E-5,20.50615,745.94366,10.082292,0
17963882.19,5905,28.9786,29.1649,-0.137,0.0003007,29.240529,0.54838085,335.73655,0.7926,171.58626,0.2814,507.32281,0.7926,0.65464418,11.90169,0.046057886,98.274546,0,0,1,,,,4.2955E-5,20.06741,855.00856,11.48189,0
17963986.3,5905,28.9999,29.1701,-0.137,0.0003043,29.307772,0.61383687,337.51705,0.6577,172.31638,0.2817,509.83343,0.6577,1.2893368,11.618167,0.035486026,98.63713,0,0,1,,,,4.4149E-5,23.80338,858.94548,11.516299,0
17964088.36,5905,29.0239,29.127,-0.137,0.0003043,29.32856,0.60537102,338.24198,0.6589,172.59212,0.2819,510.8341,0.6589,3.9501437,11.695867,0.037796282,98.557912,0,0,1,,,,4.3958E-5,23.23633,860.1644,11.532853,0
17964523.41,5905,30.9913,31.1816,-0.137,0.0003007,31.268782,0.59826479,399.57618,0.9269,196.34408,0.3351,595.92026,0.9269,0.32874785,13.245836,0.045863133,98.435048,0,0,1,,,,4.5312E-5,23.39173,977.73672,12.778757,0
17964636.02,5905,31.0226,31.1469,-0.137,0.0003043,31.335167,0.65366465,403.77496,0.8985,197.15553,0.3381,600.93048,0.8985,0.70245568,13.297646,0.04492935,98.469436,0,0,1,,,,4.5509E-5,26.49167,981.89271,12.885681,0
17964765.19,5905,31.0071,31.1212,-0.137,0.0002936,31.339324,0.65037796,400.79238,0.8176,197.15043,0.3381,597.94281,0.8176,0.13949261,12.676168,0.02793542,99.003797,0,0,1,,,,4.7384E-5,26.59529,982.1532,12.788801,0
17965254.88,5905,33.0116,33.1635,-0.137,0.0002971,33.296757,0.62978881,471.15091,1.322,222.35349,0.4032,693.50439,1.322,0.33052925,15.112956,0.058415644,98.22769,0,0,1,,,,4.6272E-5,25.35234,1108.674,14.150054,0
17965379.66,5905,33.0202,33.1159,-0.137,0.0002971,33.372722,0.69864209,471.77852,0.7915,223.2084,0.4046,694.98692,0.7915,1.8986309,14.192247,0.033311384,98.924276,0,0,1,,,,4.9215E-5,30.22591,1113.7386,14.136651,0
17965514.36,5905,33.0021,33.1297,-0.137,0.0002833,33.337466,0.67581842,472.58248,0.8248,222.79722,0.4039,695.3797,0.8248,1.0458859,14.345447,0.04053305,98.703559,0,0,1,,,,4.8769E-5,28.38449,1111.3867,14.175717,0
17966067.45,5905,35.0226,35.1222,-0.137,0.0003079,35.337055,0.67008181,542.31555,1.021,249.64503,0.4298,791.96058,1.021,0.27176251,15.848853,0.04513594,98.681643,0,0,1,,,,5.0284E-5,28.69089,1248.7075,15.346937,0
17966215.42,5905,35.007,35.1214,-0.137,0.0002867,35.351813,0.72440806,544.04441,0.8953,249.82509,0.4299,793.8695,0.8953,1.0379959,15.827452,0.041854911,98.774628,0,0,1,,,,5.0451E-5,31.69771,1249.7507,15.389435,0
17966389.91,5905,35.0037,35.1194,-0.137,0.0003007,35.350286,0.72428656,544.14499,0.885,249.80863,0.4299,793.95362,0.885,69.611588,15.887209,0.042953614,98.74709,0,0,1,,,,5.0273E-5,31.6549,1249.6427,15.392945,0
17966954.45,5905,37.0185,37.1242,-0.137,0.0003007,37.347543,0.71470776,615.152,0.9689,277.0737,0.4652,892.2257,0.9689,0.4481585,17.140523,0.041338179,98.874147,0,0,1,,,,5.2336E-5,31.77442,1394.839,16.471017,0
17967112.38,5905,37.0075,37.1303,-0.137,0.0003079,37.352373,0.76319128,620.21449,1.002,277.14449,0.4653,897.35898,1.002,9.3597542,17.514122,0.049296879,98.682068,0,0,1,,,,5.1564E-5,34.28105,1395.1998,16.60442,0
17967271.25,5905,37.0093,37.1143,-0.137,0.0003154,37.367218,0.76994178,619.88682,0.9419,277.34335,0.4657,897.23017,0.9419,7.7037269,17.360524,0.045059519,98.785241,0,0,1,,,,5.1986E-5,35.02824,1396.309,16.589055,0
17967838.09,5905,39.0189,39.1244,-0.137,0.0002936,39.359574,0.76122881,690.45419,1.101,304.92025,0.5059,995.37444,1.101,0.42637534,18.741798,0.043228414,98.914937,0,0,1,,,,5.3391E-5,34.72105,1549.176,17.542217,0
17968007.69,5905,39.006,39.128,-0.137,0.0002936,39.366166,0.81278421,694.11142,1.094,305.01754,0.506,999.12896,1.094,5.1305454,19.03833,0.048482217,98.799701,0,0,1,,,,5.2788E-5,37.4836,1549.6951,17.632182,0
17968177.5,5905,39.008,39.1106,-0.137,0.0003043,39.382145,0.81885899,693.56313,1.059,305.24387,0.5062,998.807,1.059,16.106368,18.965553,0.046063302,98.85589,0,0,1,,,,5.2959E-5,38.07666,1550.9533,17.611106,0
17969038.8,5905,45.0143,45.1435,-0.137,0.0002936,45.313532,0.88795776,908.97552,1.155,398.83389,0.5804,1307.8094,1.155,7.1562396,23.181895,0.059180055,98.796012,0,0,1,,,,5.6748E-5,41.52467,2053.3161,20.059693,0
17969237.5,5905,45.008,45.1287,-0.137,0.0002867,45.36475,0.94690964,911.43332,1.215,399.67435,0.5817,1311.1077,1.215,9.0882053,23.238106,0.058401333,98.814444,0,0,1,,,,5.6749E-5,46.36379,2057.9605,20.091223,0
17969436.02,5905,45.0066,45.1141,-0.137,0.0002799,45.387801,0.94767334,911.54713,1.176,400.06382,0.5823,1311.6109,1.176,18.453848,23.177412,0.056621623,98.847942,0,0,1,,,,5.6909E-5,46.47621,2060.0525,20.083527,0
17970224.69,5905,50.0216,50.1494,-0.137,0.0003116,50.31269,0.94946476,1093.3613,2.04,488.13774,0.7032,1581.4991,2.04,0.17925053,26.6689,0.07186768,98.73774,0,0,1,,,,5.9665E-5,46.35482,2531.3667,21.731323,0
17970448.66,5905,50.0098,50.1335,-0.137,0.0002971,50.397142,1.0529896,1098.9083,1.516,489.62858,0.7049,1588.5369,1.516,11.298282,26.497721,0.063892291,98.869632,0,0,1,,,,6.0279E-5,53.3378,2539.8719,21.804973,0
17970671.39,5905,50.0081,50.1174,-0.137,0.0002936,50.422307,1.0494687,1098.8523,1.511,490.08972,0.7054,1588.942,1.511,10.905305,26.49907,0.064015924,98.867941,0,0,1,,,,6.0291E-5,52.99544,2542.4091,21.792979,0
17971508.3,5905,55.019,55.1513,-0.137,0.0002936,55.353491,1.0571853,1286.9957,2.418,585.71343,0.7973,1872.7091,2.418,0.17377712,30.045142,0.080309157,98.757206,0,0,1,,,,6.2701E-5,52.99814,3064.009,23.250488,0
17971756.09,5905,55.0069,55.1349,-0.137,0.0002971,55.440388,1.1609432,1291.4688,1.723,587.44596,0.799,1878.9148,1.723,23.349337,29.806056,0.071570321,98.883274,0,0,1,,,,6.3375E-5,60.09028,3073.6366,23.294729,0
17972002.06,5905,55.0011,55.1218,-0.137,0.0003043,55.464249,1.1563421,1293.307,1.747,587.92558,0.7995,1881.2326,1.747,17.177725,29.823979,0.071246458,98.888735,0,0,1,,,,6.3414E-5,59.61211,3076.283,23.31785,0
17972889.31,5905,60.0191,60.1355,-0.137,0.0003079,60.388982,1.1566224,1486.3036,2.876,694.38293,0.9046,2180.6865,2.876,0.16290427,33.359201,0.090502297,98.750985,0,0,1,,,,6.5755E-5,59.64796,3646.8292,24.612165,0
17973160.58,5905,60.0065,60.1258,-0.137,0.0002971,60.484128,1.2635099,1491.9518,1.977,696.45355,0.9061,2188.4054,1.977,13.392763,33.035149,0.078290486,98.908486,0,0,1,,,,6.6585E-5,66.7184,3658.3297,24.666832,0
17973429.61,5905,60.0039,60.1082,-0.137,0.0003116,60.506737,1.2549794,1491.7729,1.896,696.98338,0.9065,2188.7563,1.896,34.846909,32.94074,0.076952834,98.9244,0,0,1,,,,6.6782E-5,66.0703,3661.0652,24.654658,0
17974343.48,5905,65.022,65.1431,-0.137,0.0003154,65.424944,1.2403563,1689.5457,3.413,814.71051,0.9709,2504.2562,3.413,0.12396521,36.536737,0.1009257,98.742827,0,0,1,,,,6.8939E-5,65.88148,4280.4233,25.824183,0
17974635.98,5905,65.0025,65.1243,-0.137,0.0003154,65.526343,1.3606358,1695.4949,2.123,817.14948,0.9727,2512.6444,2.123,34.02797,36.131664,0.086997533,98.903827,0,0,1,,,,6.9893E-5,73.07347,4293.7016,25.875011,0
17974925.88,5905,64.9941,65.1153,-0.137,0.0003116,65.550706,1.3513031,1695.5248,2.098,817.7682,0.9732,2513.293,2.098,21.04688,36.068274,0.08548145,98.921305,0,0,1,,,,7.0028E-5,72.26333,4296.895,25.865851,0
17975923.95,5905,70.0206,70.1364,-0.137,0.0002936,70.468127,1.3385712,1890.8403,3.837,943.72198,1.087,2834.5623,3.837,0.12823771,39.647268,0.11294944,98.718968,0,0,1,,,,7.1909E-5,72.13655,4965.757,26.832561,0
17976238.23,5905,70.007,70.1142,-0.137,0.0003079,70.57426,1.460069,1895.9895,2.296,946.43405,1.088,2842.4235,2.296,30.955341,39.062653,0.093912169,98.918779,0,0,1,,,,7.312E-5,79.29454,4980.7262,26.865169,0
17976548.3,5905,70.0043,70.1041,-0.137,0.0003007,70.594451,1.4480011,1895.6788,2.219,946.9762,1.089,2842.655,2.219,8.1524332,39.001901,0.092072503,98.938553,0,0,1,,,,7.3234E-5,78.12531,4983.5766,26.853085,0
17977592.59,5905,75.0157,75.1404,-0.137,0.0003116,75.505655,1.43796,2089.9692,4.001,1081.3956,1.108,3171.3649,4.001,0.15377542,42.500047,0.12301643,98.714017,0,0,1,,,,7.5044E-5,78.0038,5701.104,27.679639,0
17977927.45,5905,75.0059,75.1128,-0.137,0.0003116,75.622446,1.5627745,2095.7289,2.587,1084.6786,1.109,3180.4075,2.587,10.107218,41.977436,0.10499348,98.888624,0,0,1,,,,7.6135E-5,85.00009,5718.7543,27.713053,0
17978257.34,5905,75.0015,75.1031,-0.137,0.0003043,75.646489,1.5511091,2095.5619,2.471,1085.3724,1.109,3180.9343,2.471,6.6640444,41.845937,0.10100649,98.927665,0,0,1,,,,7.6374E-5,83.95487,5722.3913,27.702038,0
17979312.75,5905,80.0138,80.1355,-0.137,0.0003079,80.539653,1.5379833,2298.3406,4.741,1233.0767,1.177,3531.4173,4.741,0.15188666,45.429873,0.13900826,98.656216,0,0,1,,,,7.8183E-5,83.69187,6486.6358,28.536758,0
17979667.56,5905,80.0038,80.1095,-0.137,0.0003387,80.668148,1.6650209,2301.8958,2.844,1236.9312,1.179,3538.8271,2.844,8.4969662,44.755067,0.11519754,98.869804,0,0,1,,,,7.9454E-5,90.85975,6507.3501,28.535375,0
17980018.31,7697,80.0031,80.0941,-0.137,0.0003079,80.69259,1.650229,2302.1539,2.666,1237.7244,1.18,3539.8782,2.666,3.7583322,44.564662,0.10959211,98.9203,0,0,1,,,,7.98E-5,89.51013,6511.294,28.529929,0
17981018.56,7697,85.0101,85.1419,-0.137,0.0003191,85.56262,1.6354743,2500.7778,5.019,1391.4143,1.273,3892.1921,5.019,0.13950754,47.891319,0.14706964,98.666048,0,0,1,,,,8.1726E-5,89.12932,7320.962,29.227457,0
17981390.73,7697,85.0064,85.1178,-0.137,0.0003116,85.691215,1.7605555,2506.804,3.135,1395.5614,1.275,3902.3654,3.135,4.9535946,47.412848,0.12936051,98.814738,0,0,1,,,,8.2715E-5,95.78264,7342.9842,29.253921,0
17981759.23,7697,85.0051,85.1016,-0.137,0.0003191,85.727761,1.750146,2504.981,2.851,1396.7271,1.276,3901.708,2.851,10.527505,47.127398,0.12095327,98.885432,0,0,1,,,,8.3176E-5,94.8257,7349.2489,29.220184,0
17982635.53,7697,90.0103,90.2043,-0.137,0.0018629,90.376615,1.5936758,2681.1807,3.532,1549.7927,1.359,4230.9734,3.532,2.9750485,40.847576,0.14462287,98.479154,0,0,1,,,,0.00010422,94.2548,8167.9325,29.666753,0
17982914.27,7697,90.0109,90.1648,-0.137,0.002405,90.434596,1.4871869,2699.803,6.007,1552.0471,1.36,4251.8501,6.007,0.38886964,39.81211,0.18073358,98.048548,0,0,1,,,,0.00010766,81.69515,8178.4161,29.853653,0
17983186.11,7697,90.0137,90.1114,-0.137,0.0026856,90.531095,1.4486236,2693.393,3.591,1555.0135,1.361,4248.4066,3.591,1.4623705,38.220278,0.14884531,98.327079,0,0,1,,,,0.00011192,79.62422,8195.8791,29.751027,0
17984266.64,7697,95.0125,95.1254,-0.137,0.0035946,95.443369,1.3959455,2889.8326,7.561,1718.5686,1.423,4608.4012,7.561,0.086194677,39.46655,0.1778949,98.080152,0,0,1,,,,0.00011767,76.44056,9109.4366,30.277982,0
17984536.55,7697,95.0027,95.1046,-0.137,0.0036894,95.561632,1.4685206,2878.1056,3.266,1722.6266,1.426,4600.7322,3.266,1.8259961,38.670698,0.1505526,98.343706,0,0,1,,,,0.00011976,78.9331,9132.0256,30.117794,0
17984801.48,7697,95.0008,95.089,-0.137,0.0035022,95.599638,1.449942,2873.7875,3.66,1723.8684,1.426,4597.6559,3.66,0.13278665,38.286782,0.13799541,98.467124,0,0,1,,,,0.00012082,77.3414,9139.2907,30.060652,0
17985839.75,7697,100.005,100.124,-0.137,0.0035946,100.46777,1.452148,3061.4025,8.304,1897.7408,1.576,4959.1433,8.304,0.072965769,41.698439,0.19052103,98.074517,0,0,1,,,,0.00011982,76.57356,10093.773,30.471488,0
17986123.44,7697,100.011,100.1,-0.137,0.0035946,100.60954,1.5673511,3066.5447,3.544,1902.7512,1.581,4969.2959,3.544,1.1584641,40.905555,0.15990424,98.351967,0,0,1,,,,0.00012226,83.39688,10122.279,30.479662,0
17986401.36,7697,100.009,100.094,-0.137,0.0034568,100.6462,1.548237,3063.1149,4.055,1904.1093,1.582,4967.2242,4.055,0.10811876,40.585509,0.14758241,98.467244,0,0,1,,,,0.00012312,81.81111,10129.658,30.434481,0
17987771.34,5905,110.017,110.169,-0.137,0.0003191,110.78949,2.219588,3461.368,5.044,2291.9632,1.722,5753.3312,5.044,1.4966924,58.704047,0.2110416,98.50611,0,0,1,,,,9.8546E-5,112.1233,12274.312,31.242746,0
17988219.64,5905,110.01,110.135,-0.137,0.0003268,110.92099,2.2681481,3463.9245,4.435,2296.65,1.726,5760.5746,4.435,1.5721979,58.180063,0.18969428,98.644995,0,0,1,,,,9.9506E-5,117.4081,12303.465,31.228757,0
17988663.5,5905,110.012,110.115,-0.137,0.0003154,110.9733,2.2543361,3461.1742,3.821,2298.567,1.728,5759.7412,3.821,9.8677354,57.770972,0.17216892,98.761505,0,0,1,,,,0.00010015,116.3601,12315.073,31.189252,0
17989963.5,5905,120.013,120.193,-0.137,0.0003116,120.75161,2.2915881,3817.7653,9.475,2680.4643,2.095,6498.2295,9.475,0.11832121,62.466017,0.26141778,98.282157,0,0,1,,,,0.00010466,115.5419,14580.951,31.616682,0
17990370.66,5905,120.007,120.147,-0.137,0.000323,120.98129,2.4780597,3825.2862,5.004,2689.4591,2.105,6514.7453,5.004,1.3367868,61.371159,0.21576423,98.556036,0,0,1,,,,0.00010669,124.932,14636.472,31.618825,0
17990836.66,5905,119.998,120.123,-0.137,0.0003191,121.04102,2.4543223,3820.5775,4.362,2691.8242,2.108,6512.4017,4.362,21.511093,60.957309,0.20070768,98.647822,0,0,1,,,,0.00010734,122.7423,14650.928,31.564321,0
17992238.23,5905,130.004,130.176,-0.137,0.0003191,130.90622,2.4894012,4160.1306,9.763,3096.5745,2.578,7256.7051,9.763,0.12180602,64.681147,0.27849068,98.250362,0,0,1,,,,0.00011285,121.9146,17136.438,31.779472,0
17992726.91,5905,130.005,130.155,-0.137,0.0003191,131.11354,2.6634183,4166.5735,5.229,3105.0039,2.583,7271.5775,5.229,4.7079102,63.636936,0.23452756,98.501396,0,0,1,,,,0.00011484,129.3623,17190.76,31.778362,0
17993208.94,5905,129.999,130.141,-0.137,0.0003268,131.1592,2.6381812,4163.107,4.853,3106.8423,2.584,7269.9493,4.853,1.320034,63.218877,0.21421564,98.621876,0,0,1,,,,0.00011553,127.2739,17202.735,31.74087,0
17994566.23,5905,140.008,140.158,-0.137,0.000323,140.95344,2.6626656,4482.6749,10.2,3512.4223,2.694,7995.0972,10.2,0.1203647,66.432047,0.30274539,98.162326,0,0,1,,,,0.00012106,126.4378,19867.871,31.802523,0
17995067.09,5905,140.001,140.127,-0.137,0.0003191,141.1739,2.848446,4486.0431,5.312,3521.534,2.699,8007.5771,5.312,4.0020865,65.4416,0.2557,98.423279,0,0,1,,,,0.00012298,132.8641,19930.07,31.776717,0
17995562.56,5905,139.996,140.117,-0.137,0.0003308,141.21987,2.8241557,4482.1251,4.863,3523.4122,2.701,8005.5373,4.863,1.834075,65.045963,0.24000005,98.510879,0,0,1,,,,0.00012366,130.8832,19943.051,31.73863,0
17996991.48,5905,150.012,150.157,-0.137,0.0003116,151.05721,2.8631065,4783.0684,11.38,3929.6715,3.043,8712.74,11.38,0.1159537,67.829074,0.33106626,98.043865,0,0,1,,,,0.00012923,130.0919,22818.279,31.663954,0
17997501.64,5905,149.999,150.128,-0.137,0.0003308,151.27679,3.0410279,4780.7215,5.512,3938.6613,3.048,8719.3828,5.512,5.2479061,66.569695,0.27260255,98.357303,0,0,1,,,,0.00013164,135.6581,22884.667,31.602478,0
17998003.11,5905,150.006,150.129,-0.137,0.0003308,151.32176,3.0078023,4778.9201,5.209,3940.4482,3.049,8719.3682,5.209,1.4945676,66.151476,0.25469742,98.455037,0,0,1,,,,0.00013243,133.1394,22898.274,31.581183,0
17999401.53,5905,160.008,160.178,-0.137,0.0003347,161.17363,3.0391404,5067.5977,11.52,4344.5406,3.176,9412.1383,11.52,0.1228311,68.385452,0.35282237,97.941771,0,0,1,,,,0.00013848,132.303,25976.94,31.441853,0
17999916.48,5905,159.996,160.151,-0.137,0.0003154,161.39875,3.225086,5069.8892,5.875,4353.8077,3.18,9423.6969,5.875,8.4554942,67.293288,0.29581013,98.244403,0,0,1,,,,0.00014077,136.7709,26049.557,31.412196,0
18000423.69,5905,160.005,160.139,-0.137,0.0003308,161.44197,3.1950914,5063.1942,5.526,4355.53,3.181,9418.7242,5.526,1.0466495,66.875146,0.27912597,98.332694,0,0,1,,,,0.00014153,134.5866,26063.51,31.362317,0
18001872.91,5905,170.009,170.177,-0.137,0.0003428,171.28596,3.2366656,5335.7899,12.38,4753.6506,3.412,10089.441,12.38,0.11417577,68.573026,0.37416266,97.830846,0,0,1,,,,0.00014805,133.7503,29338.879,31.151357,0
18002389.02,5905,170.001,170.176,-0.137,0.0003511,171.5023,3.4049558,5332.2995,5.76,4762.2048,3.416,10094.504,5.76,9.1694126,67.348782,0.3123764,98.153832,0,0,1,,,,0.00015067,137.1461,29413.039,31.091708,0
18002897.14,5905,169.996,170.172,-0.137,0.0003511,171.54073,3.3696429,5325.5362,5.652,4763.7746,3.417,10089.311,5.652,0.86620924,66.992512,0.29528676,98.245036,0,0,1,,,,0.00015136,134.6976,29426.222,31.045316,0
18004236.59,5905,179.995,180.148,-0.137,0.0003682,181.31947,3.4203028,5580.6434,14.08,5139.6402,3.551,10720.284,14.08,0.1016823,68.580711,0.40623275,97.651858,0,0,1,,,,0.00015734,133.985,32876.749,30.777961,0
18004754.44,5905,179.99,180.137,-0.137,0.0003553,181.55888,3.6004166,5572.7625,6.057,5148.7792,3.554,10721.542,6.057,8.5661375,67.19177,0.33293561,98.032682,0,0,1,,,,0.00016044,137.1614,32963.627,30.693968,0
18005260.17,5905,179.998,180.127,-0.137,0.0003387,181.59613,3.5609701,5567.7683,6.012,5150.2384,3.554,10718.007,6.012,0.60391078,66.803639,0.31069822,98.152515,0,0,1,,,,0.00016126,134.3835,32977.156,30.66017,0
18006635.08,5905,190.005,190.138,-0.137,0.0003308,191.4303,3.6218529,5799.0476,14.44,5521.9611,3.675,11321.009,14.44,0.10356434,67.907625,0.42718385,97.511679,0,0,1,,,,0.00016784,133.6073,36645.559,30.293259,0
18007147.97,5905,190.004,190.114,-0.137,0.0003727,191.65695,3.7844738,5795.0952,6.152,5530.209,3.68,11325.304,6.152,28.700982,66.578544,0.35201618,97.904878,0,0,1,,,,0.00017106,135.8153,36732.388,30.236812,0
18007649.64,5905,189.989,190.104,-0.137,0.0003511,191.69083,3.7460209,5790.3306,6.491,5531.5261,3.681,11321.857,6.491,0.37557026,66.215571,0.33598439,97.98861,0,0,1,,,,0.00017191,133.1571,36745.375,30.206612,0
18008982.23,5905,200.011,200.108,-0.137,0.0003511,201.53961,3.8066251,6006.1499,14.74,5886.4545,3.988,11892.604,14.74,0.10952563,67.031446,0.44572871,97.373771,0,0,1,,,,0.00017865,132.4311,40618.216,29.801336,0
18009487.47,5905,199.997,200.102,-0.137,0.0003817,201.76679,3.9793715,6001.2841,6.427,5894.5632,3.991,11895.847,6.427,7.1265196,65.673576,0.37047544,97.767863,0,0,1,,,,0.00018219,134.0629,40709.837,29.743667,0
18009984.98,5905,200.002,200.084,-0.137,0.0003727,201.79169,3.9330642,5993.5367,6.866,5895.5152,3.991,11889.052,6.866,0.39857065,65.338639,0.35724583,97.835883,0,0,1,,,,0.00018299,131.3472,40719.887,29.701603,0
18011301.23,5905,210.008,210.124,-0.137,0.0004352,211.66249,3.9808503,6213.4658,14.75,6252.2419,4.161,12465.708,14.75,0.12321283,65.66038,0.46642118,97.198181,0,0,1,,,,0.00019122,130.6773,44801.01,29.355536,0
18011797.31,5905,210.011,210.11,-0.137,0.0004962,211.87567,4.1429075,6204.5037,6.816,6261.3878,4.197,12465.891,6.816,3.2346758,64.270468,0.39070368,97.597536,0,0,1,,,,0.00019515,131.3208,44891.298,29.283701,0
18012284.23,5905,210,210.106,-0.137,0.0005266,211.89507,4.0902962,6200.3308,7.198,6262.1351,4.2,12462.466,7.198,0.43736146,63.921648,0.37777715,97.663585,0,0,1,,,,0.00019613,128.5409,44899.521,29.261326,0
18013517.8,5905,220.007,220.12,-0.137,0.0009004,221.7807,4.094093,6418.3791,18.81,6720.3405,6.669,13138.72,18.81,0.23897676,63.451584,0.48031324,97.017238,0,0,1,,,,0.0002086,127.8433,49186.679,28.940206,0
18013998.23,5905,220.004,220.101,-0.137,0.0004619,221.98782,4.2698442,6334.7281,8.99,6730.1153,6.665,13064.843,8.99,6.7007675,63.232489,0.4396774,97.256207,0,0,1,,,,0.000208,126.9032,49278.591,28.536377,0
18014477.25,5905,220,220.096,-0.137,0.0004404,222.03133,4.2652354,6319.6817,9.382,6731.787,6.664,13051.469,9.382,0.34479049,62.84654,0.40705664,97.441553,0,0,1,,,,0.00020896,126.465,49297.912,28.463018,0
18015559.33,5905,230.011,230.097,-0.137,0.00043,231.8716,4.3091701,6569.4834,15.49,7127.0283,4.687,13696.512,15.49,0.08419661,63.141017,0.52324659,96.737581,0,0,1,,,,0.00021862,125.6931,53764.44,28.332419,0
18016036.72,5905,230.007,230.089,-0.137,0.0004249,232.0875,4.4766444,6470.502,7.464,7134.5312,4.703,13605.033,7.464,2.3984254,61.768557,0.45459251,97.095637,0,0,1,,,,0.00022176,126.282,53864.606,27.87958,0
18016505.59,5905,230.002,230.085,-0.137,0.0004249,232.09984,4.4252229,6464.0631,7.979,7134.9643,4.704,13599.027,7.979,0.43992888,61.624543,0.4435172,97.15869,0,0,1,,,,0.00022214,123.5371,53870.335,27.850356,0
18017504.48,5905,240.012,240.088,-0.137,0.0004457,241.96471,4.5039151,6838.5212,19.66,7413.3061,7.172,14251.827,19.66,0.49202708,61.660494,0.45244785,97.105608,0,0,1,,,,0.00023273,123.2491,58546.919,28.262474,0
18017973.56,5905,240.002,240.07,-0.137,0.0004249,242.1608,4.6649502,6623.6384,9.187,7418.2823,7.158,14041.921,9.187,2.1142311,60.19757,0.46375661,96.960215,0,0,1,,,,0.0002349,123.321,58641.852,27.352232,0
18018430.84,5905,240.001,240.064,-0.137,0.0004404,242.16875,4.601815,6617.056,9.563,7418.5418,7.158,14035.598,9.563,0.42345319,59.945639,0.44864777,97.045367,0,0,1,,,,0.00023574,120.3951,58645.705,27.324153,0
18019334.84,5905,250.018,250.052,-0.137,0.0004352,252.03124,4.7150503,6868.0607,15.22,7634.1784,4.33,14502.239,15.22,0.12387037,59.497732,0.52847851,96.505054,0,0,1,,,,0.00024574,119.8913,63519.746,27.250831,0
18019787.38,5905,250.02,250.042,-0.137,0.0004199,252.19264,4.8056339,6856.0914,7.239,7638.4014,4.314,14494.493,7.239,2.1308156,58.522183,0.46829319,96.845275,0,0,1,,,,0.0002495,118.9955,63601.126,27.18593,0
18020233.88,5905,250.006,250.021,-0.137,0.0004404,252.21424,4.7646481,6844.2213,7.873,7638.9137,4.312,14483.135,7.873,0.49332994,58.372898,0.46271605,96.874157,0,0,1,,,,0.00024992,117.0444,63612.024,27.136538,0
18021190.22,5905,259.996,260.071,-0.137,0.0004149,262.10913,4.8982265,7006.2439,18.12,7921.0187,4.731,14927.263,18.12,0.10073801,57.838414,0.56558374,96.15722,0,0,1,,,,0.00026038,116.7458,68701.198,26.730255,0
18021631.05,5905,260.028,260.041,-0.137,0.0004352,262.27342,4.9772337,6985.436,7.893,7925.7755,4.738,14911.211,7.893,1.8435504,56.863316,0.49323241,96.58267,0,0,1,,,,0.00026428,115.6768,68787.348,26.634174,0
18022064.69,5905,260.001,260.044,-0.137,0.0004619,262.29329,4.9338418,6973.1986,8.179,7926.3838,4.739,14899.582,8.179,0.52012467,56.612041,0.47476162,96.6937,0,0,1,,,,0.00026518,113.7266,68797.768,26.585502,0
18022942.98,5905,270.011,270.096,-0.137,0.000451,272.23136,5.0424032,7133.6843,16.13,8212.898,5.253,15346.582,16.13,0.15454828,55.867738,0.57891332,95.929677,0,0,1,,,,0.00027724,113.2241,74109.912,26.204491,0
18023370.78,5905,270.001,270.085,-0.137,0.0004404,272.39371,5.1238686,7113.7702,8.533,8217.5458,5.26,15331.316,8.533,2.2345705,55.120307,0.51636616,96.311569,0,0,1,,,,0.00028046,111.7355,74198.333,26.115766,0
18023794.45,5905,269.997,270.078,-0.137,0.0004051,272.41768,5.0863008,7108.845,9.323,8218.2978,5.261,15327.143,9.323,0.40605557,54.916561,0.50085544,96.406984,0,0,1,,,,0.00028136,110.2406,74211.39,26.095388,0
18024661.95,5905,280.007,280.106,-0.137,0.00043,282.30794,5.2028267,7266.8865,16.2,8485.6798,5.627,15752.566,16.2,0.18919012,54.064538,0.59896927,95.651801,0,0,1,,,,0.00029422,109.8331,79697.775,25.740992,0
18025076.63,5905,279.999,280.087,-0.137,0.000451,282.46615,5.2767261,7220.8874,8.727,8489.9201,5.631,15710.808,8.727,3.3967578,53.226119,0.54080441,96.002522,0,0,1,,,,0.00029779,108.1291,79787.128,25.563726,0
18025485.92,5905,280.002,280.083,-0.137,0.0004564,282.48879,5.2404374,7216.1706,9.703,8490.4993,5.632,15706.67,9.703,0.49242435,53.153604,0.5303874,96.072411,0,0,1,,,,0.00029807,106.4522,79799.916,25.54498,0
18026401.3,5905,289.986,290.052,-0.137,0.00043,292.32591,5.372056,7387.4291,19.09,8725.7568,5.772,16113.186,19.09,0.15640458,52.441126,0.63693969,95.241124,0,0,1,,,,0.00031053,106.3072,85454.438,25.271209,0
18026804.77,5905,290.004,290.044,-0.137,0.0004352,292.49417,5.4481115,7338.1174,9.686,8729.0454,5.772,16067.163,9.686,1.8208992,51.544059,0.56875108,95.66405,0,0,1,,,,0.0003147,104.8823,85552.837,25.088081,0
18027202.11,5905,289.979,290.045,-0.137,0.0004619,292.50839,5.4040239,7323.3945,10.02,8729.3633,5.772,16052.758,10.02,0.46273914,51.320062,0.53876937,95.86918,0,0,1,,,,0.00031563,103.0881,85561.159,25.036528,0
18028019.52,5905,300.013,300.077,-0.137,0.0004404,302.46144,5.5609419,7474.2725,17.37,8892.5503,5.683,16366.823,17.37,0.13089961,50.546251,0.62636807,95.145203,0,0,1,,,,0.00032729,102.6401,91482.924,24.711489,0
18028409.28,5905,300.017,300.052,-0.137,0.00043,302.62927,5.6227286,7437.6327,9.089,8896.3655,5.689,16333.998,9.089,6.9967743,49.674261,0.57162131,95.481298,0,0,1,,,,0.00033209,101.0925,91584.473,24.576713,0
18028795.53,5905,300.008,300.043,-0.137,0.0004457,302.64341,5.5705151,7443.8274,9.984,8896.6652,5.689,16340.493,9.984,0.65735427,49.601788,0.57029974,95.485296,0,0,1,,,,0.0003327,99.34852,91593.034,24.596033,0
18029682.23,5905,310.009,310.075,-0.137,0.0004564,312.54488,5.6904451,7600.8077,19.22,9153.5473,6.337,16754.355,19.22,0.21051028,48.814586,0.68942957,94.483949,0,0,1,,,,0.00034741,99.20358,97684.303,24.319092,0
18030060.05,5905,310.006,310.061,-0.137,0.0004404,312.71854,5.7782306,7523.3351,10.34,9157.6768,6.344,16681.012,10.34,3.316117,48.116657,0.62801075,94.886472,0,0,1,,,,0.00035053,97.62917,97792.885,24.057848,0
18030434.28,5905,310.004,310.034,-0.137,0.0004249,312.74179,5.7368746,7525.1115,11.01,9158.1691,6.344,16683.281,11.01,0.70617486,47.968352,0.60587683,95.046788,0,0,1,,,,0.00035153,96.23331,97807.429,24.061739,0
18031180.42,5905,320.021,320.006,-0.137,0.0004457,322.54366,5.8688527,7698.2963,20.83,9348.0704,6.397,17046.367,20.83,0.1682805,47.19544,0.70824752,94.147367,0,0,1,,,,0.00036584,95.9367,104034.41,23.867455,0
18031546.94,5905,319.97,319.962,-0.137,0.0004404,322.73432,5.9432378,7634.9474,10.9,9351.1648,6.392,16986.112,10.9,3.3186064,46.431067,0.64471163,94.567742,0,0,1,,,,0.00037014,94.39088,104157.44,23.657067,0
18031909.36,5905,319.982,319.965,-0.137,0.0004457,322.75999,5.8951863,7626.9428,11.09,9351.5464,6.391,16978.489,11.09,0.97139045,46.264859,0.62684292,94.694854,0,0,1,,,,0.00037119,92.86213,104174.01,23.630385,0
18032650.63,5905,330.009,330.046,-0.137,0.0004404,332.69153,6.0449846,7815.6927,20.38,9489.4367,5.881,17305.129,20.38,0.19499453,45.585891,0.72821364,93.783407,0,0,1,,,,0.00038483,92.52972,110683.65,23.492311,0
18033006.42,5905,329.997,330.018,-0.137,0.0004352,332.88595,6.1176411,7777.5451,10.75,9493.008,5.885,17270.553,10.75,3.9589691,44.798076,0.65938366,94.253841,0,0,1,,,,0.00039036,91.17178,110813.06,23.363993,0
18033355.58,5905,330.009,329.982,-0.137,0.00043,332.90149,6.0586309,7778.7345,12.04,9493.4234,5.885,17272.158,12.04,0.72520682,44.720266,0.65508472,94.280506,0,0,1,,,,0.00039105,89.59615,110823.4,23.366475,0
18034156.39,5905,340.011,340,-0.137,0.000473,342.72823,6.1949216,7899.8475,22.47,9707.9284,6.606,17607.776,22.47,0.17557588,43.93018,0.7689113,93.206384,0,0,1,,,,0.0004068,89.44053,117462.64,23.049889,0
18034501.45,5905,339.996,340.007,-0.137,0.00043,342.90992,6.2566215,7868.0439,12.28,9711.6758,6.615,17579.72,12.28,2.8723508,43.163505,0.69716343,93.709879,0,0,1,,,,0.00041285,87.86036,117587.21,22.94493,0
18034839.23,5905,339.986,340.002,-0.137,0.0004352,342.92251,6.1998703,7865.3139,12.62,9712.0656,6.616,17577.379,12.62,1.2247597,43.001059,0.68324438,93.808325,0,0,1,,,,0.00041426,86.32701,117595.85,22.936126,0
18035587.92,5905,349.972,350.004,-0.137,0.0004352,352.7866,6.2968133,7984.2933,21.14,9908.3135,6.925,17892.607,21.14,0.23357717,42.395484,0.80044151,92.689461,0,0,1,,,,0.0004288,86.00212,124458.39,22.632076,0
18036749.33,5905,350.001,349.998,-0.137,0.0004619,353.01447,6.2987677,7946.7897,12.66,9912.3473,6.931,17859.137,12.66,132.69001,41.546778,0.73072781,93.167451,0,0,1,,,,0.00043621,84.79097,124619.22,22.511229,0
18038909.19,5905,350.024,350.004,-0.137,0.0004199,353.00464,6.2227741,7934.1312,12.63,9912.262,6.931,17846.393,12.63,43.379798,41.408245,0.71890738,93.251215,0,0,1,,,,0.00043726,83.09356,124612.28,22.475997,0
18039715.2,5905,359.991,359.984,-0.137,0.0004674,362.8146,6.4984701,7880.9073,22.41,10080.363,7.167,17961.27,22.41,0.18649722,40.411264,0.81066943,92.235499,0,0,1,,,,0.00045182,82.81649,131634.43,21.721583,0
18040033.92,5905,360.029,360.001,-0.137,0.0004674,363.0374,6.5781388,7829.3036,12.71,10083.989,7.171,17913.293,12.71,15.458958,39.574303,0.74378135,92.699942,0,0,1,,,,0.00045959,80.82253,131796.15,21.566108,0
18040347.09,5905,360.006,359.997,-0.137,0.0004787,363.04671,6.4998247,7830.7324,13.44,10084.249,7.172,17914.982,13.44,2.2311987,39.486242,0.73221239,92.793367,0,0,1,,,,0.00046056,79.14861,131802.91,21.56949,0