File: Examples/data/PPMS_ACMS_dataFile.dat
[Header]
; ACMS Data File (default extension .dat)
; Copyright 1999, Quantum Design, Inc. All rights reserved.
TITLE,KA 74
FILEOPENTIME,12009029.45,12-10-2017,10:40 pm
BYAPP,ACMS,1.0,1.1
INFO,PPMS ACMS Option Version: 1.0.9 Build 14,APPNAME
INFO,HARMONICS,1
INFO,,
INFO,,
INFO,,
INFO,,
INFO,,
INFO,,
INFO,,
INFO,,
INFO,,
INFO,,
DATATYPE,COMMENT,1
DATATYPE,TIME,2
FIELDGROUP,AC Mag,2,3,4,5,6,8,9,10,11,12
FIELDGROUP,DC Mag,2,3,4,7,8
STARTUPGROUP,All
STARTUPAXIS,X,2,LINEAR,AUTO
TIMEMODE,MINUTES,RELATIVE
PLOT_APPEARANCE,ALL,HORZ_GRID_ON,VERT_GRID_ON,MARKERS_AND_LINES
RECORDS,ALL_RECORDS
DATATYPE,TIME,2
DATATYPE,COMMENT,1
[Data]
Comment,Time Stamp (sec),Temperature (K),Magnetic Field (Oe),Frequency (Hz),Amplitude (Oe),M-DC (emu),M-Std.Dev. (emu),M' (emu),M'' (emu),Moment (emu),Phase (deg),Calcoil' (emu),Calcoil'' (emu),Calcoil (emu),CC Phase (deg),Count,Gain,Measure Type,Elapsed (sec),Sample Center (cm),Max.Signal (V),PPMS Status (code),DSP Status (code),Min.Temperature (K),Max.Temperature (K),Min.Field (Oe),Max.Field (Oe),DC Position (cm),PPMS Temperature (K),PPMS Position,Bridge 1 Resistance (ohms),Bridge 1 Excitation (uA),Bridge 2 Resistance (ohms),Bridge 2 Excitation (uA),Bridge 3 Resistance (ohms),Bridge 3 Excitation (uA),Bridge 4 Resistance (ohms),Bridge 4 Excitation (uA),Signal 1 Vin (V),Signal 2 Vin (V),Digital Inputs (code),Drive 1 Iout (mA),Drive 1 Ipower (watts),Drive 2 Iout (mA),Drive 2 Ipower (watts),Pressure (),Map 20 (),Map 21 (),Map 22 (),Map 23 (),Map 24 (),Map 25 (),Map 26 (),Map 27 (),Map 28 (),Map 29 ()
,12009096.96,300.0100174,-0.009,1000,9.99889618275839,,1.01012168164324E-5,0.00901332432606876,4.93560772102417E-5,0.00901345945956715,0.313742915532145,-1.52964204511087E-8,4.4310973680105E-10,1.530283715054E-8,178.340708543947,333,5,5,13.4965986394558,0.757658162977266,0.00487719079251167,4369,0,300.0032349,300.0213013,-0.009,-0.009,,297.1605875,,,,,,,,,,,,,,,,,,,,,,,300.0100174
,12009112.78,300.0122833,-0.009,,,0.00618730372610494,0.000201251494969904,,,,,,,,,1,25,0,4.43800021894276,0.757658162977266,5.32660080638425E-5,4369,0,300.0062561,300.0183105,-0.009,-0.009,0.724201874960451,297.12925,,,,,,,,,,,,,,,,,,,,,,,300.0122833
,12009167.25,300.035255425,199.842,1000,9.99874870454451,,8.34631720414686E-6,0.00855608389854633,1.74755338084974E-5,0.00855610174514338,0.117024675249754,-1.52961599981577E-8,4.43315243927573E-10,1.53025827589573E-8,178.339911171317,333,5,5,13.4965986394558,0.757658162977266,0.00463231173913465,4369,0,300.0262146,300.0503235,199.842,199.842,,296.9652375,,,,,,,,,,,,,,,,,,,,,,,300.035255425
,12009180.75,300.04127505,199.842,,,0.204112284939755,0.000202971768469982,,,,,,,,,1,25,0,2.17199963517487,0.757658162977266,0.0010928009369887,4369,0,300.0322266,300.0503235,199.842,199.842,0.741201360844891,297.06275,,,,,,,,,,,,,,,,,,,,,,,300.04127505
,12009243.23,300.071132675,399.987,1000,9.99846661318221,,7.2952540828915E-6,0.00794596230018417,1.42515042024492E-6,0.0079459624279883,0.0102763013831399,-1.52965906358125E-8,4.43000666994189E-10,1.53030041060762E-8,178.341135189965,333,5,5,13.4965986394558,0.757658162977266,0.00430796893955925,4369,0,300.0414124,300.1076355,399.987,399.987,,296.9015875,,,,,,,,,,,,,,,,,,,,,,,300.071132675
,12009256.61,300.0669861,399.987,,,0.387023264290546,0.00017399674660255,,,,,,,,,1,25,0,2.21900010947138,0.757658162977266,0.00206053514261884,4369,0,300.0654602,300.068512,399.987,399.987,0.703987091248782,296.8766,,,,,,,,,,,,,,,,,,,,,,,300.0669861
,12009319.18,300.0629539625,600.104,1000,9.99868399300036,,7.53556884399872E-6,0.0072196528430161,-4.96521873423502E-6,0.00721965455039696,-0.0394043923114396,-1.52962292820227E-8,4.43273697568399E-10,1.53026508102082E-8,178.340074177925,333,5,5,13.4965986394558,0.757658162977266,0.00392439686538039,4369,0,300.049408,300.0825195,600.104,600.104,,296.95805,,,,,,,,,,,,,,,,,,,,,,,300.0629539625
,12009332.55,300.0814819,600.104,,,0.555345337032864,0.000202850033822301,,,,,,,,,1,25,0,2.25000036880374,0.757658162977266,0.00297684120035992,4369,0,300.0814819,300.0814819,600.104,600.104,0.741387058883759,297.00595,,,,,,,,,,,,,,,,,,,,,,,300.0814819
,12009394.84,300.0578117375,800.012,1000,9.99853040939949,,7.94634122099189E-6,0.00633623284005949,-6.77626151600469E-6,0.00633623646348275,-0.0612747428208422,-1.52964440697201E-8,4.42885566619012E-10,1.5302854269815E-8,178.341550073515,333,5,5,13.4965986394558,0.757658162977266,0.00345919178180946,4369,0,300.0454102,300.0724792,800.012,800.012,,296.9766375,,,,,,,,,,,,,,,,,,,,,,,300.0578117375
,12009408.36,300.0664978,800.012,,,0.704206508903305,0.000202529998445972,,,,,,,,,1,25,0,2.21900010947138,0.757658162977266,0.00379468811270096,4369,0,300.0454102,300.0875854,800.012,800.012,0.740885976024768,296.99695,,,,,,,,,,,,,,,,,,,,,,,300.0664978
,12009470.56,300.0365676875,999.963,1000,9.99860863750089,,7.98263697348286E-6,0.00534811672538218,-7.56028137992164E-6,0.00534812206911615,-0.0809952266749292,-1.52961672575257E-8,4.43146117795632E-10,1.53025851166369E-8,178.34054493325,333,5,5,13.4965986394558,0.757658162977266,0.00293891617682962,4369,0,300.0102234,300.0584106,999.963,999.963,,296.9655625,,,,,,,,,,,,,,,,,,,,,,,300.0365676875
,12009486.25,300.05088805,999.963,,,0.83082276985649,0.000203729648762281,,,,,,,,,1,5,0,4.32899985462427,0.757658162977266,0.00455155759236181,4369,0,300.037323,300.0644531,999.963,999.963,0.742500850612344,297.0451,,,,,,,,,,,,,,,,,,,,,,,300.05088805
,12009540.98,300.018787375,1199.824,1000,9.99879644900859,,7.75631524374064E-6,0.00432999622450305,-6.69922386901779E-6,0.00433000140690637,-0.0886460235853406,-1.52957265850747E-8,4.42838822616889E-10,1.53021357329027E-8,178.341647273407,333,5,5,13.4965986394558,0.757658162977266,0.00240145025965373,4369,0,300.0041199,300.0281982,1199.824,1199.824,,296.9888,,,,,,,,,,,,,,,,,,,,,,,300.018787375
,12009554.55,300.03271485,1199.824,,,0.934918516021722,0.000202229322264283,,,,,,,,,1,5,0,2.23399952519685,0.757658162977266,0.00502461251941988,4369,0,300.0312195,300.0342102,1199.824,1199.824,0.741975566867498,297.0181,,,,,,,,,,,,,,,,,,,,,,,300.03271485
,12009616.80,300.032856,1400.011,1000,9.9986739731938,,7.18479004380203E-6,0.00333350649810705,-5.79092534550666E-6,0.00333351152806441,-0.0995334036983309,-1.5295832293156E-8,4.43014184201621E-10,1.53022464725856E-8,178.341002401191,333,5,5,13.4965986394558,0.757658162977266,0.00187719167971235,4369,0,300.0193176,300.049408,1400.011,1400.011,,296.9399875,,,,,,,,,,,,,,,,,,,,,,,300.032856
,12009630.41,300.03585815,1400.011,,,1.01765248162875,0.000203820280228937,,,,,,,,,1,5,0,2.17200026381761,0.757658162977266,0.00545599882234592,4369,0,300.0343628,300.0373535,1400.011,1400.011,0.741733756864949,297.0109,,,,,,,,,,,,,,,,,,,,,,,300.03585815
,12009692.74,300.00499345,1600.047,1000,9.99875133051556,,6.15115062166742E-6,0.00242381701720031,-5.65156526340833E-6,0.00242382360601174,-0.133595171630532,-1.52954213476259E-8,4.42697155970235E-10,1.53018265240891E-8,178.342144428474,333,5,5,13.4965986394558,0.757658162977266,0.00139859948571405,4369,0,299.9840088,300.0192261,1600.047,1600.047,,297.0101375,,,,,,,,,,,,,,,,,,,,,,,300.00499345
,12009706.25,300.028244,1600.047,,,1.07934694982733,0.000203611072105872,,,,,,,,,1,5,0,2.26599995512515,0.757658162977266,0.0057911327508278,4369,0,300.025238,300.03125,1600.047,1600.047,0.743115044952175,297.00335,,,,,,,,,,,,,,,,,,,,,,,300.028244
,12009768.64,300.04193115,1799.956,1000,9.99871602895379,,4.69439487901814E-6,0.0016940204682665,-5.40302011722392E-6,0.00169402908461816,-0.182742301776045,-1.52950201065002E-8,4.42547330458022E-10,1.53014211169401E-8,178.342661744422,333,5,5,13.4965986394558,0.757658162977266,0.00101648157691734,4369,0,300.0223694,300.0614929,1799.956,1799.956,,296.9351375,,,,,,,,,,,,,,,,,,,,,,,300.04193115
,12009782.15,300.0479584,1799.956,,,1.12279634816259,0.000203738568136959,,,,,,,,,1,5,0,2.21900010947138,0.757658162977266,0.00602044805580672,4369,0,300.0464478,300.049469,1799.956,1799.956,0.741958810301038,296.94635,,,,,,,,,,,,,,,,,,,,,,,300.0479584
,12009836.49,300.0277137625,1999.959,1000,9.99851742812291,,3.20396101660024E-6,0.00117724670047496,-4.64638752598226E-6,0.00117725586968009,-0.226135280560527,-1.52951593676405E-8,4.42840644954408E-10,1.53015688057906E-8,178.341578987353,333,5,5,13.4965986394558,0.757658162977266,0.000745731163609665,4369,0,299.9972534,300.0454102,1999.959,1999.959,,296.9054,,,,,,,,,,,,,,,,,,,,,,,300.0277137625
,12009850.17,300.04388425,1999.959,,,1.15260209389729,0.000204707256638261,,,,,,,,,1,5,0,2.26499978452921,0.757658162977266,0.00622698686539226,4369,0,300.0363464,300.0514221,1999.959,1999.959,0.744119749237196,296.9721,,,,,,,,,,,,,,,,,,,,,,,300.04388425
,12009912.36,300.0231056375,2199.957,1000,9.99862073495016,,2.02004945481634E-6,0.000836925317503251,-3.6223229138917E-6,0.000836933156411675,-0.247982125429814,-1.52949218431975E-8,4.42359979281364E-10,1.5301317477289E-8,178.343352345633,333,5,5,13.4965986394558,0.757658162977266,0.000568175173474068,4369,0,300.0151978,300.0332642,2199.957,2199.957,,296.909025,,,,,,,,,,,,,,,,,,,,,,,300.0231056375
,12009925.92,300.03474425,2199.957,,,1.17360408959696,0.000203717935801036,,,,,,,,,1,5,0,2.18699967954308,0.757658162977266,0.00632745767003368,4369,0,300.0242004,300.0452881,2199.957,2199.957,0.741757087321626,296.90665,,,,,,,,,,,,,,,,,,,,,,,300.03474425
,12009980.41,300.0437889,2400.125,1000,9.99833208963621,,1.25104640330313E-6,0.000620853151444105,-2.75804575079109E-6,0.000620859277513383,-0.25452611678088,-1.52952711300375E-8,4.42508074622495E-10,1.53016709001816E-8,178.342835857805,333,5,5,13.4965986394558,0.757658162977266,0.000456855617503129,4369,0,300.0302429,300.0543213,2400.125,2400.125,,296.8677,,,,,,,,,,,,,,,,,,,,,,,300.0437889
,12009993.88,300.04133605,2400.125,,,1.18926553239787,0.000201981539523037,,,,,,,,,1,5,0,2.26500041317195,0.757658162977266,0.00645619906873964,4369,0,300.0362549,300.0464172,2400.125,2400.125,0.741149394726867,296.88555,,,,,,,,,,,,,,,,,,,,,,,300.04133605
,12010048.29,300.050518025,2600.029,1000,9.9984673901102,,8.63821490225322E-7,0.000479872177251141,-2.04697925943869E-6,0.000479876543106494,-0.244403752754351,-1.52950844688406E-8,4.42577300868131E-10,1.53014863191852E-8,178.34255653867,333,5,5,13.4965986394558,0.757658162977266,0.000385761312171751,4369,0,300.031311,300.0704651,2600.029,2600.029,,296.822575,,,,,,,,,,,,,,,,,,,,,,,300.050518025
,12010061.89,300.0513153,2600.029,,,1.20145123870849,0.000203505085094011,,,,,,,,,1,5,0,2.23400015383959,0.757658162977266,0.00655451565668376,4369,0,300.0483093,300.0543213,2600.029,2600.029,0.742454733305575,296.8138,,,,,,,,,,,,,,,,,,,,,,,300.0513153
,12010116.50,300.0397796375,2800.179,1000,9.99849391407137,,6.25745404410928E-7,0.000385376039253814,-1.59973442653353E-6,0.000385379359568195,-0.237839136788693,-1.52950350102808E-8,4.42575413839687E-10,1.53014368267379E-8,178.342558245059,333,5,5,13.4965986394558,0.757658162977266,0.000339651485686318,4369,0,300.0162048,300.0523376,2800.179,2800.179,,296.89625,,,,,,,,,,,,,,,,,,,,,,,300.0397796375
,12010129.91,300.04632565,2800.179,,,1.20873462736784,0.000203891999457488,,,,,,,,,1,5,0,2.23400015383959,0.757658162977266,0.00651595903675049,4369,0,300.0403137,300.0523376,2800.179,2800.179,0.741789978230813,296.88955,,,,,,,,,,,,,,,,,,,,,,,300.04632565
,12010192.32,300.0332488875,2999.983,1000,9.99840986825154,,4.4470535821251E-7,0.000319502784467966,-1.11609506547914E-6,0.000319504733847527,-0.200146226539346,-1.5295170392628E-8,4.42499217169917E-10,1.53015699487576E-8,178.342858101748,333,5,5,13.4965986394558,0.757658162977266,0.000307715776716941,4369,0,300.0151978,300.0723877,2999.983,2999.983,,296.8349,,,,,,,,,,,,,,,,,,,,,,,300.0332488875
,12010205.74,300.0528259,2999.983,,,1.2144191539144,0.000174960674978732,,,,,,,,,1,5,0,2.20300052314997,0.757658162977266,0.00651766029434399,4369,0,300.0483093,300.0573425,2999.983,2999.983,0.705109429181725,296.938,,,,,,,,,,,,,,,,,,,,,,,300.0528259
,12010261.32,300.035350775,3199.882,1000,9.9984833376983,,3.3962963929E-7,0.000272906622233052,-7.92795391488578E-7,0.000272907773768331,-0.166444118506718,-1.52950910853064E-8,4.42471981960309E-10,1.53014898870221E-8,178.342951452447,333,5,5,13.4965986394558,0.757658162977266,0.000285735507671468,4369,0,300.019165,300.0462646,3199.882,3199.882,,296.852825,,,,,,,,,,,,,,,,,,,,,,,300.035350775
,12010274.76,300.0342102,3199.882,,,1.22230561118978,0.000203692674834261,,,,,,,,,1,5,0,2.13999983388931,0.757658162977266,0.00661830329652219,4369,0,300.0342102,300.0342102,3199.882,3199.882,0.741782157779918,296.8076,,,,,,,,,,,,,,,,,,,,,,,300.0342102
,12010330.50,300.0324974125,3399.833,1000,9.99854922003345,,2.62085768150611E-7,0.000238312636660994,-5.92777721370785E-7,0.000238313373896099,-0.142516956104942,-1.52950841076806E-8,4.42684388222822E-10,1.53014890559252E-8,178.342155683242,333,5,5,13.4965986394558,0.757658162977266,0.000269456046319178,4369,0,300.018219,300.0392761,3399.833,3399.833,,296.841475,,,,,,,,,,,,,,,,,,,,,,,300.0324974125
,12010343.97,300.03627015,3399.833,,,1.22783681467337,0.000206281568959432,,,,,,,,,1,5,0,2.18699967954308,0.757658162977266,0.00663484485156855,4369,0,300.0332642,300.0392761,3399.833,3399.833,0.742797661417423,296.8906,,,,,,,,,,,,,,,,,,,,,,,300.03627015
,12010406.24,300.016826625,3600.058,1000,9.99851222059287,,1.75195135687769E-7,0.000211879161018029,-4.21067373117464E-7,0.000211879579411128,-0.113863730130447,-1.52951681383966E-8,4.42787841258287E-10,1.53015760447802E-8,178.341777575081,333,5,5,13.4965986394558,0.757658162977266,0.000257531091193635,4369,0,300.0081787,300.0292358,3600.058,3600.058,,296.8263,,,,,,,,,,,,,,,,,,,,,,,300.016826625
,12010419.78,300.01675415,3600.058,,,1.23202507268,0.000202186150921635,,,,,,,,,1,5,0,2.26599995512515,0.757658162977266,0.00663604043666026,4369,0,300.0081787,300.0253296,3600.058,3600.058,0.741817755884062,296.8792,,,,,,,,,,,,,,,,,,,,,,,300.01675415
,12010482.15,300.016586325,3799.981,1000,9.99843350877545,,1.39742803892455E-7,0.000191351280356053,-2.91112792535168E-7,0.000191351501798545,-0.0871670232630777,-1.52954825936656E-8,4.42619111871599E-10,1.53018854868059E-8,178.342443166079,333,5,5,13.4965986394558,0.757658162977266,0.000248250799482869,4369,0,300.0012207,300.031311,3799.981,3799.981,,296.8186625,,,,,,,,,,,,,,,,,,,,,,,300.016586325
,12010495.68,300.00816345,3799.981,,,1.2363439823553,0.000205302798060941,,,,,,,,,1,5,0,2.23400015383959,0.757658162977266,0.00668500953309967,4369,0,300.0021362,300.0141907,3799.981,3799.981,0.744183443933814,296.88515,,,,,,,,,,,,,,,,,,,,,,,300.00816345
,12010551.28,300.0167999375,4000.149,1000,9.99841643991204,,1.1446404030345E-7,0.00017499560088191,-7.18643970756828E-8,0.00017499561563797,-0.0235293138654242,-1.52954841745222E-8,4.42579065775585E-10,1.53018859086886E-8,178.342593221582,333,5,5,13.4965986394558,0.757658162977266,0.00024085612881708,4369,0,300.0092773,300.0273438,4000.149,4000.149,,296.830625,,,,,,,,,,,,,,,,,,,,,,,300.0167999375
,12010564.85,300.0348358,4000.149,,,1.24075472738446,0.000205001969308491,,,,,,,,,1,5,0,2.21900010947138,0.757658162977266,0.00671659827233019,4369,0,300.0333252,300.0363464,4000.149,4000.149,0.742490160027649,296.81125,,,,,,,,,,,,,,,,,,,,,,,300.0348358
,12010620.45,300.01002885,4199.944,1000,9.99856492583478,,8.73391116910554E-8,0.000161625020571329,-2.52401485368498E-8,0.000161625022542141,-0.00894758725212341,-1.52954054594168E-8,4.42651882023097E-10,1.53018093327755E-8,178.3423121592,333,5,5,13.4965986394558,0.757658162977266,0.000235007507609778,4369,0,299.993103,300.0352478,4199.944,4199.944,,296.878475,,,,,,,,,,,,,,,,,,,,,,,300.01002885
,12010633.93,300.01416015,4199.944,,,1.24396390601396,0.000204759882281574,,,,,,,,,1,5,0,2.18699967954308,0.757658162977266,0.00671730443848978,4369,0,300.0081482,300.0201721,4199.944,4199.944,0.741561193807854,296.98335,,,,,,,,,,,,,,,,,,,,,,,300.01416015
,12010696.35,299.99809265,4400.009,1000,9.998732753137,,7.25418371858386E-8,0.000150480188110734,4.12411067229707E-8,0.000150480193762072,0.0157026737418434,-1.52951670185574E-8,4.42558798222692E-10,1.5301568299212E-8,178.342634732117,333,5,5,13.4965986394558,0.757658162977266,0.000230293454997336,4369,0,299.9890747,300.0071106,4400.009,4400.009,,296.984625,,,,,,,,,,,,,,,,,,,,,,,299.99809265
,12010709.88,299.99658205,4400.009,,,1.24651426174613,0.000205283717078484,,,,,,,,,1,5,0,2.14100000448525,0.757658162977266,0.00671445444603046,4369,0,299.9860535,300.0071106,4400.009,4400.009,0.742384468877897,296.9644,,,,,,,,,,,,,,,,,,,,,,,299.99658205
,12010772.15,299.9983558625,4599.898,1000,9.99861161313192,,7.83494698154251E-8,0.000141149283638916,7.93607285471218E-8,0.000141149305949071,0.0322143634630641,-1.52954290356011E-8,4.42580215875127E-10,1.53018308261003E-8,178.342582945481,333,5,5,13.4965986394558,0.757658162977266,0.000226654046582137,4369,0,299.9791565,300.0062561,4599.898,4599.898,,296.906525,,,,,,,,,,,,,,,,,,,,,,,299.9983558625
,12010785.81,299.98509215,4599.898,,,1.25041589069929,0.000204464586620196,,,,,,,,,1,5,0,2.31200025882572,0.757658162977266,0.00674613629486018,4369,0,299.9790649,299.9911194,4599.898,4599.898,0.74101412553617,296.94735,,,,,,,,,,,,,,,,,,,,,,,299.98509215
,12010848.04,299.9842643875,4800.09,1000,9.99862866433294,,7.5354167469054E-8,0.000133190626424655,1.14074820342682E-7,0.000133190675275924,0.0490725536145382,-1.52954488020763E-8,4.42585829002602E-10,1.53018507466571E-8,178.342564077356,333,5,5,13.4965986394558,0.757658162977266,0.000223641846861983,4369,0,299.9660645,300.0052185,4800.09,4800.09,,296.83285,,,,,,,,,,,,,,,,,,,,,,,299.9842643875
,12010861.63,299.9751129,4800.09,,,1.25384132888149,0.000201714965784604,,,,,,,,,1,5,0,2.23400015383959,0.757658162977266,0.00684292405924752,4369,0,299.9691162,299.9811096,4800.09,4800.09,0.740836921864884,296.8533,,,,,,,,,,,,,,,,,,,,,,,299.9751129
,12010923.98,299.9805336125,5000.069,1000,9.99861676352495,,7.37089337941551E-8,0.00012633170804983,2.2987563113032E-7,0.00012633191719274,0.104256398838166,-1.5295506157724E-8,4.42415801015085E-10,1.53019031614359E-8,178.343206668036,333,5,5,13.4965986394558,0.757658162977266,0.000220865349772451,4369,0,299.9711304,299.9891968,5000.069,5000.069,,296.894925,,,,,,,,,,,,,,,,,,,,,,,299.9805336125
,12010937.55,299.97415165,5000.069,,,1.25504470399434,0.000204787315384613,,,,,,,,,1,5,0,2.28099999949336,0.757658162977266,0.00668488442233671,4369,0,299.9711304,299.9771729,5000.069,5000.069,0.742941724631566,296.9057,,,,,,,,,,,,,,,,,,,,,,,299.97415165
,12010999.83,299.95620345,5200.144,1000,9.99877103073963,,6.07530424788077E-8,0.000120344422408896,2.74260367941066E-7,0.000120344734922971,0.130574679340399,-1.52952458380632E-8,4.42594118510995E-10,1.53016481073292E-8,178.342511069467,333,5,5,13.4965986394558,0.757658162977266,0.000218536288185117,4369,0,299.9298706,299.9810486,5200.144,5200.144,,296.9221875,,,,,,,,,,,,,,,,,,,,,,,299.95620345
,12011013.36,299.96899415,5200.144,,,1.2578283357282,0.0002049703864517,,,,,,,,,1,5,0,2.18799985013902,0.757658162977266,0.00675258839139581,4369,0,299.9569397,299.9810486,5200.144,5200.144,0.743402434547261,296.98375,,,,,,,,,,,,,,,,,,,,,,,299.96899415
,12011075.75,299.9594497625,5399.924,1000,9.99888282039538,,5.95144582947025E-8,0.000115018878790832,2.92408013971835E-7,0.000115019250478982,0.145660513986885,-1.52950053853998E-8,4.42404387284264E-10,1.53014022684621E-8,178.343195173964,333,5,5,13.4965986394558,0.757658162977266,0.000216275140915081,4369,0,299.9489136,299.9639587,5399.924,5399.924,,296.8948625,,,,,,,,,,,,,,,,,,,,,,,299.9594497625
,12011089.33,299.97610475,5399.924,,,1.25990943747704,0.000204407052425003,,,,,,,,,1,5,0,2.21900010947138,0.757658162977266,0.00676033585153375,4369,0,299.9640503,299.9881592,5399.924,5399.924,0.741930733650541,296.92955,,,,,,,,,,,,,,,,,,,,,,,299.97610475
,12011151.61,299.9605941875,5600.126,1000,9.99852754262555,,6.29024338851791E-8,0.000110327279991033,3.38996259375799E-7,0.000110327800796915,0.176048877573009,-1.52952765883676E-8,4.4266149757817E-10,1.53016807938248E-8,178.342262210548,333,5,5,13.4965986394558,0.757658162977266,0.000214081907962343,4369,0,299.947052,299.9711304,5600.126,5600.126,,296.8902125,,,,,,,,,,,,,,,,,,,,,,,299.9605941875
,12011165.14,299.9771576,5600.126,,,1.26257427795139,0.000202654654817967,,,,,,,,,1,5,0,2.249999740161,0.757658162977266,0.00676893619015195,4369,0,299.9651184,299.9891968,5600.126,5600.126,0.742095133631668,296.92815,,,,,,,,,,,,,,,,,,,,,,,299.9771576
,12011220.73,299.9930114625,5799.906,1000,9.9985972575107,,4.88116915939268E-8,0.000106135747392915,3.6281226070812E-7,0.000106136367506097,0.195857953944926,-1.52951160227975E-8,4.42689202564952E-10,1.53015210969663E-8,178.342141121088,333,5,5,13.4965986394558,0.757658162977266,0.000212491913945604,4369,0,299.9802246,300.0103149,5799.906,5799.906,,296.8774125,,,,,,,,,,,,,,,,,,,,,,,299.9930114625
,12011234.15,299.9877472,5799.906,,,1.26404050824173,0.000203672578633551,,,,,,,,,1,5,0,2.21899948082864,0.757658162977266,0.00676150281452228,4369,0,299.9862366,299.9892578,5799.906,5799.906,0.742845105308062,296.8972,,,,,,,,,,,,,,,,,,,,,,,299.9877472
,12011296.50,299.996276875,6000.122,1000,9.99834629818085,,5.63922166530186E-8,0.000102335633403786,3.80544424528369E-7,0.000102336340945986,0.213058621116456,-1.5295248311614E-8,4.4257854588001E-10,1.53016501294208E-8,178.342569623414,333,5,5,13.4965986394558,0.757658162977266,0.000210853980410773,4369,0,299.9831238,300.0252686,6000.122,6000.122,,296.944575,,,,,,,,,,,,,,,,,,,,,,,299.996276875
,12011309.99,299.99816895,6000.122,,,1.26598502866526,0.000205086296521558,,,,,,,,,1,5,0,2.249999740161,0.757658162977266,0.00679475548477706,4369,0,299.9951782,300.0011597,6000.122,6000.122,0.741977561836914,296.98725,,,,,,,,,,,,,,,,,,,,,,,299.99816895
,12011372.32,300.01121905,6199.898,1000,10.0017670531615,,4.80376577080879E-8,9.88796311795298E-5,4.1798098299006E-7,9.8880514613861E-5,0.242197541724967,-1.52955953864766E-8,4.42640095412787E-10,1.53019988393959E-8,178.342376845929,333,5,5,13.4965986394558,0.757658162977266,0.000209551623502589,4369,0,299.9931641,300.0292664,6199.898,6199.898,,296.9310875,,,,,,,,,,,,,,,,,,,,,,,300.01121905
,12011385.80,300.0142212,6199.898,,,1.26867327198686,0.000205977909308329,,,,,,,,,1,5,0,2.23499969579279,0.757658162977266,0.00682960370959409,4369,0,300.0142212,300.0142212,6199.898,6199.898,0.743348221352272,296.958,,,,,,,,,,,,,,,,,,,,,,,300.0142212
,12011448.99,300.0162735125,6400.067,1000,9.99828675219231,,5.79519173778321E-8,9.56940361931865E-5,4.31607744270984E-7,9.56950095260343E-5,0.258418763077801,-1.52952614831111E-8,4.42398301204667E-10,1.53016580831507E-8,178.343245678666,333,5,5,13.4965986394558,0.757658162977266,0.000208153387558221,4369,0,300.0061951,300.0293579,6400.067,6400.067,,296.9120875,,,,,,,,,,,,,,,,,,,,,,,300.0162735125
,12011462.70,300.0272827,6400.067,,,1.27079236088876,0.000205441011379006,,,,,,,,,1,5,0,2.21900010947138,0.757658162977266,0.00684669632401242,4369,0,300.0152588,300.0393066,6400.067,6400.067,0.743242300667847,297.0058,,,,,,,,,,,,,,,,,,,,,,,300.0272827
,12011524.98,300.0241241375,6600.003,1000,10.0017551003731,,5.45973230743611E-8,9.2859775331243E-5,4.91941559494706E-7,9.28610783970705E-5,0.303531979743408,-1.52955189541433E-8,4.42732339108602E-10,1.5301925107667E-8,178.342023319098,333,5,5,13.4965986394558,0.757658162977266,0.000207254521593984,4369,0,300.0053101,300.0384521,6600.003,6600.003,,296.943625,,,,,,,,,,,,,,,,,,,,,,,300.0241241375
,12011538.52,300.0414581,6600.003,,,1.27300936850366,0.000205267659208326,,,,,,,,,1,5,0,2.21900010947138,0.757658162977266,0.00684162537930382,4369,0,300.0294189,300.0534973,6600.003,6600.003,0.741857855076234,296.97855,,,,,,,,,,,,,,,,,,,,,,,300.0414581
,12011608.51,300.0226745625,6799.973,1000,10.00155078297,,4.82004541596949E-8,9.01385991668508E-5,4.706153694455E-7,9.01398277044512E-5,0.299139654816922,-1.52956803837861E-8,4.42630729594604E-10,1.53020835302164E-8,178.34242110599,333,5,5,13.4965986394558,0.757658162977266,0.000206032063882622,4369,0,300.0102539,300.0433655,6799.973,6799.973,,296.796725,,,,,,,,,,,,,,,,,,,,,,,300.0226745625
,12011622.00,300.0388641,6799.973,,,1.27492100411421,0.000203366481457297,,,,,,,,,1,5,0,2.15600004885346,0.757658162977266,0.00687843619749411,4369,0,300.031311,300.0464172,6799.973,6799.973,0.74228860750803,296.9228,,,,,,,,,,,,,,,,,,,,,,,300.0388641
,12011684.36,300.014865875,7000.127,1000,10.0016547101498,,4.86704698726977E-8,8.76837468465905E-5,4.7815514177557E-7,8.76850505696187E-5,0.312441028171125,-1.52956022571486E-8,4.42952139699324E-10,1.53020147368559E-8,178.341209682535,333,5,5,13.4965986394558,0.757658162977266,0.00020522907695457,4369,0,299.9821472,300.0363159,7000.127,7000.127,,296.7721,,,,,,,,,,,,,,,,,,,,,,,300.014865875
,12011697.89,300.0247345,7000.127,,,1.27699700014685,0.000204989906242401,,,,,,,,,1,5,0,2.17200026381761,0.757658162977266,0.0068923197239072,4369,0,300.0141907,300.0352783,7000.127,7000.127,0.741883866562364,296.80915,,,,,,,,,,,,,,,,,,,,,,,300.0247345
,12011761.28,300.018749225,7200.131,1000,10.0014701040115,,4.96266396343325E-8,8.5380565837931E-5,5.18849005697479E-7,8.53821423196677E-5,0.348176332756942,-1.52959800880983E-8,4.42710006075712E-10,1.53023854024456E-8,178.342156860074,333,5,5,13.4965986394558,0.757658162977266,0.000204625838018571,4369,0,299.999176,300.056366,7200.131,7200.131,,296.7934,,,,,,,,,,,,,,,,,,,,,,,300.018749225
,12011774.82,300.0322876,7200.131,,,1.2784627830775,0.000203761216064895,,,,,,,,,1,5,0,2.25000036880374,0.757658162977266,0.00693875161435093,4369,0,300.0292664,300.0353088,7200.131,7200.131,0.742213281942928,296.8325,,,,,,,,,,,,,,,,,,,,,,,300.0322876
,12011830.46,300.01963045,7399.939,1000,10.0014501161534,,4.70943125807179E-8,8.32452953332753E-5,5.17872504255462E-7,8.32469061710698E-5,0.356434870326999,-1.52958676516031E-8,4.42846413364239E-10,1.53022769600209E-8,178.341634149202,333,5,5,13.4965986394558,0.757658162977266,0.000203539208941805,4369,0,300.0011597,300.0433655,7399.939,7399.939,,296.8042875,,,,,,,,,,,,,,,,,,,,,,,300.01963045
,12011844.11,300.0252686,7399.939,,,1.27984347143868,0.00020471003383901,,,,,,,,,1,5,0,2.249999740161,0.757658162977266,0.00692425352114301,4369,0,300.0252686,300.0252686,7399.939,7399.939,0.742273994148257,296.83395,,,,,,,,,,,,,,,,,,,,,,,300.0252686
,12011914.18,300.0114822375,7599.995,1000,10.001594686645,,5.53906875411254E-8,8.12222592869785E-5,5.58658054234901E-7,8.12241805283545E-5,0.394082166991261,-1.52959139750909E-8,4.42472528385332E-10,1.53023124485078E-8,178.34303850357,333,5,5,13.4965986394558,0.757658162977266,0.000202632353057886,4369,0,299.9941711,300.0272827,7599.995,7599.995,,296.861725,,,,,,,,,,,,,,,,,,,,,,,300.0114822375
,12011927.69,300.001709,7599.995,,,1.28218720934721,0.000204967075615582,,,,,,,,,1,5,0,2.21900010947138,0.757658162977266,0.0069167848026916,4369,0,299.9821472,300.0212708,7599.995,7599.995,0.740871930261208,296.90345,,,,,,,,,,,,,,,,,,,,,,,300.001709
,12011990.13,299.9856605625,7799.945,1000,10.001683870175,,5.57804176786731E-8,7.93120568500144E-5,5.43820215212715E-7,7.93139212383702E-5,0.392854707017988,-1.52958200272295E-8,4.42730956884854E-10,1.53022260147202E-8,178.342061108693,333,5,5,13.4965986394558,0.757658162977266,0.000201901275406973,4369,0,299.9801636,300.0012207,7799.945,7799.945,,296.8287875,,,,,,,,,,,,,,,,,,,,,,,299.9856605625
,12012003.60,299.9911041,7799.945,,,1.28388218212955,0.000203455235612905,,,,,,,,,1,5,0,2.23499969579279,0.757658162977266,0.00693875793052171,4369,0,299.9851074,299.9971008,7799.945,7799.945,0.737692047223382,296.88055,,,,,,,,,,,,,,,,,,,,,,,299.9911041
,12012059.28,300.00549315,7999.991,1000,10.0017051272431,,4.18877562568881E-8,7.75458315446088E-5,5.43073673598362E-7,7.75477331645471E-5,0.401250720486774,-1.52958226621491E-8,4.42705611839305E-10,1.53022279152634E-8,178.34215625328,333,5,5,13.4965986394558,0.757658162977266,0.000201274066711928,4369,0,299.9820557,300.0152893,7999.991,7999.991,,296.86365,,,,,,,,,,,,,,,,,,,,,,,300.00549315
,12012072.89,300.0017395,7999.991,,,1.28531792342449,0.000205206405233984,,,,,,,,,1,5,0,2.249999740161,0.757658162977266,0.00695078385415123,4369,0,299.9881897,300.0152893,7999.991,7999.991,0.741490013879704,296.89955,,,,,,,,,,,,,,,,,,,,,,,300.0017395
,12012136.20,300.0032386875,8200.065,1000,10.0015535774892,,5.20478147384247E-8,7.58047906839907E-5,5.59535713343284E-7,7.58068556982688E-5,0.422908003112983,-1.52959764713272E-8,4.42777797355894E-10,1.53023837485938E-8,178.341902747795,333,5,5,13.4965986394558,0.757658162977266,0.000200594923538949,4369,0,299.9851685,300.0152893,8200.065,8200.065,,296.9150625,,,,,,,,,,,,,,,,,,,,,,,300.0032386875
,12012149.77,300.0092621,8200.065,,,1.28654772875226,0.000204532657209221,,,,,,,,,1,5,0,2.17200026381761,0.757658162977266,0.00694071100649328,4369,0,300.0032349,300.0152893,8200.065,8200.065,0.742929303543059,296.94115,,,,,,,,,,,,,,,,,,,,,,,300.0092621
,12012213.26,300.0046425,8400.191,1000,10.0016913298315,,5.31580743262954E-8,7.42981633999535E-5,6.34057839367836E-7,7.43008688640305E-5,0.48894824062529,-1.52957393472246E-8,4.42607757345565E-10,1.53021418045023E-8,178.342513471169,333,5,5,13.4965986394558,0.757658162977266,0.000200051609000566,4369,0,299.9880676,300.0151978,8400.191,8400.191,,296.9476375,,,,,,,,,,,,,,,,,,,,,,,300.0046425
,12012226.81,299.99861145,8400.191,,,1.28852834700224,0.000204318403353167,,,,,,,,,1,5,0,2.20300052314997,0.757658162977266,0.00698927582949704,4369,0,299.9880676,300.0091553,8400.191,8400.191,0.741514510180726,296.9329,,,,,,,,,,,,,,,,,,,,,,,299.99861145
,12012282.46,300.00611875,8600.047,1000,10.0014913758831,,4.87979324288294E-8,7.27196025956369E-5,5.87586262869188E-7,7.27219764533643E-5,0.462949178915924,-1.52958803162569E-8,4.42621304198717E-10,1.53022831063925E-8,178.342478036517,333,5,5,13.4965986394558,0.757658162977266,0.000199372465827586,4369,0,299.992218,300.0193176,8600.047,8600.047,,296.75755,,,,,,,,,,,,,,,,,,,,,,,300.00611875
,12012296.06,300.00123595,8600.047,,,1.28966028823522,0.000204179648838172,,,,,,,,,1,5,0,2.23400015383959,0.757658162977266,0.00698476081638422,4369,0,299.9952087,300.0072632,8600.047,8600.047,0.742615352742895,296.8605,,,,,,,,,,,,,,,,,,,,,,,300.00123595
,12012359.58,299.994735725,8800.046,1000,10.0016630806893,,5.11379772428024E-8,7.12497201020275E-5,6.04755896064963E-7,7.12522865900533E-5,0.486305467120221,-1.52958920822027E-8,4.42693614663131E-10,1.53022969591775E-8,178.342208674911,333,5,5,13.4965986394558,0.757658162977266,0.000199028899281256,4369,0,299.9720154,300.0163574,8800.046,8800.046,,296.8565375,,,,,,,,,,,,,,,,,,,,,,,299.994735725
,12012373.01,300.01333615,8800.046,,,1.2917259467791,0.00020404949983827,,,,,,,,,1,5,0,2.14100000448525,0.757658162977266,0.00699697798784116,4369,0,300.0103149,300.0163574,8800.046,8800.046,0.741174062908182,296.8717,,,,,,,,,,,,,,,,,,,,,,,300.01333615
,12012435.29,299.9909401,9000.072,1000,10.0016419736844,,4.99037474375972E-8,6.99308048149028E-5,6.30352321437031E-7,6.99336457372928E-5,0.516446930616164,-1.52958317297351E-8,4.4291359415166E-10,1.53022429975561E-8,178.341378818879,333,5,5,13.4965986394558,0.757658162977266,0.000198697317614449,4369,0,299.980011,299.9981079,9000.072,9000.072,,296.88,,,,,,,,,,,,,,,,,,,,,,,299.9909401
,12012448.82,300.01013185,9000.072,,,1.29256846344881,0.00020347871751989,,,,,,,,,1,5,0,2.21899948082864,0.757658162977266,0.00700896427953575,4369,0,300.0071106,300.0131531,9000.072,9000.072,0.74186197968989,296.99455,,,,,,,,,,,,,,,,,,,,,,,300.01013185
,12012504.45,299.992904625,9200.156,1000,10.0016340796245,,4.77668943008575E-8,6.86108556299774E-5,6.44134185041523E-7,6.86138792018491E-5,0.537889896186331,-1.52957134803736E-8,4.42822842578825E-10,1.53021221712412E-8,178.341705662437,333,5,5,13.4965986394558,0.757658162977266,0.000198110058517814,4369,0,299.9801025,299.9981689,9200.156,9200.156,,296.85305,,,,,,,,,,,,,,,,,,,,,,,299.992904625
,12012517.99,299.99215695,9200.156,,,1.29417120506628,0.000204175072399228,,,,,,,,,1,5,0,2.20299989450723,0.757658162977266,0.00700709374133489,4369,0,299.9891357,299.9951782,9200.156,9200.156,0.741564534611047,296.8859,,,,,,,,,,,,,,,,,,,,,,,299.99215695
,12012581.40,299.9942931875,9400.116,1000,10.0014342372353,,6.17380903337076E-8,6.73798620760202E-5,6.5261594402371E-7,6.73830224979104E-5,0.554927969291661,-1.52961623419172E-8,4.42862117918617E-10,1.53025719813949E-8,178.341607304585,333,5,5,13.4965986394558,0.757658162977266,0.000197742522212437,4369,0,299.9691162,300.0052185,9400.116,9400.116,,296.849725,,,,,,,,,,,,,,,,,,,,,,,299.9942931875
,12012594.98,300.00067135,9400.116,,,1.29523298434008,0.000203168574804061,,,,,,,,,1,5,0,2.28099999949336,0.757658162977266,0.0069580592370572,4369,0,299.999176,300.0021667,9400.116,9400.116,0.742298248999426,296.8925,,,,,,,,,,,,,,,,,,,,,,,300.00067135
,12012665.21,299.9750213625,9600.053,1000,10.001549566869,,5.89918930541947E-8,6.61323627097641E-5,6.56801015195287E-7,6.61356241760018E-5,0.56902078472124,-1.52961536552742E-8,4.429722081079E-10,1.53025664848389E-8,178.341194336928,333,5,5,13.4965986394558,0.757658162977266,0.000197295086710239,4369,0,299.9651184,299.9952087,9600.053,9600.053,,296.9166625,,,,,,,,,,,,,,,,,,,,,,,299.9750213625
,12012678.73,299.9921875,9600.053,,,1.29797266274382,0.000202998202684272,,,,,,,,,1,5,0,2.31199963018298,0.757658162977266,0.00695556919863388,4369,0,299.9831543,300.0012207,9600.053,9600.053,0.74064943948315,296.96135,,,,,,,,,,,,,,,,,,,,,,,299.9921875
,12012734.36,299.9575271625,9799.861,1000,10.0015286305643,,5.19804346178242E-8,6.50066402899047E-5,6.5879331870807E-7,6.50099783911503E-5,0.580629677729948,-1.5296135623976E-8,4.42928589510343E-10,1.5302547198505E-8,178.341355630859,333,5,5,13.4965986394558,0.757658162977266,0.000197167247995325,4369,0,299.9440002,299.9680481,9799.861,9799.861,,296.8950875,,,,,,,,,,,,,,,,,,,,,,,299.9575271625
,12012747.88,299.97857665,9799.861,,,1.29950074197406,0.000205128505145265,,,,,,,,,1,5,0,2.2490001982078,0.757658162977266,0.00702644695592788,4369,0,299.9680481,299.9891052,9799.861,9799.861,0.742071158249755,296.9776,,,,,,,,,,,,,,,,,,,,,,,299.97857665
,12012832.49,299.9625702,9999.959,1000,10.0017740367954,,5.07438517041707E-8,6.37904068171609E-5,6.78257348021007E-7,6.37940125319691E-5,0.609179672225173,-1.52959980676106E-8,4.43192615914347E-10,1.53024173443005E-8,178.340352561525,333,5,5,13.4965986394558,0.757658162977266,0.000196839661288359,4369,0,299.9429932,299.973114,9999.959,9999.959,,296.96885,,,,,,,,,,,,,,,,,,,,,,,299.9625702
,12012846.11,299.9725952,9999.959,,,1.30104759511037,0.000203815006369489,,,,,,,,,1,5,0,2.23399952519685,0.757658162977266,0.00709436370365736,4369,0,299.9500122,299.9951782,9999.959,9999.959,0.74049489402977,297.03615,,,,,,,,,,,,,,,,,,,,,,,299.9725952